Workbook

Sheet Raw
A1: name | B1: category | C1: rating | D1: address | E1: phone | F1: website | G1: url
A2: NEXA UNISEX SALON VASHI | B2: beauty parlor | C2: 4.9 | D2: Address: SHOP NO 13/14, SAI UDYAN, PLOT 25, Atmaram Janu Bhoir Marg, Juhu Nagar, Sector 14, Vashi, Navi Mumbai, Maharashtra 400703, India | E2: Phone: +91 89890 20251 | F2: https://www.instagram.com/nexa_salon_vashi | G2: https://www.google.com/maps/place/NEXA+UNISEX+SALON+VASHI/data=!4m7!3m6!1s0x3be7c1b673c7e4a7:0x82b55cbf4d8c90a9!8m2!3d19.083514!4d73.0015081!16s%2Fg%2F11y_qh6y8g!19sChIJp-THc7bB5zsRqZCMTb9ctYI?authuser=0&hl=ne&rclk=1
A3: Mountain spa salon | B3: beauty parlor | C3: 5 | D3: Address: 23B, Phase 2, Sector 19E, Vashi, Navi Mumbai, Maharashtra 400703, India | G3: https://www.google.com/maps/place/Mountain+spa+salon/data=!4m7!3m6!1s0x3be7c12846351565:0xc2b9424d4671667d!8m2!3d19.0877797!4d73.0093807!16s%2Fg%2F11nx5ck4d8!19sChIJZRU1RijB5zsRfWZxRk1CucI?authuser=0&hl=ne&rclk=1
A4: Beauty Queen, Ladies Beauty Salon & Spa | B4: beauty parlor | C4: 4.9 | D4: Address: Shree Vighnaharata Co-OP, Hsg. Soc. Ltd Shop No-5, Plot No-36,37,44 & 45, Sector-50 (Old, Seawoods West, Navi Mumbai, Maharashtra 400706, India | E4: Phone: +91 82915 23552 | G4: https://www.google.com/maps/place/Beauty+Queen,+Ladies+Beauty+Salon+%26+Spa/data=!4m7!3m6!1s0x3be7c3f95d5a2cbd:0x995bfdb6b655f59!8m2!3d19.0101587!4d73.0162682!16s%2Fg%2F11qyjyjy2k!19sChIJvSxaXfnD5zsRWV9la9u_lQk?authuser=0&hl=ne&rclk=1
A5: Spa Soul Koparkhairane | B5: Mineral Health Center | C5: 4.3 | D5: Address: Plot No - 62, The Residency Apartment CHS Shop No- 3,4,5, Sec-2A, Kopar Khairane, Navi Mumbai, Maharashtra 400709, India | E5: Phone: +91 75063 59471 | F5: http://spasoulkoparkhairane.in/ | G5: https://www.google.com/maps/place/Spa+Soul+Koparkhairane/data=!4m7!3m6!1s0x3be7c131ea4084db:0x967bfb7c8fd176ac!8m2!3d19.1108755!4d73.0037881!16s%2Fg%2F11kjdshcqy!19sChIJ24RA6jHB5zsRrHbRj3z7e5Y?authuser=0&hl=ne&rclk=1
A6: PUNAM BEUTY SALON SPA | B6: hair salon | C6: 4.5 | D6: Address: Shop No 02, Turbhe Village Rd, Turbhe Village, Sector 22, Turbhe, Navi Mumbai, Maharashtra 400703, India | E6: Phone: +91 77099 72518 | G6: https://www.google.com/maps/place/PUNAM+BEUTY+SALON+SPA/data=!4m7!3m6!1s0x3be7c10ab6d3df8f:0xb697c87ddc70b253!8m2!3d19.0703679!4d73.0130899!16s%2Fg%2F11ty70pbbm!19sChIJj9_TtgrB5zsRU7Jw3H3Il7Y?authuser=0&hl=ne&rclk=1
A7: B Blush On | B7: make-up artist | C7: 4.9 | D7: Address: Shop no 22, Shiv Complex, plot no 15, Prabhakar Krishanati Patil Marg, Sector 3, Ghansoli, Navi Mumbai, Maharashtra 400701, India | E7: Phone: +91 91369 45572 | F7: https://sites.google.com/view/bblushonbridalmakeupnavimumbai | G7: https://www.google.com/maps/place/B+Blush+On/data=!4m7!3m6!1s0x3be7c1000dd2eb7f:0xe07bed0996a67311!8m2!3d19.113844!4d73.0042693!16s%2Fg%2F11vryjd5wl!19sChIJf-vSDQDB5zsREXOmlgnte-A?authuser=0&hl=ne&rclk=1
A8: Avantara Spa In Vashi | B8: Mineral Health Center | C8: 4.5 | D8: Address: Shop No.06 Plot No.286, Mahavir Arcade, Padmasagar Society Opp Petrol pump, kopri Signal, Sector 28, Vashi, Navi Mumbai, Maharashtra 400703, India | E8: Phone: +91 91378 54464 | F8: https://avantaraspavashi.in/ | G8: https://www.google.com/maps/place/Avantara+Spa+In+Vashi/data=!4m7!3m6!1s0x3be7c1cff896f0c1:0x86833f505a5fa35f!8m2!3d19.0887008!4d73.0091452!16s%2Fg%2F11h11kthzh!19sChIJwfCW-M_B5zsRX6NfWlA_g4Y?authuser=0&hl=ne&rclk=1
A9: serenity salon and spa | B9: beautician | C9: 5 | D9: Address: Mahadev Niwas, plot no 205A, L.Sanjay Kumar Gorad Marg, near by Chatrapati Sambhaji udyan, Dharshana Society, Nerul West, Nerul, Navi Mumbai, Maharashtra 400706, India | E9: Phone: +91 83569 09858 | G9: https://www.google.com/maps/place/serenity+salon+and+spa/data=!4m7!3m6!1s0x3be7c37a1b758473:0xa13233a2aab04619!8m2!3d19.0356962!4d73.0097058!16s%2Fg%2F11yfkzjgzl!19sChIJc4R1G3rD5zsRGUawqqIzMqE?authuser=0&hl=ne&rclk=1
A10: Aspire Beauty Day Spa | B10: Massage spa | C10: 4.4 | D10: Address: PLOT NO.- 88, Mansarovar C.H.S.L 104/105 first floor, 14, above McDonald's, Sector 17, Vashi, Navi Mumbai, Maharashtra 400703, India | E10: Phone: +91 70451 04497 | F10: http://www.avanabeautydayspa.com/ | G10: https://www.google.com/maps/place/Aspire+Beauty+Day+Spa/data=!4m7!3m6!1s0x3be7c15c3f2c3291:0xc8a5fedb58dd7dec!8m2!3d19.0721187!4d72.9986256!16s%2Fg%2F11h1kct5mb!19sChIJkTIsP1zB5zsR7H3dWNv-pcg?authuser=0&hl=ne&rclk=1
A11: Nikhar Beauty Salon Makeup Studio & Academy | B11: beauty parlor | C11: 4.9 | D11: Address: Shop no.11, A-1, next to Vinayak Stationery, Sector 15, Vashi, Navi Mumbai, Maharashtra 400703, India | E11: Phone: +91 73031 50296 | G11: https://www.google.com/maps/place/Nikhar+Beauty+Salon+Makeup+Studio+%26+Academy/data=!4m7!3m6!1s0x3be7c1b77d3a00eb:0x13326fa7c7df1997!8m2!3d19.0800384!4d72.9998376!16s%2Fg%2F11rv2xz267!19sChIJ6wA6fbfB5zsRlxnfx6dvMhM?authuser=0&hl=ne&rclk=1
A12: Dhruva Spa & Saloon | B12: Mineral Health Center | C12: 4.5 | D12: Address: Ground Floor, Type-1, F-19, Sagar Vihar Marg, behind Ramdev Hotel, Bhodakdeo, Sector 4, Vashi, Navi Mumbai, Maharashtra 400703, India | E12: Phone: +91 97698 60170 | F12: https://dhruvaspa.com/ | G12: https://www.google.com/maps/place/Dhruva+Spa+%26+Saloon/data=!4m7!3m6!1s0x3be7c13428f153c3:0x3a1c462f6612b5fa!8m2!3d19.0746768!4d72.9904474!16s%2Fg%2F11bzt6shcy!19sChIJw1PxKDTB5zsR-rUSZi9GHDo?authuser=0&hl=ne&rclk=1
A13: Kaizo Salon - Hair , Nails , Skin & Hair Extensions | B13: beauty parlor | C13: 4.4 | D13: Address: Shop Number.5-6-7, Arenja Terrace, Plot Number.98, Sector 29, Vashi, Navi Mumbai, Maharashtra 400703, India | E13: Phone: +91 80807 94449 | G13: https://www.google.com/maps/place/Kaizo+Salon+-+Hair+,+Nails+,+Skin+%26+Hair+Extensions/data=!4m7!3m6!1s0x3be7c1a87ef8d17f:0xb94d93757c1d49e6!8m2!3d19.0858467!4d73.0067218!16s%2Fg%2F11gk39bw2b!19sChIJf9H4fqjB5zsR5kkdfHWTTbk?authuser=0&hl=ne&rclk=1
A14: H&S Salon | B14: beauty parlor | C14: 4.8 | D14: ठेगाना: SAGAR DARSHAN TOWER, Shop No.12 and 13.D-91, Plot No.38, Sector 18, Nerul West, Nerul, Maharashtra 400706, भारत | E14: Phone: +91 91677 79514 | F14: https://www.instagram.com/salonhns?igsh=ZWplb2M1Y2x3Z3Nz&utm_source=qr | G14: https://www.google.com/maps/place/H%26S+Salon/data=!4m7!3m6!1s0x3be7c30a0e12e50d:0x12469ebdf3718f4d!8m2!3d19.035497!4d73.0086784!16s%2Fg%2F11w4rky3x0!19sChIJDeUSDgrD5zsRTY9x872eRhI?authuser=0&hl=ne&rclk=1
A15: Glamour Zone Studio (Ladies Salon) | B15: beauty parlor | C15: 4.8 | D15: Address: Shop no 13, Pyramid Icon, railway station, opp. to union bank, near ghansoli, Sector 5, Savoli, Ghansoli, Navi Mumbai, Maharashtra 400701, India | E15: Phone: +91 90827 97847 | F15: https://www.instagram.com/glamourzonestudio?igsh=cTUydzhpcWowczM0 | G15: https://www.google.com/maps/place/Glamour+Zone+Studio+%28Ladies+Salon%29/data=!4m7!3m6!1s0x3be7c13a6eb3c7df:0x2ea58ddd81f5b0ce!8m2!3d19.1172645!4d73.0048958!16s%2Fg%2F11l33bcbjy!19sChIJ38ezbjrB5zsRzrD1gd2NpS4?authuser=0&hl=ne&rclk=1
A16: KB's Spa And Salon | B16: Mineral Health Center | C16: 4.4 | D16: Address: Shop No. 1, Mausam, Vijay Dairy, 285, Parmarth Niketan Marg, Sector 28, Vashi, Navi Mumbai, Maharashtra 400703, India | E16: Phone: +91 93215 51333 | G16: https://www.google.com/maps/place/KB%27s+Spa+And+Salon/data=!4m7!3m6!1s0x3be7c1245728ceb7:0xfc7278b6e58c8195!8m2!3d19.0888943!4d73.0086341!16s%2Fg%2F1q62grwb3!19sChIJt84oVyTB5zsRlYGM5bZ4cvw?authuser=0&hl=ne&rclk=1
A17: Swara Beauty Salon | B17: beauty parlor | C17: 4.9 | D17: Address: Shop No 52, B-wing, Welfare Chambers, Plot No 73, 17, Vashi, Navi Mumbai, Maharashtra 400703, India | E17: Phone: +91 80 6507 2185 | F17: http://www.swarabeautysalon.in/ | G17: https://www.google.com/maps/place/Swara+Beauty+Salon/data=!4m7!3m6!1s0x3be7c13a0ccafa01:0xb2e63ffd51afe27d!8m2!3d19.0733036!4d73.00117!16s%2Fg%2F11xp1vp2w3!19sChIJAfrKDDrB5zsRfeKvUf0_5rI?authuser=0&hl=ne&rclk=1
A18: ROSE HAIR & BEAUTY SALON | B18: Esthetics service | C18: 4.8 | D18: Address: Tulsidas Building, Shop No: 3, Plot No: 56 Ram Bhau Sudama Bhoir Marg Karave Nagar, Karave Village, Sector 44A, Seawoods, Navi Mumbai, Maharashtra 400706, India | E18: Phone: +91 99300 65947 | F18: https://rose-hair-beauty-salon.grexa.site/ | G18: https://www.google.com/maps/place/ROSE+HAIR+%26+BEAUTY+SALON/data=!4m7!3m6!1s0x3be7c39bdc64c91f:0xb602674887e78acf!8m2!3d19.013165!4d73.010486!16s%2Fg%2F1ptzm0nqf!19sChIJH8lk3JvD5zsRz4rnh0hnArY?authuser=0&hl=ne&rclk=1
A19: Blue Tara Spa & Salon | B19: Massage spa | C19: 5 | D19: Address: Shop No- 18, Kesav Kunj Building, West, near Rajmata Restaurant, Sector 30A, Sanpada, Navi Mumbai, Maharashtra 400705, India | E19: Phone: +91 91363 34115 | F19: https://bluetaraspa.in/ | G19: https://www.google.com/maps/place/Blue+Tara+Spa+%26+Salon/data=!4m7!3m6!1s0x3be7c19e603858bd:0xc52e76f0a563c82e!8m2!3d19.0662008!4d73.0059748!16s%2Fg%2F11wm_pz3hq!19sChIJvVg4YJ7B5zsRLshjpfB2LsU?authuser=0&hl=ne&rclk=1
A20: Unique salon & spa | B20: hairdresser | C20: 4.8 | D20: Address: near Sai Holy Faith High School, 19/C, Gaothan, Sector 19, Kopar Khairane, Navi Mumbai, Maharashtra 400709, India | G20: https://www.google.com/maps/place/Unique+salon+%26+spa/data=!4m7!3m6!1s0x3be7c1749bc16eab:0xaee77d8a063ca95!8m2!3d19.1038114!4d72.9984667!16s%2Fg%2F11pydfn2wp!19sChIJq27Bm3TB5zsRlcpjoNh37go?authuser=0&hl=ne&rclk=1
A21: Looks Salon, Seawoods, Navi Mumbai | B21: hair salon | C21: 4.7 | D21: Address: UG-14, Ground floor, Nexus Seawoods Mall, Nerul East, Sector 40, Nerul, Navi Mumbai, Maharashtra 400706, India | E21: Phone: +91 98998 81774 | F21: http://www.lookssalon.in/ | G21: https://www.google.com/maps/place/Looks+Salon,+Seawoods,+Navi+Mumbai/data=!4m7!3m6!1s0x3be7c3964fffffb9:0x4260de3e50c4519b!8m2!3d19.0215201!4d73.0186911!16s%2Fg%2F11c5_vsqx8!19sChIJuf__T5bD5zsRm1HEUD7eYEI?authuser=0&hl=ne&rclk=1
A22: White Oasis Spa | B22: Mineral Health Center | C22: 4.9 | D22: Address: Shop No. 24, Satra Plaza, Palm Beach Rd, next to JIMI'S Burger, Phase 2, Sector 19D, Vashi, Navi Mumbai, Maharashtra 400703, India | E22: Phone: +91 88929 00600 | F22: https://whitespalon.com/ | G22: https://www.google.com/maps/place/White+Oasis+Spa/data=!4m7!3m6!1s0x3be7c1bd4ca8efe1:0x947049532e8273b0!8m2!3d19.0825961!4d73.006019!16s%2Fg%2F11qp4wq_2y!19sChIJ4e-oTL3B5zsRsHOCLlNJcJQ?authuser=0&hl=ne&rclk=1
A23: Glam Studio by pramila | B23: beauty parlor | C23: 4.7 | D23: ठेगाना: PLATINUM VENECIA ,SHOP NO:11,FIRST FLOOR ,plot no 20, above Foodway Restaurant, Nerul East, Sector 29, Nerul, Navi Mumbai, Maharashtra 400706, भारत | E23: Phone: +91 22 7966 4028 | F23: https://www.instagram.com/glam_studio_by_pramila?igsh=eHdqc2pwMzRlcDZj | G23: https://www.google.com/maps/place/Glam+Studio+by+pramila/data=!4m7!3m6!1s0x3be7c3c25b0fdaa7:0x6503cc330ef67609!8m2!3d19.0371476!4d73.0189344!16s%2Fg%2F11fy_fk0wn!19sChIJp9oPW8LD5zsRCXb2DjPMA2U?authuser=0&hl=ne&rclk=1
A24: Peacock Salon | Hair, Nail & Beauty Salon in Navi Mumbai | B24: beauty parlor | C24: 4.6 | D24: Address: Shop no 20, 21, 21A, 22, Mahavir Center, next to Golden. Punjab Hotel, Sector 17, Vashi, Navi Mumbai, Maharashtra 400703, India | E24: Phone: +91 93247 74567 | F24: https://peacocksalon.in/ | G24: https://www.google.com/maps/place/Peacock+Salon+%7C+Hair,+Nail+%26+Beauty+Salon+in+Navi+Mumbai/data=!4m7!3m6!1s0x3be7c14a08786177:0x8fc18a9d9f475bc4!8m2!3d19.0735796!4d72.9993896!16s%2Fg%2F1tqt83rj!19sChIJd2F4CErB5zsRxFtHn52KwY8?authuser=0&hl=ne&rclk=1
A25: Elegance Hair & Beauty Salon | Hair & Beauty Studio | Nerul, Navi Mumbai | B25: beauty parlor | C25: 4.7 | D25: Address: Oppo, Sagardeep c, Shop no.14, meridian appt, plot no. 25 & 27, Sector Number 6 Road, near apna bazaar, Nerul West, Navi Mumbai, Maharashtra 400706, India | E25: Phone: +91 88799 41107 | F25: https://www.instagram.com/invites/contact/?igsh=13vik18hoh4o9&utm_content=1go0qx1 | G25: https://www.google.com/maps/place/Elegance+Hair+%26+Beauty+Salon+%7C+Hair+%26+Beauty+Studio+%7C+Nerul,+Navi+Mumbai/data=!4m7!3m6!1s0x3be7c3ef161ccc8f:0x164912d4cdcb0b24!8m2!3d19.0418903!4d73.0095818!16s%2Fg%2F11gfnx2f6z!19sChIJj8wcFu_D5zsRJAvLzdQSSRY?authuser=0&hl=ne&rclk=1
A26: Gingerlin nx | B26: beauty parlor | C26: 4.9 | D26: Address: Shop No11, Shanti Vaibhav, building-A, plot 11A, Sector 42A, Seawoods, Navi Mumbai, Maharashtra 400706, India | E26: Phone: +91 98202 92472 | F26: https://www.connectto.in/business/gingerlin-nx-unisex-salon-seawoods | G26: https://www.google.com/maps/place/Gingerlin+nx/data=!4m7!3m6!1s0x3be7c397ae37f19f:0xbcc45040a8a69959!8m2!3d19.0179124!4d73.0162353!16s%2Fg%2F11cjpybkvm!19sChIJn_E3rpfD5zsRWZmmqEBQxLw?authuser=0&hl=ne&rclk=1
A27: Anagha's Salon & Academy | B27: beauty parlor | C27: 4.8 | D27: Address: Shop no. 08, Swastik Sindhu, plot. 268, Sector 23, Juinagar, Navi Mumbai, Maharashtra 400705, India | E27: Phone: +91 96198 23636 | F27: http://anaghassalonacademy.in/ | G27: https://www.google.com/maps/place/Anagha%27s+Salon+%26+Academy/data=!4m7!3m6!1s0x3be7c1a0bd1c7de7:0xd88e1912af8f9060!8m2!3d19.0521686!4d73.0166491!16s%2Fg%2F11t7td8vt9!19sChIJ530cvaDB5zsRYJCPrxIZjtg?authuser=0&hl=ne&rclk=1
A28: Colors Spa And Salon | B28: Massage spa | C28: 5 | D28: Address: 2'Nd Floor, Aditi Apartment, F-2 / A-4, Plot No 12, Sector 9, Vashi, Navi Mumbai, Maharashtra 400703, India | E28: Phone: +91 83699 24908 | G28: https://www.google.com/maps/place/Colors+Spa+And+Salon/data=!4m7!3m6!1s0x3be7c1e7b58bdaf3:0x7cfc0cd212172af4!8m2!3d19.0795002!4d72.9981334!16s%2Fg%2F11ypc6076t!19sChIJ89qLtefB5zsR9CoXEtIM_Hw?authuser=0&hl=ne&rclk=1
A29: Sayli Beauty Salon & Spa | B29: beauty parlor | C29: 4.9 | D29: Address: Shop No. 03, Shri, Sector 10, Sanpada, Navi Mumbai, Maharashtra 400705, India | E29: Phone: +91 89284 63304 | G29: https://www.google.com/maps/place/Sayli+Beauty+Salon+%26+Spa/data=!4m7!3m6!1s0x3be7c1d0a8aa8f11:0x54041372fc407ea6!8m2!3d19.0596102!4d73.0146172!16s%2Fg%2F11s7tchhdc!19sChIJEY-qqNDB5zsRpn5A_HITBFQ?authuser=0&hl=ne&rclk=1
A30: Spa Berry (Spa In Vashi) | B30: Mineral Health Center | C30: 4.8 | D30: Address: Shop No 102, PLOT NO.- 88, 14, Mansarovar Chs, Sector 17, Vashi, Navi Mumbai, Maharashtra 400703, India | E30: Phone: +91 91523 22432 | F30: https://spaberryvashi.in/ | G30: https://www.google.com/maps/place/Spa+Berry+%28Spa+In+Vashi%29/data=!4m7!3m6!1s0x3be7c1eb76d4dcdb:0xd2e680d4af1b5a76!8m2!3d19.0721832!4d72.9989916!16s%2Fg%2F11ks09zm_y!19sChIJ29zUduvB5zsRdlobr9SA5tI?authuser=0&hl=ne&rclk=1
A31: The Cloud Family Salon | B31: beauty parlor | C31: 5 | D31: Address: Shop 4, Ambe Bhakti Apartment, Plot no 17, Sector 5, Sector 4, Ghansoli, Navi Mumbai, Maharashtra 400701, India | E31: Phone: +91 88283 26133 | F31: https://www.instagram.com/thecloudfamilysalon?igsh=eTRkbTYwaDZwanV5 | G31: https://www.google.com/maps/place/The+Cloud+Family+Salon/data=!4m7!3m6!1s0x3be7c16e3394b759:0xc6ec6fbbbb13a2e8!8m2!3d19.1176584!4d73.0024697!16s%2Fg%2F11xcrjjx1p!19sChIJWbeUM27B5zsR6KITu7tv7MY?authuser=0&hl=ne&rclk=1
A32: The Alvi Men Salon | B32: Facial Spa | C32: 4.3 | D32: Address: Shop No 34, BUILDING no 3, NL2 Rd, Nerul East, Sector 15, Nerul, Navi Mumbai, Maharashtra 400706, India | E32: Phone: +91 84259 21245 | G32: https://www.google.com/maps/place/The+Alvi+Men+Salon/data=!4m7!3m6!1s0x3be7c3b27d44df4f:0x25e22ebcd0224a46!8m2!3d19.0361976!4d73.0199154!16s%2Fg%2F11fl5d7snz!19sChIJT99EfbLD5zsRRkoi0Lwu4iU?authuser=0&hl=ne&rclk=1
A33: Doxa Salon | B33: hairdresser | C33: 4.9 | D33: Address: A-9, One Akshar, Shop No. A-7, A-8, Plot no. 7, Sector 13, Sanpada, Navi Mumbai, Maharashtra 400705, India | E33: Phone: +91 85917 32960 | F33: https://doxasalon.in/ | G33: https://www.google.com/maps/place/Doxa+Salon/data=!4m7!3m6!1s0x3be7c194e913822f:0x878e1d4269c82825!8m2!3d19.0602003!4d73.0017482!16s%2Fg%2F11rsr0y57y!19sChIJL4IT6ZTB5zsRJSjIaUIdjoc?authuser=0&hl=ne&rclk=1
A34: PP Family Salon & Spa | B34: Mineral Health Center | C34: 5 | D34: Address: 3rd Floor, Amrit House, Plot No 38, Palm Beach Rd, near Fortune Hotel, Phase 2, Sector 19E, Vashi, Navi Mumbai, Maharashtra 400703, India | E34: Phone: +91 83697 49392 | F34: https://ppfamilysalonandspa.in/ | G34: https://www.google.com/maps/place/PP+Family+Salon+%26+Spa/data=!4m7!3m6!1s0x3be7c1f80d09f17b:0x2c76a0912dce9c72!8m2!3d19.0865426!4d73.008696!16s%2Fg%2F11vqhh75cw!19sChIJe_EJDfjB5zsRcpzOLZGgdiw?authuser=0&hl=ne&rclk=1
A35: Raybence Spa Nerul | B35: Mineral Health Center | C35: 4.4 | D35: ठेगाना: Near, Shop no G-15 Plot No-103 Ground Floor , Haware Centurian Mall, Seawoods, Navi Mumbai, Maharashtra 400706, भारत | E35: Phone: +91 98201 50592 | F35: https://raybencespa.in/ | G35: https://www.google.com/maps/place/Raybence+Spa+Nerul/data=!4m7!3m6!1s0x3be7c3122f13e81b:0x7198d298587de950!8m2!3d19.0246753!4d73.0221464!16s%2Fg%2F11h99r23bg!19sChIJG-gTLxLD5zsRUOl9WJjSmHE?authuser=0&hl=ne&rclk=1
A36: The King's Luxury Spa | B36: Mineral Health Center | C36: 4.8 | D36: Address: Shop No. A-01, 1st Floor, Mahavir Dham CHS, Plot no. 112, Vashi Kopar Khairane Rd, near Bhagat Tarachand Hotel, Juhu Nagar, Sector 12, Vashi, Navi Mumbai, Maharashtra 400703, India | E36: Phone: +91 90369 36907 | F36: http://kingsspavashi.com/ | G36: https://www.google.com/maps/place/The+King%27s+Luxury+Spa/data=!4m7!3m6!1s0x3be7c1d305a5b82b:0x9180c9d872385d37!8m2!3d19.0898111!4d73.0047826!16s%2Fg%2F11s6f4mdf9!19sChIJK7ilBdPB5zsRN104ctjJgJE?authuser=0&hl=ne&rclk=1
A37: Scissors Noise - The Family Salon (Vashi) | B37: beauty parlor | C37: 4.8 | D37: Address: ground floor, RAGHULEELA MALL, Shop no 226 and 227, Opp, Vashi Railway Station Rd, Sector 30A, Vashi, Navi Mumbai, Maharashtra 400703, India | E37: Phone: +91 76664 77224 | G37: https://www.google.com/maps/place/Scissors+Noise+-+The+Family+Salon+%28Vashi%29/data=!4m7!3m6!1s0x3be7c14da4367553:0x87dfcb94ed98c350!8m2!3d19.0643146!4d72.9962712!16s%2Fg%2F11bzs4ffq_!19sChIJU3U2pE3B5zsRUMOY7ZTL34c?authuser=0&hl=ne&rclk=1
A38: V-Wellness Spa | B38: Mineral Health Center | C38: 4.9 | D38: Address: Shop No A002, Ground Floor, Railway Commercial Complex, near Power Gym, Sector 3, Sanpada, Navi Mumbai, Maharashtra 400705, India | E38: Phone: +91 87793 76090 | F38: https://vwellnessspa.site/ | G38: https://www.google.com/maps/place/V-Wellness+Spa/data=!4m7!3m6!1s0x3be7c1db47750d6d:0xdea0ce088774199c!8m2!3d19.065272!4d73.0088996!16s%2Fg%2F11y7jk3j0v!19sChIJbQ11R9vB5zsRnBl0hwjOoN4?authuser=0&hl=ne&rclk=1
A39: Enrich Salon Vashi Sector 17 | B39: beauty parlor | C39: 4.5 | D39: Address: Shop No.32,33,35, Ground Floor, Chhada Crescent Chsl, Plot No.46, 55, Sector 17, Road, Navi, Vashi, Mumbai, Maharashtra 400703, India | E39: Phone: +91 91672 58614 | F39: https://www.enrichbeauty.com/ | G39: https://www.google.com/maps/place/Enrich+Salon+Vashi+Sector+17/data=!4m7!3m6!1s0x3be7c149a5db924b:0x6759cf9d39a4eb7a!8m2!3d19.0714788!4d73.0012998!16s%2Fg%2F1pp2vk8_p!19sChIJS5LbpUnB5zsReuukOZ3PWWc?authuser=0&hl=ne&rclk=1
A40: Arth Thai Spa Palm Beach Rd | B40: Mineral Health Center | C40: 4.6 | D40: Address: Shah Complex III, Plot No, Shop No 1/2/3, opp. Palm Beach Road, Sector 13, Sanpada, Navi Mumbai, Maharashtra 400705, India | E40: Phone: +91 85910 78771 | F40: https://arththaispanavimumbai.in/ | G40: https://www.google.com/maps/place/Arth+Thai+Spa+Palm+Beach+Rd/data=!4m7!3m6!1s0x3be7c1153c5e66b1:0x5e9ea133a047798b!8m2!3d19.0611794!4d73.0017859!16s%2Fg%2F11lc7k9skd!19sChIJsWZePBXB5zsRi3lHoDOhnl4?authuser=0&hl=ne&rclk=1
...

Sheet Navi Leads
A1: Collected and prepared by AkishaBhujel@gmail.com
A3: Name | B3: Industry | C3: Rating | D3: Contact | E3: Location | F3: Website | G3: Quality
A4: 3D Salon Academy | B4: beauty parlor | C4: 4.6 | D4: =SUBSTITUTE(Raw!E63,"Phone:","") -> +91 73049 64010 | E4: =HYPERLINK(Raw!G63,"Open Maps") -> Open Maps | F4: Not Available | G4: Not Available
A5: 7 Seas Family Salon & Spa | Best Salon in Vashi, Navi Mumbai | B5: Mineral Health Center | C5: 4.5 | D5: =SUBSTITUTE(Raw!E82,"Phone:","") -> +91 70455 53444 | E5: =HYPERLINK(Raw!G82,"Open Maps") -> Open Maps | F5: Not Available | G5: Not Available
A6: Ace Wellness Spa - Authentic Professional Massage Spa in Vashi | B6: Massage spa | C6: 4.9 | D6: =SUBSTITUTE(Raw!E65,"Phone:","") -> +91 93723 63557 | E6: =HYPERLINK(Raw!G65,"Open Maps") -> Open Maps | F6: Ace Wellness Spa | G6: Good
A7: Allure Thai Spa & Wellness in Seawoods | B7: Mineral Health Center | C7: 4.7 | D7: =SUBSTITUTE(Raw!E69,"Phone:","") -> +91 70214 32356 | E7: =HYPERLINK(Raw!G69,"Open Maps") -> Open Maps | F7: Spa In Seawoods | Massage In Nerul | Spas In Navi Mumbai | G7: Okey
A8: Anagha's Salon & Academy | B8: beauty parlor | C8: 4.8 | D8: =SUBSTITUTE(Raw!E27,"Phone:","") -> +91 96198 23636 | E8: =HYPERLINK(Raw!G27,"Open Maps") -> Open Maps | F8: Anagha’s Salon | G8: To much is happening, website
A9: Arc Luxury Body Spa | B9: Mineral Health Center | C9: 4.8 | D9: =SUBSTITUTE(Raw!E111,"Phone:","") -> +91 76669 85184 | E9: =HYPERLINK(Raw!G103,"Open Maps") -> Open Maps | F9: Not Available | G9: Not Available
A10: Arth Thai Spa Palm Beach Rd | B10: Mineral Health Center | C10: 4.6 | D10: =SUBSTITUTE(Raw!E40,"Phone:","") -> +91 85910 78771 | E10: =HYPERLINK(Raw!G40,"Open Maps") -> Open Maps | F10: Arth Thai spa Sanpada | G10: Need better UI, website
A11: Aspire Beauty Day Spa | B11: Massage spa | C11: 4.4 | D11: =SUBSTITUTE(Raw!E10,"Phone:","") -> +91 70451 04497 | E11: =HYPERLINK(Raw!G10,"Open Maps") -> Open Maps | F11: http://www.avanabeautydayspa.com/ | G11: Not available
A12: Athenian Salon Ghatkopper Mumbai - Salon & Academy Ghatkopar East Mumbai Maharashtra | B12: beauty parlor | C12: 4.9 | D12: =SUBSTITUTE(Raw!E121,"Phone:","") -> +91 93210 16619 | E12: =HYPERLINK(Raw!G113,"Open Maps") -> Open Maps | F12: Athenian Salon Mumbai | G12: Color is bad, website
A13: AURA UNISEX SALON | Best Hair Spa, Nail Art & Semi Permanent Makeup in Navi Mumbai | B13: beauty parlor | C13: 4.3 | D13: =SUBSTITUTE(Raw!E70,"Phone:","") -> +91 70212 18149 | E13: =HYPERLINK(Raw!G70,"Open Maps") -> Open Maps | F13: aurasalon | G13: To much AI, need better Digital Marketing
A14: Avantara Spa In Vashi | B14: Mineral Health Center | C14: 4.5 | D14: =SUBSTITUTE(Raw!E8,"Phone:","") -> +91 91378 54464 | E14: =HYPERLINK(Raw!G8,"Open Maps") -> Open Maps | F14: Avantara Spa Vashi | G14: Okey
A15: Avenue Spa | B15: massage spa | C15: 4.4 | D15: =SUBSTITUTE(Raw!E118,"Phone:","") -> +91 22 2770 0160 | E15: =HYPERLINK(Raw!G110,"Open Maps") -> Open Maps | F15: http://avenuespa.in/ | G15: Not available
A16: B Blush On | B16: make-up artist | C16: 4.9 | D16: =SUBSTITUTE(Raw!E7,"Phone:","") -> +91 91369 45572 | E16: =HYPERLINK(Raw!G7,"Open Maps") -> Open Maps | F16: B BLUSH ON BRIDAL MAKEUP | G16: Slow, website
A17: B'DESI THE SPA | B17: Mineral Health Center | C17: 4.9 | D17: =SUBSTITUTE(Raw!E120,"Phone:","") -> +91 96073 15335 | E17: =HYPERLINK(Raw!G112,"Open Maps") -> Open Maps | F17: B'Desi The Spa | G17: Good
A18: Beauty Queen, Ladies Beauty Salon & Spa | B18: beauty parlor | C18: 4.9 | D18: =SUBSTITUTE(Raw!E4,"Phone:","") -> +91 82915 23552 | E18: =HYPERLINK(Raw!G4,"Open Maps") -> Open Maps | F18: Not Available | G18: Not Available
A19: Blue Diamond Spa and Salon | B19: Mineral Health Center | C19: 4.3 | D19: =SUBSTITUTE(Raw!E48,"Phone:","") -> +91 89299 34855 | E19: =HYPERLINK(Raw!G48,"Open Maps") -> Open Maps | F19: Blue Diamond Spa | G19: Good
A20: Blue Tara Spa & Salon | B20: Massage spa | C20: 5 | D20: =SUBSTITUTE(Raw!E19,"Phone:","") -> +91 91363 34115 | E20: =HYPERLINK(Raw!G19,"Open Maps") -> Open Maps | F20: Blue Tara Spa | G20: Good
A21: Bodhi Wellness Spa & Salon | B21: Mineral Health Center | C21: 4.8 | D21: =SUBSTITUTE(Raw!E87,"Phone:","") -> +91 98980 18686 | E21: =HYPERLINK(Raw!G87,"Open Maps") -> Open Maps | F21: Bodhi Wellness | G21: To much happening, website
A22: Colors Spa And Salon | B22: Massage spa | C22: 5 | D22: =SUBSTITUTE(Raw!E28,"Phone:","") -> +91 83699 24908 | E22: =HYPERLINK(Raw!G28,"Open Maps") -> Open Maps | F22: Not Available | G22: Not Available
A23: Colour Spa and Hammam | B23: Mineral Health Center | C23: 4.7 | D23: =SUBSTITUTE(Raw!E91,"Phone:","") -> +91 73888 87976 | E23: =HYPERLINK(Raw!G91,"Open Maps") -> Open Maps | F23: Colour Spa And Hammam | G23: Average
A24: Colours Family Salon | B24: Mineral Health Center | C24: 5 | D24: =SUBSTITUTE(Raw!E47,"Phone:","") -> +91 75061 19512 | E24: =HYPERLINK(Raw!G47,"Open Maps") -> Open Maps | F24: Not Available | G24: Not Available
A25: Crystal Spa In Vashi | B25: Mineral Health Center | C25: 4.4 | D25: =SUBSTITUTE(Raw!E62,"Phone:","") -> +91 77158 21206 | E25: =HYPERLINK(Raw!G62,"Open Maps") -> Open Maps | F25: Crystal Spa & Massage Vashi | G25: Idk, website
A26: D.S SPA AND FAMILY SALOON | B26: Mineral Health Center | C26: 4.1 | D26: =SUBSTITUTE(Raw!E119,"Phone:","") -> +91 98925 73005 | E26: =HYPERLINK(Raw!G111,"Open Maps") -> Open Maps | F26: Not Available | G26: Not Available
A27: DAMANDEEPS WELLNESS- Salon service in Vashi / Hair Treatments in Navi Mumbai/ Pigmentation Treatment in Navi Mumbai | B27: wellness center | C27: 4.8 | D27: =SUBSTITUTE(Raw!E66,"Phone:","") -> +91 93213 92535 | E27: =HYPERLINK(Raw!G66,"Open Maps") -> Open Maps | F27: https://damandeepswellness.in/ | G27: Not available
A28: Dhruva Spa & Saloon | B28: Mineral Health Center | C28: 4.5 | D28: =SUBSTITUTE(Raw!E12,"Phone:","") -> +91 97698 60170 | E28: =HYPERLINK(Raw!G12,"Open Maps") -> Open Maps | F28: https://dhruvaspa.com/ | G28: Not available
A29: Dimple Beauty Salon (Only For Ladies) | B29: beauty parlor | C29: 4.6 | D29: =SUBSTITUTE(Raw!E53,"Phone:","") -> +91 98678 73647 | E29: =HYPERLINK(Raw!G53,"Open Maps") -> Open Maps | F29: Dimple beauty salon 17th anniversary 🎉🥳 #dimplebeautysalonkoparkhairane | G29: Looks good
A30: Doxa Salon | B30: hairdresser | C30: 4.9 | D30: =SUBSTITUTE(Raw!E33,"Phone:","") -> +91 85917 32960 | E30: =HYPERLINK(Raw!G33,"Open Maps") -> Open Maps | F30: Doxa Salon | G30: Basic, Website
A31: Elegance Hair & Beauty Salon | Hair & Beauty Studio | Nerul, Navi Mumbai | B31: beauty parlor | C31: 4.7 | D31: =SUBSTITUTE(Raw!E25,"Phone:","") -> +91 88799 41107 | E31: =HYPERLINK(Raw!G25,"Open Maps") -> Open Maps | F31: https://www.instagram.com/invites/contact/?igsh=13vik18hoh4o9&utm_content=1go0qx1 | G31: Not available
A32: Enrich Salon Sanpada Moraj Residency | B32: beauty parlor | C32: 4.8 | D32: =SUBSTITUTE(Raw!E68,"Phone:","") -> +91 91523 53000 | E32: =HYPERLINK(Raw!G68,"Open Maps") -> Open Maps | F32: Enrich Beauty | G32: Good
A33: Enrich Salon Seawoods - Navi Mumbai | B33: beauty parlor | C33: 4.6 | D33: =SUBSTITUTE(Raw!E43,"Phone:","") -> +91 91672 30097 | E33: =HYPERLINK(Raw!G43,"Open Maps") -> Open Maps | F33: Enrich Beauty | G33: Good
A34: Enrich Salon Vashi Sector 17 | B34: beauty parlor | C34: 4.5 | D34: =SUBSTITUTE(Raw!E39,"Phone:","") -> +91 91672 58614 | E34: =HYPERLINK(Raw!G39,"Open Maps") -> Open Maps | F34: Enrich Beauty | G34: Good
A35: Envi Salon & Spa - Inorbit Mall, Vashi | B35: hairdresser | C35: 4.6 | D35: =SUBSTITUTE(Raw!E42,"Phone:","") -> +91 80 6927 0009 | E35: =HYPERLINK(Raw!G42,"Open Maps") -> Open Maps | F35: Envi Salon And Spa | Premium Salon Services In Vashi, Navi Mumbai | G35: Bad, Website
A36: Envi Salon & Spa - Nexus Seawoods Mall | B36: hairdresser | C36: 4.6 | D36: =SUBSTITUTE(Raw!E117,"Phone:","") -> +91 80 6927 0008 | E36: =HYPERLINK(Raw!G109,"Open Maps") -> Open Maps | F36: Envi Salon And Spa | Premium Salon Services In Nerul, Navi Mumbai | G36: Bad, Website
A37: Evian salon vashi | B37: hairdresser | C37: 4.8 | D37: =SUBSTITUTE(Raw!E75,"Phone:","") -> +91 93218 56492 | E37: =HYPERLINK(Raw!G75,"Open Maps") -> Open Maps | F37: http://eviansalon.in/ | G37: Not available
A38: Gingerlin nx | B38: beauty parlor | C38: 4.9 | D38: =SUBSTITUTE(Raw!E26,"Phone:","") -> +91 98202 92472 | E38: =HYPERLINK(Raw!G26,"Open Maps") -> Open Maps | F38: Gingerlin NX Unisex Salon in Seawoods Nerul for Hair, Skin, Beauty | G38: Not user friendly, Website
A39: Girls Mumbai Spa Center | B39: Spa and Health Club | C39: 5 | D39: =SUBSTITUTE(Raw!E58,"Phone:","") -> +91 70559 88801 | E39: =HYPERLINK(Raw!G58,"Open Maps") -> Open Maps | F39: Navi Mumbai – Best Spa In Mumbai | G39: Nav bars are huge, Website
A40: Glam Studio by pramila | B40: beauty parlor | C40: 4.7 | D40: =SUBSTITUTE(Raw!E23,"Phone:","") -> +91 22 7966 4028 | E40: =HYPERLINK(Raw!G23,"Open Maps") -> Open Maps | F40: Glam studio by pramila | Skin | Hair | Nail | Makeup | Academy (@glam_studio_by_pramila) • Instagram photos and videos | G40: Not good, Digital Marketing
A41: Glamour Zone Studio (Ladies Salon) | B41: beauty parlor | C41: 4.8 | D41: =SUBSTITUTE(Raw!E15,"Phone:","") -> +91 90827 97847 | E41: =HYPERLINK(Raw!G15,"Open Maps") -> Open Maps | F41: 𝗚𝗹𝗮𝗺𝗼𝘂𝗿 𝗭𝗼𝗻𝗲 (@glamourzonestudio) • Instagram photos and videos | G41: Needs to be genzified, Digital Market
...
