Workbook

Sheet Notes
A1: Navi Mumbai Gyms — Lead Generation Dataset
A3: Total Records: 156 gyms located across Navi Mumbai.
A4: Data sourced from Google Maps, official websites, and public social media profiles.
A5: Includes gym name, address, contact details, email, website, social media, Google rating, and review count.
A6: Google Maps link is provided for each gym.
A7: Duplicate entries have been removed.
A8: Missing information is marked as "Not Available" or "Not publicly listed".
A9: Contact details include only information that is publicly accessible.
A10: Ratings and review counts are based on Google Maps at the time of data collection.
A11: Data has been organized in a structured Excel format with clearly labeled columns.
A12: Collected solely for lead generation and research purposes using publicly available information.

Sheet Raw
A1: Area/Location | B1: Full Address | C1: Contact Number | D1: Google Maps Link | E1: Google Rating | F1: Number of Reviews | G1: S.No | H1: Gym Name | I1: Email Address | J1: Website | K1: Instagram/Facebook | L1: Instagram/Facebook
A2: Vashi | B2: Shop no 16, Ground Floor, Satra Plaza, Palm Beach Rd, Phase 2, Sector 19D, Vashi, Navi Mumbai, Maharashtra 400703 | C2: 91 89767 22977 | D2: https://www.google.com/maps/place/?q=place_id:ChIJRa3DCunB5zsRoexUMQbO5T8 | E2: 4.8 | F2: 324 | G2: 1 | H2: Kenzo Fitness Vashi | Kenzo pilates | I2: Not Available | J2: Kenzo Fitness | K2: https://www.instagram.com/kenzofitnessindia/ | L2: https://www.facebook.com/kenzofitnessindia/
A3: Vashi | B3: 500 B Wing, 2nd Floor, Vashi Plaza, Plot No 80 and 81, Sector 17, Vashi, Navi Mumbai, Maharashtra 400703 | C3: 91 91670 00877 | D3: https://www.google.com/maps/place/?q=place_id:ChIJPUki99zB5zsR8aHLAUEdz0A | E3: 4.8 | F3: 175 | G3: 2 | H3: Ragnor Fitness Arena Vashi | I3: ragnorfitnessarena@gmail.com | J3: Not Available | K3: https://www.instagram.com/ragnorfitness/ | L3: https://www.facebook.com/ragnorfitness/
A4: Vashi | B4: 1st Floor, Krishna Residency, Plot no. 97, Sector 29, Vashi, Navi Mumbai, Maharashtra 400703 | C4: =+91 81692 32775 -> #ERROR! | D4: https://www.google.com/maps/place/?q=place_id:ChIJlYLQSZ7B5zsRApygL4U2J50 | E4: 4.9 | F4: 85 | G4: 3 | H4: Tungsten Fitness Club (TFC) - Vashi | I4: tungstenfitnessclub@gmail.com | J4: https://tungstenfitnessclub.com/ | K4: https://www.instagram.com/tungstenfitnessclub/ | L4: https://www.facebook.com/tungstenfitnessclub/
A5: Vashi | B5: Shop 1, 1st Floor, Ganesh Tower, Sector 1, Vashi, Navi Mumbai, Maharashtra 400703 | C5: =+91 78888 15252 -> #ERROR! | D5: https://www.google.com/maps/place/?q=place_id:ChIJ9flM1qzp5zsRY151CC6z8II | E5: 4.7 | F5: 122 | G5: 4 | H5: ZenXFit | I5: info.zenxfit@gmail.com | J5: https://zenxfit.in/ | K5: https://www.instagram.com/zenxfit/ | L5: Not Available
A6: Vashi | B6: 1st Floor, Marine Street, Juhu Nagar Rd, Sector 11, Vashi, Navi Mumbai, Maharashtra 400703 | C6: =+91 85915 03535 -> #ERROR! | D6: https://www.google.com/maps/place/?q=place_id:ChIJd5fmQDHB5zsRxEfVDyJjtYI | E6: 4.6 | F6: 159 | G6: 5 | H6: Aqua Fitness Club | I6: Not Available | J6: Not Available | K6: Not Available | L6: Not Available
A7: Vashi | B7: Plot No 3, near Palm Beach Galleria Mall, Phase 2, Sector 19D, Vashi, Navi Mumbai, Maharashtra 400703 | C7: =+91 89281 15003 -> #ERROR! | D7: https://www.google.com/maps/place/?q=place_id:ChIJuRR9kRLB5zsRdgJoKfV6BTU | E7: 4.8 | F7: 319 | G7: 6 | H7: CrossBox Fitness | I7: Not Available | J7: https://crossboxfitness.in/ | K7: https://www.instagram.com/crossboxfitness/ | L7: https://www.facebook.com/crossboxfitness/
A8: Vashi | B8: Plot 75, Vardhaman Market, 1st Floor, Sector 17, Vashi, Navi Mumbai, Maharashtra 400703 | C8: =+91 98336 66622 -> #ERROR! | D8: https://www.google.com/maps/place/?q=place_id:ChIJE2g-4knB5zsR3N3xQNJQfKw | E8: 4.6 | F8: 524 | G8: 7 | H8: Intense Fitness Club (IFC Gym) | I8: Not Available | J8: Not Available | K8: https://www.instagram.com/intensefitnessclub/ | L8: https://www.facebook.com/intensefitnessclub/
A9: Vashi | B9: 1st Floor, Mahavir Center, Plot no. 77, Sector 17, Vashi, Navi Mumbai, Maharashtra 400703 | C9: =+91 87792 72114 -> #ERROR! | D9: https://www.google.com/maps/place/?q=place_id:ChIJY2hQkjTB5zsRHAwrydyUfwQ | E9: 4.8 | F9: 383 | G9: 8 | H9: Mustangs Fitness Centre | Vashi | I9: sales@mustangs.in | J9: Not Available | K9: https://www.instagram.com/mustangsfitnesscentre/ | L9: https://www.facebook.com/mustangsfitnesscentre/
A10: Vashi | B10: 1st Floor, near Gaondevi Maidan Road, Sector 11, Vashi, Navi Mumbai, Maharashtra 400703 | C10: =+91 87796 72100 -> #ERROR! | D10: https://www.google.com/maps/place/?q=place_id:ChIJDdLEj37B5zsRQtOZXyj14MU | E10: 4.8 | F10: 349 | G10: 9 | H10: Ragnor Fitness Vashi 24/7 | I10: ragnorfitnessarena@gmail.com | J10: Not Available | K10: https://www.instagram.com/ragnorfitness/ | L10: https://www.facebook.com/ragnorfitness/
A11: Vashi | B11: 40, Palm Beach Rd, Phase 2, Sector 19E, Vashi, Navi Mumbai, Maharashtra 400703 | C11: =+91 79000 31593 -> #ERROR! | D11: https://www.google.com/maps/place/?q=place_id:ChIJ63v9_Q7B5zsRNwKopMhDhEU | E11: 4.6 | F11: 108 | G11: 10 | H11: Seven Star Fitness Studio | I11: Not Available | J11: Not Available | K11: https://www.instagram.com/sevenstarfitnessstudio/ | L11: https://www.facebook.com/sevenstarfitnessstudio/
A12: Nerul | B12: 1st Floor, Hawares Centurion Mall, Nerul East, Sector 19A, Nerul, Navi Mumbai, Maharashtra 400706 | C12: =+91 91374 64261 -> #ERROR! | D12: https://www.google.com/maps/place/?q=place_id:ChIJ-wkhrL7D5zsRefWTOo92UsY | E12: 4.7 | F12: 556 | G12: 11 | H12: Oneabove Fitness Nerul | I12: ig@talwalkars.net | J12: https://oneabovefitness.com/ | K12: https://www.instagram.com/oneabovefitness/ | L12: https://www.facebook.com/oneabovefitness/
A13: Nerul | B13: Unit No. 7, Akshar, Plot no. C-1, Seawoods East, Nerul East, Sector 23, Nerul, Navi Mumbai, Maharashtra 400706 | C13: =+91 91676 77002 -> #ERROR! | D13: https://www.google.com/maps/place/?q=place_id:ChIJD7B7TJTD5zsRXvgCTXcxMCU | E13: 4.9 | F13: 564 | G13: 12 | H13: Tungsten Fitness Club (TFC) - Nerul | I13: tungstenfitnessclub@gmail.com | J13: https://tungstenfitness.in/ | K13: https://www.instagram.com/tungstenfitnessclub/ | L13: https://www.facebook.com/tungstenfitnessclub/
A14: Nerul | B14: 1st Floor, Amrita Sadan, Nerul East, Sector 22, Nerul, Navi Mumbai, Maharashtra 400706 | C14: =+91 91374 54549 -> #ERROR! | D14: https://www.google.com/maps/place/?q=place_id:ChIJE7x_46LD5zsR8IWA6yWrsnU | E14: 4.6 | F14: 207 | G14: 13 | H14: Ragnor Fitness Nerul 24/7 | I14: ragnorfitnessarena@gmail.com | J14: Not Available | K14: https://www.instagram.com/ragnorfitness/ | L14: https://www.facebook.com/ragnorfitness/
A15: Nerul | B15: Plot No 5 & 5A, Sector No 28, Nerul, Navi Mumbai, Maharashtra 400706 | C15: =+91 93727 70136 -> #ERROR! | D15: https://www.google.com/maps/place/?q=place_id:ChIJ0QJ4GpXD5zsRMOeBKWTMJug | E15: 4 | F15: 2839 | G15: 14 | H15: Nerul Gymkhana | I15: info@nerulgymkhana.com | J15: https://www.nerulgymkhana.com/ | K15: Not Available | L15: https://www.facebook.com/NerulGymkhana/
A16: Nerul | B16: Plot P11, Sector 14 Nerul Rd, Sector 14, Nerul, Navi Mumbai, Maharashtra 400706 | C16: =+91 95949 18007 -> #ERROR! | D16: https://www.google.com/maps/place/?q=place_id:ChIJ0-V5YlPD5zsRxkc8NJ8CbKg | E16: 4.8 | F16: 2589 | G16: 15 | H16: Be More Fit Gym | I16: Not Available | J16: Not Available | K16: https://www.instagram.com/bemorefitgym/ | L16: https://www.facebook.com/bemorefitgym/
A17: Nerul | B17: Shree Samarth Krupa, 464, near NMMC Hospital, Sec-20, Nerul, Navi Mumbai, Maharashtra 400706 | C17: =+91 98336 99346 -> #ERROR! | D17: https://www.google.com/maps/place/?q=place_id:ChIJ94Tn6-nD5zsRaKRMT_gBNiY | E17: 4.7 | F17: 862 | G17: 16 | H17: Vulkan Health Club | I17: Not Available | J17: Not Available | K17: https://www.instagram.com/vulkanhealthclub/ | L17: https://www.facebook.com/vulkanhealthclub/
A18: Nerul | B18: Sukhshanti Society, Plot no A-7, Nerul East, Sector 20, Nerul, Navi Mumbai, Maharashtra 400706 | C18: =+91 95945 75707 -> #ERROR! | D18: https://www.google.com/maps/place/?q=place_id:ChIJ1xzHpjrD5zsRNP8iVooisnU | E18: 4.9 | F18: 633 | G18: 17 | H18: Akhada Unisex Fitness Zone | I18: Not Available | J18: Not Available | K18: https://www.instagram.com/akhadafitnesszone/ | L18: https://www.facebook.com/akhadafitnesszone/
A19: Nerul | B19: Sector No 28, Nerul Gymkhana, Plot No 5A, Nerul East, Sector 28, Nerul, Navi Mumbai, Maharashtra 400706 | C19: =+91 90049 99948 -> #ERROR! | D19: https://www.google.com/maps/place/?q=place_id:ChIJQ8i44BbD5zsRGOv9keZMD2c | E19: 4.9 | F19: 79 | G19: 18 | H19: Passion Gym | I19: Not Available | J19: Not Available | K19: Not Available | L19: Not Available
A20: Nerul | B20: Vignahar Heights, Plot No. 5 & 6 Sec 14, Palm Beach Rd, Nerul West, Nerul, Navi Mumbai, Maharashtra 400706 | C20: =+91 88504 31372 -> #ERROR! | D20: https://www.google.com/maps/place/?q=place_id:ChIJa-lDh6HB5zsRBsOFyckSv0Q | E20: 4.5 | F20: 103 | G20: 19 | H20: Tornado Fitness | I20: Not Available | J20: Not Available | K20: https://www.instagram.com/tornadofitness24x7/ | L20: https://www.facebook.com/tornadofitness24x7/
A21: Nerul | B21: Bhanushali wadi, Nerul East, Sector 19A, Nerul, Navi Mumbai, Maharashtra 400706 | C21: =+91 91376 47501 -> #ERROR! | D21: https://www.google.com/maps/place/?q=place_id:ChIJBWAwQe7D5zsRYQLyaH3jazA | E21: 4.6 | F21: 174 | G21: 20 | H21: SHREDX FITNESS NERUL | I21: Not Available | J21: Not Available | K21: https://www.instagram.com/shredxfitness/ | L21: https://www.facebook.com/shredxfitness/
A22: Kharghar | B22: 1st Floor, Ravechi Heights, Sector 7, Plot 25, Kharghar, Panvel, Maharashtra 410210 | C22: =+91 84335 89999 -> #ERROR! | D22: https://www.google.com/maps/place/?q=place_id:ChIJJ07Q_H3D5zsRgsu7ZIP0rec | E22: 4.7 | F22: 1340 | G22: 21 | H22: COREGYM | I22: info@coregym.co.in | J22: https://coregym.co.in/ | K22: https://www.instagram.com/coregymindia/ | L22: https://www.facebook.com/coregymindia/
A23: Kharghar | B23: 1st Floor, opp. Raghunath Vihar, Block G, Sector 13, Kharghar, Panvel, Maharashtra 410210 | C23: =+91 83696 08923 -> #ERROR! | D23: https://www.google.com/maps/place/?q=place_id:ChIJzUFViOTD5zsRBqfbuu2f6TE | E23: 4.9 | F23: 169 | G23: 22 | H23: Traance.fit | I23: info@traance.fit | J23: https://traance.fit/ | K23: https://www.instagram.com/traance.fit/ | L23: https://www.facebook.com/traance.fit/
A24: Kharghar | B24: Ashirwad Heights, Plot No. 7, Sector 18 Rd, Sector 18, Kharghar, Mumbai, Panvel, Maharashtra 410210 | C24: =+91 88792 39044 -> #ERROR! | D24: https://www.google.com/maps/place/?q=place_id:ChIJ7aQUWnXD5zsRtfplTvXQeJo | E24: 4.7 | F24: 342 | G24: 23 | H24: Body Power (cult.fit) - Kharghar | I24: Not Available | J24: https://www.cult.fit/fitness/centers/body-power-kharghar | K24: https://www.instagram.com/cultfitofficial/ | L24: https://www.facebook.com/cultfitofficial/
A25: Kharghar | B25: 1st Floor, Tiara Shopping Complex, Block G, Sector 13, Kharghar, Panvel, Maharashtra 410210 | C25: =+91 91461 91916 -> #ERROR! | D25: https://www.google.com/maps/place/?q=place_id:ChIJwazG-erD5zsR5CUOaenen0o | E25: 4.8 | F25: 1284 | G25: 24 | H25: Ragnor Fitness Kharghar | I25: ragnorfitnessarena@gmail.com | J25: Not Available | K25: https://www.instagram.com/ragnorfitness/ | L25: https://www.facebook.com/ragnorfitness/
A26: Kharghar | B26: 1st Floor, Garden Court, Sector 35E, Kharghar, Panvel, Maharashtra 410210 | C26: =+91 86938 39862 -> #ERROR! | D26: https://www.google.com/maps/place/?q=place_id:ChIJFyaSqPjB5zsRKqYnQztKruY | E26: 4.7 | F26: 435 | G26: 25 | H26: FOR LIFE FITNESS | I26: Not Available | J26: Not Available | K26: https://www.instagram.com/forlifefitness24x7/ | L26: https://www.facebook.com/forlifefitness24x7/
A27: Kharghar | B27: Aashirwad rowhouse, Plot F34, Block G, Sector 12, Kharghar, Panvel, Maharashtra 410210 | C27: =+91 75079 99555 -> #ERROR! | D27: https://www.google.com/maps/place/?q=place_id:ChIJZXSKDdTD5zsRLX7AuGvEcbo | E27: 4.9 | F27: 188 | G27: 26 | H27: Zara's Fitness | I27: Not Available | J27: Not Available | K27: https://www.instagram.com/zarasfitness/ | L27: https://www.facebook.com/zarasfitness/
A28: Kharghar | B28: 9th floor, The Pacific, Block G, Sector 13, Kharghar, Panvel, Maharashtra 410210 | C28: =+91 84510 96123 -> #ERROR! | D28: https://www.google.com/maps/place/?q=place_id:ChIJZSnPE_jD5zsRsALyNTxE2Io | E28: 4.3 | F28: 184 | G28: 27 | H28: Shark Fitness | I28: Not Available | J28: Not Available | K28: https://www.instagram.com/sharkfitnesskharghar/ | L28: https://www.facebook.com/sharkfitnesskharghar/
A29: Kharghar | B29: Shop no 7, Mita heights, Plot No. 51/B, Sector 20, Kharghar, Panvel, Maharashtra 410210 | C29: =+91 88283 08182 -> #ERROR! | D29: https://www.google.com/maps/place/?q=place_id:ChIJTfLYGgnD5zsR18cYIlK3lb4 | E29: 5 | F29: 191 | G29: 28 | H29: Revamp Fitness | I29: Not Available | J29: Not Available | K29: https://www.instagram.com/revampfitnesskharghar/ | L29: https://www.facebook.com/revampfitnesskharghar/
A30: Kharghar | B30: Shop 08/09, Sai Sakshaat society, Sector-06, Kharghar, Panvel, Maharashtra 410210 | C30: =+91 89286 03693 -> #ERROR! | D30: https://www.google.com/maps/place/?q=place_id:ChIJq6qqajzC5zsRd-Ghq6IcgCw | E30: 4.8 | F30: 136 | G30: 29 | H30: Aesthetic Fitness | I30: Not Available | J30: Not Available | K30: https://www.instagram.com/aestheticfitnesskharghar/ | L30: Not Available
A31: Kharghar | B31: 3rd Floor, Prime Mall Ln, Sector 12, Kharghar, Panvel, Maharashtra 410210 | C31: =+91 99676 41791 -> #ERROR! | D31: https://www.google.com/maps/place/?q=place_id:ChIJ3WMtYcTD5zsRUXFmuL8o3UY | E31: 4.7 | F31: 407 | G31: 30 | H31: Arise Fitness Kharghar | I31: Not Available | J31: Not Available | K31: https://www.instagram.com/arisefitnesskharghar/ | L31: https://www.facebook.com/arisefitnesskharghar/
A32: CBD Belapur | B32: Level 3, Mayuresh square, Plot no. 17, Sector 15, CBD Belapur, Navi Mumbai, Maharashtra 400614 | C32: =+91 93213 98773 -> #ERROR! | D32: https://www.google.com/maps/place/?q=place_id:ChIJpdRze-TD5zsR5y6jX_uS3-U | E32: 4.8 | F32: 357 | G32: 31 | H32: Plus Fitness Belapur | I32: belapur@plusfitness.co.in | J32: https://www.plusfitness.co.in/gyms/belapur/ | K32: https://www.instagram.com/plusfitnessindia/ | L32: https://www.facebook.com/PlusFitnessIndia/
A33: CBD Belapur | B33: 2nd Floor, NMS Titanium, Sector 15, CBD Belapur, Navi Mumbai, Maharashtra 400614 | C33: =+91 90225 54999 -> #ERROR! | D33: https://www.google.com/maps/place/?q=place_id:ChIJZ96XEarD5zsR3KguAzsdDG8 | E33: 4.7 | F33: 392 | G33: 32 | H33: Gym Arenaa Fitness And Wellness Club | I33: gymarenaa163@gmail.com | J33: https://gymarenaa.in/ | K33: Not Available | L33: Not Available
A34: CBD Belapur | B34: Shop no 28-31, F type, Sector - 03 Market, CBD Belapur, Navi Mumbai, Maharashtra 400614 | C34: Not publicly listed | D34: https://www.google.com/maps/place/?q=place_id:ChIJC-6IZbjD5zsR8DB6niiDU0Q | E34: 4.8 | F34: 100 | G34: 33 | H34: MP's Fitness World (Sector 3) | I34: Not Available | J34: Not Available | K34: https://www.instagram.com/mps_fitness_world/ | L34: https://www.facebook.com/mpsfitnessworld
A35: CBD Belapur | B35: Shop-1/2, Arenja Towers, Sector 11, CBD Belapur, Navi Mumbai, Maharashtra 400614 | C35: =+91 98214 49296 -> #ERROR! | D35: https://www.google.com/maps/place/?q=place_id:ChIJAQAA8E3C5zsR_3BDYp3wJTM | E35: 4.8 | F35: 118 | G35: 34 | H35: Image Fitness Club | I35: Not Available | J35: Not Available | K35: Not Available | L35: Not Available
A36: CBD Belapur | B36: 403, Plot No.7, Chamber 2, Arenja Plaza, Sector 15, CBD Belapur, Navi Mumbai, Maharashtra 400614 | C36: =+91 77688 79921 -> #ERROR! | D36: https://www.google.com/maps/place/?q=place_id:ChIJWxqoy9TD5zsRii1UDYEy1Xo | E36: 5 | F36: 209 | G36: 35 | H36: Perfect Health & Fitness | I36: Not Available | J36: Not Available | K36: Not Available | L36: Not Available
A37: CBD Belapur | B37: Shop No: 6, Rajkamal Bayside, Plot No: 28, Sector 15, CBD Belapur, Navi Mumbai, Maharashtra 400614 | C37: =+91 80977 34167 -> #ERROR! | D37: https://www.google.com/maps/place/?q=place_id:ChIJ58yNSFjD5zsRcGRVeloljXA | E37: 4.7 | F37: 260 | G37: 36 | H37: Fitness Freak | I37: Not Available | J37: Not Available | K37: Not Available | L37: Not Available
A38: CBD Belapur | B38: C-4, Kali Mata Mandir Rd, Sector 8B, CBD Belapur, Navi Mumbai, Maharashtra 400614 | C38: =+91 90828 20128 -> #ERROR! | D38: https://www.google.com/maps/place/?q=place_id:ChIJpUpPAt_D5zsRU0z82JwQs1s | E38: 4.3 | F38: 46 | G38: 37 | H38: MP's FITNESS WORLD (Sector 8B) | I38: Not Available | J38: Not Available | K38: https://www.instagram.com/mps_fitness_world/ | L38: https://www.facebook.com/mpsfitnessworld
A39: CBD Belapur | B39: Plot no-92, Sector 8A, CBD Belapur, Navi Mumbai, Maharashtra 400614 | C39: =+91 93723 00166 -> #ERROR! | D39: https://www.google.com/maps/place/?q=place_id:ChIJ71OfJ_7D5zsRi_5zskjiDoE | E39: 4.6 | F39: 134 | G39: 38 | H39: FOCUS THE FITNESS | I39: Not Available | J39: Not Available | K39: Not Available | L39: Not Available
A40: CBD Belapur | B40: 44, Shop no.12, Progressive Sea Lounge, Sector 15, CBD Belapur, Navi Mumbai, Maharashtra 400614 | C40: =+91 90829 55754 -> #ERROR! | D40: https://www.google.com/maps/place/?q=place_id:ChIJ4T5tIkrD5zsRg-b0KMf1J1U | E40: 5 | F40: 60 | G40: 39 | H40: Panada Fitness Centre | I40: Not Available | J40: Not Available | K40: Not Available | L40: Not Available
...

Sheet Navi Gym Lead
A1: S.No | B1: Gym Name | C1: Area/Location | D1: Full Address | E1: Google Map | F1: Contact Number | G1: Email Address | H1: Website | I1: Instagram | J1: Facebook | K1: Google Rating | L1: Number of Reviews
A2: 1 | B2: 2 More Fitness Gym | C2: Rabale | D2: Trimbakeshwar Apt, Sector 30D, near Balaji Park, Sector 30, Rabale, Navi Mumbai, Maharashtra 400701 | E2: =IF(OR(Raw!D152="",LOWER(Raw!D152)="not available"),"Not Available",HYPERLINK(Raw!D152,"Maps")) -> Maps | F2: 96193 97773 | G2: Not Available | H2: Not Available | I2: Not Available | J2: Not Available | K2: 4.8 | L2: 157
A3: 2 | B3: 4 Fitness gym | C3: Ghansoli | D3: 1st floor, Plot no. 14, Sector 8, Ghansoli, Navi Mumbai, Maharashtra 400701 | E3: =IF(OR(Raw!D73="",LOWER(Raw!D73)="not available"),"Not Available",HYPERLINK(Raw!D73,"Maps")) -> Maps | F3: 79773 94068 | G3: Not Available | H3: Not Available | I3: =IF(OR(Raw!K73="",LOWER(Raw!K73)="not available"),"Not Available",HYPERLINK(Raw!K73,"Instagram")) -> Not Available | J3: =IF(OR(Raw!L73="",LOWER(Raw!L73)="not available"),"Not Available",HYPERLINK(Raw!L73,"Facebook")) -> Not Available | K3: 4.8 | L3: 36
A4: 3 | B4: 4FIT GYM - EMPOWERING BODIES | C4: Kopar Khairane | D4: 1st floor, Balaji Exotica, Plot no. 31, Sector 9, Kopar Khairane, Navi Mumbai, Maharashtra 400709 | E4: =IF(OR(Raw!D57="",LOWER(Raw!D57)="not available"),"Not Available",HYPERLINK(Raw!D57,"Maps")) -> Maps | F4: 95944 14178 | G4: Not Available | H4: Not Available | I4: =IF(OR(Raw!K57="",LOWER(Raw!K57)="not available"),"Not Available",HYPERLINK(Raw!K57,"Instagram")) -> Not Available | J4: =IF(OR(Raw!L57="",LOWER(Raw!L57)="not available"),"Not Available",HYPERLINK(Raw!L57,"Facebook")) -> Not Available | K4: 4.7 | L4: 136
A5: 4 | B5: AEI Fitness | C5: Ulwe | D5: 8th Floor, NMS Icon, Plot No 194, Sector 19, Ulwe, Navi Mumbai, Maharashtra 410206 | E5: =IF(OR(Raw!D135="",LOWER(Raw!D135)="not available"),"Not Available",HYPERLINK(Raw!D135,"Maps")) -> Maps | F5: 77158 03788 | G5: Not Available | H5: Not Available | I5: =IF(OR(Raw!K135="",LOWER(Raw!K135)="not available"),"Not Available",HYPERLINK(Raw!K135,"Instagram")) -> Instagram | J5: =IF(OR(Raw!L135="",LOWER(Raw!L135)="not available"),"Not Available",HYPERLINK(Raw!L135,"Facebook")) -> Facebook | K5: 4.8 | L5: 265
A6: 5 | B6: Aesthetic Arena Fitness Center | C6: Panvel | D6: Shop No 06, Aditya Vihar CHS, Mahatma Phule Rd, Old Panvel, Panvel, Maharashtra 410206 | E6: =IF(OR(Raw!D101="",LOWER(Raw!D101)="not available"),"Not Available",HYPERLINK(Raw!D101,"Maps")) -> Maps | F6: 85912 22344 | G6: Not Available | H6: Not Available | I6: =IF(OR(Raw!K101="",LOWER(Raw!K101)="not available"),"Not Available",HYPERLINK(Raw!K101,"Instagram")) -> Instagram | J6: =IF(OR(Raw!L101="",LOWER(Raw!L101)="not available"),"Not Available",HYPERLINK(Raw!L101,"Facebook")) -> Not Available | K6: 4.6 | L6: 136
A7: 6 | B7: Aesthetic Fitness | C7: Kharghar | D7: Shop 08/09, Sai Sakshaat society, Sector-06, Kharghar, Panvel, Maharashtra 410210 | E7: =IF(OR(Raw!D30="",LOWER(Raw!D30)="not available"),"Not Available",HYPERLINK(Raw!D30,"Maps")) -> Maps | F7: 89286 03693 | G7: Not Available | H7: Not Available | I7: =IF(OR(Raw!K30="",LOWER(Raw!K30)="not available"),"Not Available",HYPERLINK(Raw!K30,"Instagram")) -> Instagram | J7: =IF(OR(Raw!L30="",LOWER(Raw!L30)="not available"),"Not Available",HYPERLINK(Raw!L30,"Facebook")) -> Not Available | K7: 4.8 | L7: 136
A8: 7 | B8: Akhada Unisex Fitness Zone | C8: Nerul | D8: Sukhshanti Society, Plot no A-7, Nerul East, Sector 20, Nerul, Navi Mumbai, Maharashtra 400706 | E8: =IF(OR(Raw!D18="",LOWER(Raw!D18)="not available"),"Not Available",HYPERLINK(Raw!D18,"Maps")) -> Maps | F8: 95945 75707 | G8: Not Available | H8: Not Available | I8: =IF(OR(Raw!K18="",LOWER(Raw!K18)="not available"),"Not Available",HYPERLINK(Raw!K18,"Instagram")) -> Instagram | J8: =IF(OR(Raw!L18="",LOWER(Raw!L18)="not available"),"Not Available",HYPERLINK(Raw!L18,"Facebook")) -> Facebook | K8: 4.9 | L8: 633
A9: 8 | B9: Anytime Fitness | C9: Sanpada | D9: Kshitij Towers, Palm Beach Service Road, Sector 19, Sanpada, Navi Mumbai, Maharashtra 400705 | E9: =IF(OR(Raw!D84="",LOWER(Raw!D84)="not available"),"Not Available",HYPERLINK(Raw!D84,"Maps")) -> Maps | F9: 95209 82437 | G9: Not Available | H9: Anytime Fitness | I9: =IF(OR(Raw!K84="",LOWER(Raw!K84)="not available"),"Not Available",HYPERLINK(Raw!K84,"Instagram")) -> Instagram | J9: =IF(OR(Raw!L84="",LOWER(Raw!L84)="not available"),"Not Available",HYPERLINK(Raw!L84,"Facebook")) -> Facebook | K9: 4.8 | L9: 66
A10: 9 | B10: Aqua Fitness Club | C10: Vashi | D10: 1st Floor, Marine Street, Juhu Nagar Rd, Sector 11, Vashi, Navi Mumbai, Maharashtra 400703 | E10: =IF(OR(Raw!D6="",LOWER(Raw!D6)="not available"),"Not Available",HYPERLINK(Raw!D6,"Maps")) -> Maps | F10: 85915 03535 | G10: Not Available | H10: Not Available | I10: =IF(OR(Raw!K6="",LOWER(Raw!K6)="not available"),"Not Available",HYPERLINK(Raw!K6,"Instagram")) -> Not Available | J10: =IF(OR(Raw!L6="",LOWER(Raw!L6)="not available"),"Not Available",HYPERLINK(Raw!L6,"Facebook")) -> Not Available | K10: 4.6 | L10: 159
A11: 10 | B11: Arise Fitness Kharghar | C11: Kharghar | D11: 3rd Floor, Prime Mall Ln, Sector 12, Kharghar, Panvel, Maharashtra 410210 | E11: =IF(OR(Raw!D31="",LOWER(Raw!D31)="not available"),"Not Available",HYPERLINK(Raw!D31,"Maps")) -> Maps | F11: 99676 41791 | G11: Not Available | H11: Not Available | I11: =IF(OR(Raw!K31="",LOWER(Raw!K31)="not available"),"Not Available",HYPERLINK(Raw!K31,"Instagram")) -> Instagram | J11: =IF(OR(Raw!L31="",LOWER(Raw!L31)="not available"),"Not Available",HYPERLINK(Raw!L31,"Facebook")) -> Facebook | K11: 4.7 | L11: 407
A12: 11 | B12: Be More Fit Gym | C12: Nerul | D12: Plot P11, Sector 14 Nerul Rd, Sector 14, Nerul, Navi Mumbai, Maharashtra 400706 | E12: =IF(OR(Raw!D16="",LOWER(Raw!D16)="not available"),"Not Available",HYPERLINK(Raw!D16,"Maps")) -> Maps | F12: 95949 18007 | G12: Not Available | H12: Not Available | I12: =IF(OR(Raw!K16="",LOWER(Raw!K16)="not available"),"Not Available",HYPERLINK(Raw!K16,"Instagram")) -> Instagram | J12: =IF(OR(Raw!L16="",LOWER(Raw!L16)="not available"),"Not Available",HYPERLINK(Raw!L16,"Facebook")) -> Facebook | K12: 4.8 | L12: 2589
A13: 12 | B13: BEAST FITNESS | C13: Kalamboli | D13: Shop 02, 1st Floor, Anchit Towers, Roadpali, Kalamboli, Panvel, Maharashtra 410218 | E13: =IF(OR(Raw!D122="",LOWER(Raw!D122)="not available"),"Not Available",HYPERLINK(Raw!D122,"Maps")) -> Maps | F13: 81044 84873 | G13: Not Available | H13: Not Available | I13: =IF(OR(Raw!K122="",LOWER(Raw!K122)="not available"),"Not Available",HYPERLINK(Raw!K122,"Instagram")) -> Not Available | J13: =IF(OR(Raw!L122="",LOWER(Raw!L122)="not available"),"Not Available",HYPERLINK(Raw!L122,"Facebook")) -> Not Available | K13: 4.6 | L13: 136
A14: 13 | B14: BHAGAT FITNESS GYM | C14: Panvel | D14: Takka Village, near Sai Baba Mandir, Old Panvel, Takka Colony, Panvel, Maharashtra 410206 | E14: =IF(OR(Raw!D102="",LOWER(Raw!D102)="not available"),"Not Available",HYPERLINK(Raw!D102,"Maps")) -> Maps | F14: 98206 57515 | G14: Not Available | H14: Not Available | I14: =IF(OR(Raw!K102="",LOWER(Raw!K102)="not available"),"Not Available",HYPERLINK(Raw!K102,"Instagram")) -> Not Available | J14: =IF(OR(Raw!L102="",LOWER(Raw!L102)="not available"),"Not Available",HYPERLINK(Raw!L102,"Facebook")) -> Not Available | K14: 4.9 | L14: 485
A15: 14 | B15: Bhagwat Gym | C15: New Panvel | D15: Plot no.- A, 33, Sector 6, New Panvel East, Panvel, Maharashtra 410206 | E15: =IF(OR(Raw!D110="",LOWER(Raw!D110)="not available"),"Not Available",HYPERLINK(Raw!D110,"Maps")) -> Maps | F15: Not publicly listed | G15: Not Available | H15: Not Available | I15: =IF(OR(Raw!K110="",LOWER(Raw!K110)="not available"),"Not Available",HYPERLINK(Raw!K110,"Instagram")) -> Not Available | J15: =IF(OR(Raw!L110="",LOWER(Raw!L110)="not available"),"Not Available",HYPERLINK(Raw!L110,"Facebook")) -> Not Available | K15: 5 | L15: 25
A16: 15 | B16: Body Power (cult.fit) - Kharghar | C16: Kharghar | D16: Ashirwad Heights, Plot No. 7, Sector 18 Rd, Sector 18, Kharghar, Mumbai, Panvel, Maharashtra 410210 | E16: =IF(OR(Raw!D24="",LOWER(Raw!D24)="not available"),"Not Available",HYPERLINK(Raw!D24,"Maps")) -> Maps | F16: 88792 39044 | G16: Not Available | H16: https://www.cult.fit/fitness/centers/body-power-kharghar | I16: =IF(OR(Raw!K24="",LOWER(Raw!K24)="not available"),"Not Available",HYPERLINK(Raw!K24,"Instagram")) -> Instagram | J16: =IF(OR(Raw!L24="",LOWER(Raw!L24)="not available"),"Not Available",HYPERLINK(Raw!L24,"Facebook")) -> Facebook | K16: 4.7 | L16: 342
A17: 16 | B17: Body Power Gym (Kamothe Sector 36) | C17: Kamothe | D17: 1st Floor, Ambe Shraddha Building, Plot No 4, Sector 36, Kamothe, Panvel, Maharashtra 410209 | E17: =IF(OR(Raw!D117="",LOWER(Raw!D117)="not available"),"Not Available",HYPERLINK(Raw!D117,"Maps")) -> Maps | F17: 90829 78262 | G17: Not Available | H17: Not Available | I17: =IF(OR(Raw!K117="",LOWER(Raw!K117)="not available"),"Not Available",HYPERLINK(Raw!K117,"Instagram")) -> Not Available | J17: =IF(OR(Raw!L117="",LOWER(Raw!L117)="not available"),"Not Available",HYPERLINK(Raw!L117,"Facebook")) -> Not Available | K17: 4.3 | L17: 167
A18: 17 | B18: Body Power Gym (Sector 9 Kamothe) | C18: Kamothe | D18: 1st Floor, Trimurti Enclave, Plot No. 6, Sector 9, Kamothe, Panvel, Maharashtra 410209 | E18: =IF(OR(Raw!D119="",LOWER(Raw!D119)="not available"),"Not Available",HYPERLINK(Raw!D119,"Maps")) -> Maps | F18: 70458 13690 | G18: Not Available | H18: Not Available | I18: =IF(OR(Raw!K119="",LOWER(Raw!K119)="not available"),"Not Available",HYPERLINK(Raw!K119,"Instagram")) -> Not Available | J18: =IF(OR(Raw!L119="",LOWER(Raw!L119)="not available"),"Not Available",HYPERLINK(Raw!L119,"Facebook")) -> Not Available | K18: 4.4 | L18: 391
A19: 18 | B19: BODY VISION FITNESS | C19: Airoli | D19: Shop no. 1, Radha Krishna Apartment, Sector 9, Airoli, Navi Mumbai, Maharashtra 400708 | E19: =IF(OR(Raw!D50="",LOWER(Raw!D50)="not available"),"Not Available",HYPERLINK(Raw!D50,"Maps")) -> Maps | F19: 73403 04141 | G19: Not Available | H19: Not Available | I19: =IF(OR(Raw!K50="",LOWER(Raw!K50)="not available"),"Not Available",HYPERLINK(Raw!K50,"Instagram")) -> Instagram | J19: =IF(OR(Raw!L50="",LOWER(Raw!L50)="not available"),"Not Available",HYPERLINK(Raw!L50,"Facebook")) -> Facebook | K19: 4.8 | L19: 140
A20: 19 | B20: CLUB 90 | C20: Seawoods | D20: 1st Floor, Merchant Classic Building, Plot No.3, Sector 48-A, Seawoods, Navi Mumbai, Maharashtra 400706 | E20: =IF(OR(Raw!D93="",LOWER(Raw!D93)="not available"),"Not Available",HYPERLINK(Raw!D93,"Maps")) -> Maps | F20: 98193 61809 | G20: Not Available | H20: Not Available | I20: =IF(OR(Raw!K93="",LOWER(Raw!K93)="not available"),"Not Available",HYPERLINK(Raw!K93,"Instagram")) -> Instagram | J20: =IF(OR(Raw!L93="",LOWER(Raw!L93)="not available"),"Not Available",HYPERLINK(Raw!L93,"Facebook")) -> Facebook | K20: 4.8 | L20: 596
A21: 20 | B21: Core fitness | C21: Kopar Khairane | D21: 56, Gyan Vikas Road, Sector 17, Kopar Khairane, Navi Mumbai, Maharashtra 400709 | E21: =IF(OR(Raw!D62="",LOWER(Raw!D62)="not available"),"Not Available",HYPERLINK(Raw!D62,"Maps")) -> Maps | F21: Not publicly listed | G21: Not Available | H21: Not Available | I21: =IF(OR(Raw!K62="",LOWER(Raw!K62)="not available"),"Not Available",HYPERLINK(Raw!K62,"Instagram")) -> Not Available | J21: =IF(OR(Raw!L62="",LOWER(Raw!L62)="not available"),"Not Available",HYPERLINK(Raw!L62,"Facebook")) -> Not Available | K21: 4.3 | L21: 35
A22: 21 | B22: COREGYM | C22: Kharghar | D22: 1st Floor, Ravechi Heights, Sector 7, Plot 25, Kharghar, Panvel, Maharashtra 410210 | E22: =IF(OR(Raw!D22="",LOWER(Raw!D22)="not available"),"Not Available",HYPERLINK(Raw!D22,"Maps")) -> Maps | F22: 84335 89999 | G22: info@coregym.co.in | H22: Core Gym | I22: =IF(OR(Raw!K22="",LOWER(Raw!K22)="not available"),"Not Available",HYPERLINK(Raw!K22,"Instagram")) -> Instagram | J22: =IF(OR(Raw!L22="",LOWER(Raw!L22)="not available"),"Not Available",HYPERLINK(Raw!L22,"Facebook")) -> Facebook | K22: 4.7 | L22: 1340
A23: 22 | B23: CrossBox Fitness | C23: Vashi | D23: Plot No 3, near Palm Beach Galleria Mall, Phase 2, Sector 19D, Vashi, Navi Mumbai, Maharashtra 400703 | E23: =IF(OR(Raw!D7="",LOWER(Raw!D7)="not available"),"Not Available",HYPERLINK(Raw!D7,"Maps")) -> Maps | F23: 89281 15003 | G23: Not Available | H23: Not Available | I23: =IF(OR(Raw!K7="",LOWER(Raw!K7)="not available"),"Not Available",HYPERLINK(Raw!K7,"Instagram")) -> Instagram | J23: =IF(OR(Raw!L7="",LOWER(Raw!L7)="not available"),"Not Available",HYPERLINK(Raw!L7,"Facebook")) -> Facebook | K23: 4.8 | L23: 319
A24: 23 | B24: Cut And Curve Fitness Club | C24: Ulwe | D24: 1st floor, Sai Ashish Residency, Sector 18, Ulwe, Navi Mumbai, Maharashtra 410206 | E24: =IF(OR(Raw!D136="",LOWER(Raw!D136)="not available"),"Not Available",HYPERLINK(Raw!D136,"Maps")) -> Maps | F24: 75063 10493 | G24: Not Available | H24: Not Available | I24: =IF(OR(Raw!K136="",LOWER(Raw!K136)="not available"),"Not Available",HYPERLINK(Raw!K136,"Instagram")) -> Instagram | J24: =IF(OR(Raw!L136="",LOWER(Raw!L136)="not available"),"Not Available",HYPERLINK(Raw!L136,"Facebook")) -> Facebook | K24: 5 | L24: 50
A25: 24 | B25: D2 Fitnesss | C25: Ghansoli | D25: Shop No 25-29, Patel Heights CHS, Sector 7, Ghansoli, Navi Mumbai, Maharashtra 400701 | E25: =IF(OR(Raw!D72="",LOWER(Raw!D72)="not available"),"Not Available",HYPERLINK(Raw!D72,"Maps")) -> Maps | F25: 85911 19656 | G25: Not Available | H25: Not Available | I25: =IF(OR(Raw!K72="",LOWER(Raw!K72)="not available"),"Not Available",HYPERLINK(Raw!K72,"Instagram")) -> Not Available | J25: =IF(OR(Raw!L72="",LOWER(Raw!L72)="not available"),"Not Available",HYPERLINK(Raw!L72,"Facebook")) -> Not Available | K25: 4.2 | L25: 157
A26: 25 | B26: DK Fitness (Digha) | C26: Digha | D26: Digha Naka, Dighe, Navi Mumbai, Maharashtra 400708 | E26: =IF(OR(Raw!D154="",LOWER(Raw!D154)="not available"),"Not Available",HYPERLINK(Raw!D154,"Maps")) -> Maps | F26: 86527 06211 | G26: Not Available | H26: Not Available | I26: =IF(OR(Raw!K154="",LOWER(Raw!K154)="not available"),"Not Available",HYPERLINK(Raw!K154,"Instagram")) -> Instagram | J26: =IF(OR(Raw!L154="",LOWER(Raw!L154)="not available"),"Not Available",HYPERLINK(Raw!L154,"Facebook")) -> Not Available | K26: 4.9 | L26: 377
A27: 26 | B27: Evolve Fitness | C27: Airoli | D27: Shop no 9-11, Narmada Co-op Chs, Plot No. 36, Sector-19, Airoli, Navi Mumbai, Maharashtra 400708 | E27: =IF(OR(Raw!D42="",LOWER(Raw!D42)="not available"),"Not Available",HYPERLINK(Raw!D42,"Maps")) -> Maps | F27: 80835 35352 | G27: Not Available | H27: Not Available | I27: =IF(OR(Raw!K42="",LOWER(Raw!K42)="not available"),"Not Available",HYPERLINK(Raw!K42,"Instagram")) -> Not Available | J27: =IF(OR(Raw!L42="",LOWER(Raw!L42)="not available"),"Not Available",HYPERLINK(Raw!L42,"Facebook")) -> Not Available | K27: 4.7 | L27: 470
A28: 27 | B28: Falcon Fitness Arena | C28: Airoli | D28: Basement Shankar Sheela Apartment, Sector 9, Airoli, Navi Mumbai, Maharashtra 400708 | E28: =IF(OR(Raw!D46="",LOWER(Raw!D46)="not available"),"Not Available",HYPERLINK(Raw!D46,"Maps")) -> Maps | F28: 98924 85426 | G28: Not Available | H28: Not Available | I28: =IF(OR(Raw!K46="",LOWER(Raw!K46)="not available"),"Not Available",HYPERLINK(Raw!K46,"Instagram")) -> Instagram | J28: =IF(OR(Raw!L46="",LOWER(Raw!L46)="not available"),"Not Available",HYPERLINK(Raw!L46,"Facebook")) -> Facebook | K28: 4.9 | L28: 176
A29: 28 | B29: Fit2Fit health fitness club | C29: Kalamboli | D29: 1st floor, Vaishnavi Heights, Roadpali Rd, Sector 20, Kalamboli, Panvel, Maharashtra 410218 | E29: =IF(OR(Raw!D130="",LOWER(Raw!D130)="not available"),"Not Available",HYPERLINK(Raw!D130,"Maps")) -> Maps | F29: 90041 96965 | G29: Not Available | H29: Not Available | I29: =IF(OR(Raw!K130="",LOWER(Raw!K130)="not available"),"Not Available",HYPERLINK(Raw!K130,"Instagram")) -> Instagram | J29: =IF(OR(Raw!L130="",LOWER(Raw!L130)="not available"),"Not Available",HYPERLINK(Raw!L130,"Facebook")) -> Not Available | K29: 4.1 | L29: 141
A30: 29 | B30: FitBeat Studio | C30: Rabale | D30: Shop-9,10, Swami krupa Apartment, Sector 30, Rabale, Navi Mumbai, Maharashtra 400701 | E30: =IF(OR(Raw!D153="",LOWER(Raw!D153)="not available"),"Not Available",HYPERLINK(Raw!D153,"Maps")) -> Maps | F30: 77180 01722 | G30: Not Available | H30: Not Available | I30: =IF(OR(Raw!K153="",LOWER(Raw!K153)="not available"),"Not Available",HYPERLINK(Raw!K153,"Instagram")) -> Instagram | J30: =IF(OR(Raw!L153="",LOWER(Raw!L153)="not available"),"Not Available",HYPERLINK(Raw!L153,"Facebook")) -> Facebook | K30: 5 | L30: 4
A31: 30 | B31: FITnation Arena Gym Kamothe | C31: Kamothe | D31: Office No. 1, Shubh Nil Sivam HSG Soc, Plot No. 40, Sector 11, Kamothe, Panvel, Maharashtra 410209 | E31: =IF(OR(Raw!D121="",LOWER(Raw!D121)="not available"),"Not Available",HYPERLINK(Raw!D121,"Maps")) -> Maps | F31: Not publicly listed | G31: Not Available | H31: Not Available | I31: =IF(OR(Raw!K121="",LOWER(Raw!K121)="not available"),"Not Available",HYPERLINK(Raw!K121,"Instagram")) -> Not Available | J31: =IF(OR(Raw!L121="",LOWER(Raw!L121)="not available"),"Not Available",HYPERLINK(Raw!L121,"Facebook")) -> Not Available | K31: 5 | L31: 19
A32: 31 | B32: FITNESS CLUB STUDIO KAMOTHE | C32: Kamothe | D32: Sector 15, Kamothe, Panvel, Maharashtra 410209 | E32: =IF(OR(Raw!D113="",LOWER(Raw!D113)="not available"),"Not Available",HYPERLINK(Raw!D113,"Maps")) -> Maps | F32: 73048 65699 | G32: fitnessclubstudio15@gmail.com | H32: Gym Services | Weight Loss, Body Transformation | I32: =IF(OR(Raw!K113="",LOWER(Raw!K113)="not available"),"Not Available",HYPERLINK(Raw!K113,"Instagram")) -> Instagram | J32: =IF(OR(Raw!L113="",LOWER(Raw!L113)="not available"),"Not Available",HYPERLINK(Raw!L113,"Facebook")) -> Facebook | K32: 5 | L32: 361
A33: 32 | B33: Fitness Club Studio, Kopar Khairne | C33: Kopar Khairane | D33: 1st Floor, Bonkode Village Marg, Sector 11, Kopar Khairane, Navi Mumbai, Maharashtra 400709 | E33: =IF(OR(Raw!D56="",LOWER(Raw!D56)="not available"),"Not Available",HYPERLINK(Raw!D56,"Maps")) -> Maps | F33: 73043 99220 | G33: Not Available | H33: Not Available | I33: =IF(OR(Raw!K56="",LOWER(Raw!K56)="not available"),"Not Available",HYPERLINK(Raw!K56,"Instagram")) -> Not Available | J33: =IF(OR(Raw!L56="",LOWER(Raw!L56)="not available"),"Not Available",HYPERLINK(Raw!L56,"Facebook")) -> Not Available | K33: 4.8 | L33: 38
A34: 33 | B34: Fitness Empire Unisex Gym | C34: New Panvel | D34: 1st Floor, Shop no 110, Shubham Complex, Sector 11, New Panvel East, Panvel, Maharashtra 410206 | E34: =IF(OR(Raw!D103="",LOWER(Raw!D103)="not available"),"Not Available",HYPERLINK(Raw!D103,"Maps")) -> Maps | F34: 89281 21483 | G34: Not Available | H34: Not Available | I34: =IF(OR(Raw!K103="",LOWER(Raw!K103)="not available"),"Not Available",HYPERLINK(Raw!K103,"Instagram")) -> Not Available | J34: =IF(OR(Raw!L103="",LOWER(Raw!L103)="not available"),"Not Available",HYPERLINK(Raw!L103,"Facebook")) -> Not Available | K34: 5 | L34: 175
A35: 34 | B35: FITNESS FIRST GYM | C35: Airoli | D35: Shiv Shankar plaza, Sector 7, Airoli, Thane, Navi Mumbai, Maharashtra 400708 | E35: =IF(OR(Raw!D54="",LOWER(Raw!D54)="not available"),"Not Available",HYPERLINK(Raw!D54,"Maps")) -> Maps | F35: 89761 04020 | G35: Not Available | H35: Not Available | I35: =IF(OR(Raw!K54="",LOWER(Raw!K54)="not available"),"Not Available",HYPERLINK(Raw!K54,"Instagram")) -> Not Available | J35: =IF(OR(Raw!L54="",LOWER(Raw!L54)="not available"),"Not Available",HYPERLINK(Raw!L54,"Facebook")) -> Not Available | K35: 5 | L35: 29
A36: 35 | B36: Fitness Freak | C36: CBD Belapur | D36: Shop No: 6, Rajkamal Bayside, Plot No: 28, Sector 15, CBD Belapur, Navi Mumbai, Maharashtra 400614 | E36: =IF(OR(Raw!D37="",LOWER(Raw!D37)="not available"),"Not Available",HYPERLINK(Raw!D37,"Maps")) -> Maps | F36: 80977 34167 | G36: Not Available | H36: Not Available | I36: =IF(OR(Raw!K37="",LOWER(Raw!K37)="not available"),"Not Available",HYPERLINK(Raw!K37,"Instagram")) -> Not Available | J36: =IF(OR(Raw!L37="",LOWER(Raw!L37)="not available"),"Not Available",HYPERLINK(Raw!L37,"Facebook")) -> Not Available | K36: 4.7 | L36: 260
A37: 36 | B37: Fitness Kingdom Golds | C37: Kopar Khairane | D37: Jigna arcade, near Bonkode Road, Sector 13, Kopar Khairane, Navi Mumbai, Maharashtra 400709 | E37: =IF(OR(Raw!D60="",LOWER(Raw!D60)="not available"),"Not Available",HYPERLINK(Raw!D60,"Maps")) -> Maps | F37: 91367 86296 | G37: Not Available | H37: Not Available | I37: =IF(OR(Raw!K60="",LOWER(Raw!K60)="not available"),"Not Available",HYPERLINK(Raw!K60,"Instagram")) -> Not Available | J37: =IF(OR(Raw!L60="",LOWER(Raw!L60)="not available"),"Not Available",HYPERLINK(Raw!L60,"Facebook")) -> Not Available | K37: 4.1 | L37: 74
A38: 37 | B38: Fitness Square | C38: Kopar Khairane | D38: Shop no 67, Ganesh Bhavana, Sector 4A, Kopar Khairane, Navi Mumbai, Maharashtra 400709 | E38: =IF(OR(Raw!D59="",LOWER(Raw!D59)="not available"),"Not Available",HYPERLINK(Raw!D59,"Maps")) -> Maps | F38: 86683 80880 | G38: Not Available | H38: Not Available | I38: =IF(OR(Raw!K59="",LOWER(Raw!K59)="not available"),"Not Available",HYPERLINK(Raw!K59,"Instagram")) -> Not Available | J38: =IF(OR(Raw!L59="",LOWER(Raw!L59)="not available"),"Not Available",HYPERLINK(Raw!L59,"Facebook")) -> Not Available | K38: 4.7 | L38: 123
A39: 38 | B39: FITNESS WORLD GYM | C39: Taloja | D39: Midland enclave, Plot no 136/137, Taloja Phase 1, Taloja Panchanand, Taloja, Panvel, Maharashtra 410208 | E39: =IF(OR(Raw!D148="",LOWER(Raw!D148)="not available"),"Not Available",HYPERLINK(Raw!D148,"Maps")) -> Maps | F39: 79726 27087 | G39: Not Available | H39: Not Available | I39: =IF(OR(Raw!K148="",LOWER(Raw!K148)="not available"),"Not Available",HYPERLINK(Raw!K148,"Instagram")) -> Not Available | J39: =IF(OR(Raw!L148="",LOWER(Raw!L148)="not available"),"Not Available",HYPERLINK(Raw!L148,"Facebook")) -> Not Available | K39: 4.3 | L39: 29
A40: 39 | B40: FITNESSIUM | C40: Kalamboli | D40: Shop 1-6, Henita Arcade, Plot No 16, Sector 8E, Roadpali, Kalamboli, Panvel, Maharashtra 410218 | E40: =IF(OR(Raw!D124="",LOWER(Raw!D124)="not available"),"Not Available",HYPERLINK(Raw!D124,"Maps")) -> Maps | F40: 72089 95744 | G40: Not Available | H40: Not Available | I40: =IF(OR(Raw!K124="",LOWER(Raw!K124)="not available"),"Not Available",HYPERLINK(Raw!K124,"Instagram")) -> Instagram | J40: =IF(OR(Raw!L124="",LOWER(Raw!L124)="not available"),"Not Available",HYPERLINK(Raw!L124,"Facebook")) -> Facebook | K40: 4.8 | L40: 340
...
