Workbook

Sheet Notes
A1: Clinic Data Analysis (Navi Mumbai)
A3: The Excel file contains 6 sheets.
A4: The data required for outreach is in "Clinic Data".
A5: The findings/data analysis were added in the "Analysis" sheet.
A6: The Clinic Data sheet contains "13 rows" and "120 columns".
A7: The data was collected from open resources through Google.
A8: The original dataset contained several impurities and inconsistencies:
A10: Unnecessary columns were identified and dropped using Excel and Python libraries.
A11: Lead classification was based on available details such as: Website availability, Instagram availability and Contact availability
A14: Analysis And Report
A16: Many clinics have limited online visibility, with a lack of proper websites and digital presence.
A17: Most clinics have available contact details, creating better chances for sales outreach.
... A22: as only their availability was checked, not their quality, activity, or engagement.

Sheet Raw
A1: hfpxzc href | B1: xxVWCe | C1: MW4etd | D1: UY7F9 | E1: W4Efsd | F1: W4Efsd 2 | G1: W4Efsd 3 | H1: W4Efsd 4 | I1: W4Efsd 5 | J1: W4Efsd 6 | K1: UsdlK | L1: Cw1rxd | M1: R8c4Qb | N1: Jn12ke src | O1: ah5Ghc | P1: doJOZc | Q1: lcr4fd href | R1: Cw1rxd 2 | S1: R8c4Qb 2 | T1: W4Efsd 7 | U1: ah5Ghc 2 | V1: ah5Ghc 3
A4: https://www.google.com/maps/place/Family+Care+Clinic+Nerul+Navi+Mumbai/data=!4m7!3m6!1s0x3be7c3c934900977:0x57d39a810a8d346!8m2!3d19.0396026!4d73.017636!16s%2Fg%2F11vm7jbkdb!19sChIJdwmQNMnD5zsRRtOoEKg5fQU?authuser=0&hl=en&rclk=1 | B4: Family Care Clinic Nerul Navi Mumbai | C4: 5 | D4: -9 | E4: Medical clinic | F4: · | G4: e1/2, Vrindavan apartment, A-4, near Sai baba hotel | H4: Open | I4: · Closes 10 PM | J4: · | K4: +91 87793 87362 | L4:  | M4: Directions | N4: https://ssl.gstatic.com/local/servicebusiness/default_user.png | O4: "A rare combination of expertise, compassion, and genuine care."
A5: https://www.google.com/maps/place/Family+Health+Clinic/data=!4m7!3m6!1s0x3be7c3751b6a4f49:0x64c685205b2a7c4c!8m2!3d19.0311396!4d73.0268152!16s%2Fg%2F11t6n7_wh9!19sChIJSU9qG3XD5zsRTHwqWyCFxmQ?authuser=0&hl=en&rclk=1 | B5: Family Health Clinic | C5: 5 | D5: -71 | E5: Doctor | F5: · | G5: Plot no.13, Shop No. 18, Bhima Shankar CHS Shopping Complex, Sector 19A Nerul Rd | H5: Open | I5: · Closes 8:30 PM | J5: · | K5: +91 91372 08535 | L5:  | M5: Directions | N5: https://ssl.gstatic.com/local/servicebusiness/default_user.png | O5: "The staff made me feel comfortable throughout the visit."
A6: https://www.google.com/maps/place/Apollo+Hospital,/data=!4m7!3m6!1s0x3be7c3903a3c9297:0xb858a25d34856005!8m2!3d19.0208646!4d73.0287337!16s%2Fg%2F11plkkvf08!19sChIJl5I8OpDD5zsRBWCFNF2iWLg?authuser=0&hl=en&rclk=1 | B6: Apollo Hospital, | C6: 4.7 | D6: -28262 | E6: Hospital | F6: · | G6: · | H6: Plot no 13, Parsik Hill Rd, off Uran Road | I6: Open 24 hours | J6: · | K6: +91 80 6297 2766 | L6:  | M6: Website | N6: https://ssl.gstatic.com/local/servicebusiness/default_user.png | O6: "The therapists exhibited a remarkable level of expertise and compassion." | P6:  | Q6: https://www.apollohospitals.com/hospitals/apollo-hospitals-mumbai | R6:  | S6: Directions
A7: https://www.google.com/maps/place/Jalphama+Clinic+%28+Dr.+Bhanushali%29/data=!4m7!3m6!1s0x3be7c3c7911986eb:0x74e823347d80b11d!8m2!3d19.031161!4d73.026728!16s%2Fg%2F1pv2l2tyb!19sChIJ64YZkcfD5zsRHbGAfTQj6HQ?authuser=0&hl=en&rclk=1 | B7: Jalphama Clinic ( Dr. Bhanushali) | C7: 5 | D7: -29 | E7: Medical clinic | F7: · | G7: Shop No.10, Plot, 13, Annasaheb Urf Blvd Zhute Marg | H7: Open | I7: · Closes 11 PM | J7: · | K7: +91 93232 05179 | L7:  | M7: Directions | N7: https://ssl.gstatic.com/local/servicebusiness/default_user.png | O7: "He's very polite and doesn't make you feel like a patient."
A8: https://www.google.com/maps/place/Parasnath+Speciality+Clinics+%7C+Knee+and+Spine+Clinic+in+Vashi,+Navi+Mumbai/data=!4m7!3m6!1s0x3be7c1dfafcc8b65:0xbaba3c2e67be05d4!8m2!3d19.0737122!4d72.9992978!16s%2Fg%2F11fk2mhxc4!19sChIJZYvMr9_B5zsR1AW-Zy48uro?authuser=0&hl=en&rclk=1 | B8: Parasnath Speciality Clinics | Knee and Spine Clinic in Vashi, Navi Mumbai | C8: 4.8 | D8: -241 | E8: Ayurvedic clinic | F8: · | G8: · | H8: 2nd Floor, Mahavir tower, above golden punjab hotel | I8: Closes soon | J8: · | K8: +91 90824 00043 | L8:  | M8: Website | N8: https://ssl.gstatic.com/local/servicebusiness/default_user.png | O8: "All the staff in the | P8:  | Q8: https://parasnathclinics.com/ | R8:  | S8: Directions | T8: · 7 PM · Opens 10 AM Wed | U8: clinic | V8: very supportive and helpful."
A9: https://www.google.com/maps/place/Sanjeevni+Clinic-+The+Family+Doctor/data=!4m7!3m6!1s0x3be7c1cea7b703fb:0x600191e4e76c7976!8m2!3d19.0390708!4d73.01777!16s%2Fg%2F11shj5hf25!19sChIJ-wO3p87B5zsRdnls5-SRAWA?authuser=0&hl=en&rclk=1 | B9: Sanjeevni Clinic- The Family Doctor | C9: 5 | D9: -20 | E9: Walk-in clinic | F9: · | G9: Sanjeevni Clinic, NL-A 3/4, 706, Station Road | H9: Open | I9: · Closes 10 PM | J9: · | K9: +91 98695 13498 | L9:  | M9: Directions | N9: https://ssl.gstatic.com/local/servicebusiness/default_user.png | O9: "I would recommend her."
A10: https://www.google.com/maps/place/Dr.+Salman%27s+Healthcare+clinic/data=!4m7!3m6!1s0x3be7c3e97713dd7f:0x3e624dd525be13e9!8m2!3d19.034756!4d73.01564!16s%2Fg%2F11rmx06x2j!19sChIJf90Td-nD5zsR6RO-JdVNYj4?authuser=0&hl=en&rclk=1 | B10: Dr. Salman's Healthcare clinic | C10: 4.8 | D10: -41 | E10: Medical clinic | F10: · | G10: House No. 17,Shop, no. 02, Gaon (West | K10: +91 87073 40438 | L10:  | M10: Directions | N10: https://ssl.gstatic.com/local/servicebusiness/default_user.png | O10: "The services that I receive from Dr is excellent."
A11: https://www.google.com/maps/place/Lions+Hospital/data=!4m7!3m6!1s0x3be7c0d766c60807:0xdadd8c3a5ffb464a!8m2!3d19.1005881!4d73.0047438!16s%2Fg%2F1tf7qlnq!19sChIJBwjGZtfA5zsRSkb7XzqM3do?authuser=0&hl=en&rclk=1 | B11: Lions Hospital | C11: 4.8 | D11: -4169 | E11: Hospital | F11: · | G11: · | H11: 101, Vashi Kopar Khairane Rd | I11: Open 24 hours | J11: · | K11: +91 83559 61073 | L11:  | M11: Website | N11: https://ssl.gstatic.com/local/servicebusiness/default_user.png | O11: "Excellent service, professional care, and a friendly environment." | P11:  | Q11: http://lionshospital.co.in/ | R11:  | S11: Directions
A12: https://www.google.com/maps/place/DR.+PARVEZ+UMAR+KHAN,+ROSHAN+UMAR+CLINIC,Family+Phsician+%28M.B.B.S%29Nerul,Navi+Mumbai/data=!4m7!3m6!1s0x3be7c36ec80371df:0x5fed2ab38de5bd89!8m2!3d19.0284367!4d73.0181821!16s%2Fg%2F11s2k6tmd9!19sChIJ33EDyG7D5zsRib3ljbMq7V8?authuser=0&hl=en&rclk=1 | B12: DR. PARVEZ UMAR KHAN, ROSHAN UMAR CLINIC,Family Phsician (M.B.B.S)Nerul,Navi Mumbai | C12: 5 | D12: -98 | E12: Medical clinic | F12: · | G12: · | H12: Open | I12: · Closes 10 PM | J12: SHOP NO. 27 MARY LAND CHS PLOT No. A-7,SECTOR-23,DARAVE,NERUL(E),NAVI MUMBAI PIN- 4000706, NERUL EAST | K12: +91 98218 22843 | L12:  | M12: Directions | N12: https://ssl.gstatic.com/local/servicebusiness/default_user.png | O12: "The diagnosis and | P12:  | T12: · | U12: treatment | V12: were spot on."
A13: https://www.google.com/maps/place/Dr+Suresh+Ade/data=!4m7!3m6!1s0x3be7c14b0b438087:0x8a4507f5b2b8135e!8m2!3d19.0418173!4d73.0193001!16s%2Fg%2F11c6pm6_m8!19sChIJh4BDC0vB5zsRXhO4svUHRYo?authuser=0&hl=en&rclk=1 | B13: Dr Suresh Ade | C13: 4.9 | D13: -330 | E13: Diabetologist | F13: · | G13: · | H13: Clinic No.22, Ayush Clinic, Saisthan CHS | I13: Open 24 hours | L13:  | M13: Website | N13: https://ssl.gstatic.com/local/servicebusiness/default_user.png | O13: "Highly skilled specialist." | P13:  | Q13: https://drsureshadediabetologist.com/ | R13:  | S13: Directions
A14: https://www.google.com/maps/place/Skin+Science+Clinic/data=!4m7!3m6!1s0x3be7c36b1840cb01:0xe12325ea03317617!8m2!3d19.0241021!4d73.0210187!16s%2Fg%2F11t4276g1s!19sChIJActAGGvD5zsRF3YxA-olI-E?authuser=0&hl=en&rclk=1 | B14: Skin Science Clinic | C14: 4.9 | D14: -283 | E14: Skin care clinic | F14: · | G14: · | H14: Plot no. 17, Office No. 9, Wing D First Floor, Millennium Park building, circle, near Haware Centurion Mall | I14: Open | J14: · | K14: +91 77770 05606 | L14:  | M14: Website | N14: https://ssl.gstatic.com/local/servicebusiness/default_user.png | O14: "The care, | P14:  | Q14: https://skinsciencemumbai.com/ | R14:  | S14: Directions | T14: · Closes 10 PM | U14: treatment | V14: , and ambience here are truly comforting."
A15: https://www.google.com/maps/place/Dr.Chitra%27s+BellaDerma/data=!4m7!3m6!1s0x3be7c3f2fe429b63:0xfcbeea04dc4c9309!8m2!3d19.0297471!4d73.025239!16s%2Fg%2F11r_w828f0!19sChIJY5tC_vLD5zsRCZNM3ATqvvw?authuser=0&hl=en&rclk=1 | B15: Dr.Chitra's BellaDerma | C15: 4.8 | D15: -512 | E15: Skin care clinic | F15: · | G15: · | H15: Open | I15: · Closes 8:30 PM | J15: Shop no 14, Lenyadri Complex, Plot No. 47/1 2, opp. Madhavi CHS | K15: +91 85915 94849 | L15:  | M15: Directions | N15: https://ssl.gstatic.com/local/servicebusiness/default_user.png | O15: "The treatments have made a noticeable difference in my skin and hair health." | P15:  | T15: ·
A16: https://www.google.com/maps/place/Skin+Soul+-+Laser+hair+reduction+in+Navi+Mumbai,+ChemicalPeeling,+Hydra-facial+in+Navi+Mumbai,+Botox+treatment+in+Navi+Mumbai/data=!4m7!3m6!1s0x3be7c14a46874ead:0xffde2beb7bdfa747!8m2!3d19.0442387!4d73.009609!16s%2Fg%2F11fzbjjzkx!19sChIJrU6HRkrB5zsRR6ffe-sr3v8?authuser=0&hl=en&rclk=1 | B16: Skin Soul - Laser hair reduction in Navi Mumbai, ChemicalPeeling, Hydra-facial in Navi Mumbai, Botox treatment in Navi Mumbai | C16: 4.6 | D16: -291 | E16: Skin care clinic | F16: · | G16: · | H16: First Floor, Sai Paradise shop no 1, Plot 21, opp. Prashant Corner | I16: Open | J16: · | K16: +91 93215 84678 | L16:  | M16: Website | N16: https://ssl.gstatic.com/local/servicebusiness/default_user.png | O16: "I underwent several procedures, and the results were excellent." | P16:  | Q16: https://www.skinsoul.in/ | R16:  | S16: Directions | T16: · Closes 9 PM
A17: https://www.google.com/maps/place/Ayushakti+Ayurved+Health+Centre+%7C+Panchakarma+Clinic+in+Navi+Mumbai/data=!4m7!3m6!1s0x3be7c3ab786a6a1f:0x4294e10b00f08572!8m2!3d19.0367236!4d73.0643284!16s%2Fg%2F11g_v6hfzy!19sChIJH2pqeKvD5zsRcoXwAAvhlEI?authuser=0&hl=en&rclk=1 | B17: Ayushakti Ayurved Health Centre | Panchakarma Clinic in Navi Mumbai | C17: 4.9 | D17: -274 | E17: Ayurvedic clinic | F17: · | G17: · | H17: h.s, shops, Mahavir Shraddha c, Plot no 11-B, opp. Kendriya Vihar Metro Station Road | I17: Open | J17: · | K17: +91 86578 62385 | L17:  | M17: Website | N17: https://ssl.gstatic.com/local/servicebusiness/default_user.png | O17: "The | P17:  | Q17: https://www.ayushakti.com/ | R17:  | S17: Directions | T17: · Closes 8 PM | U17: doctors | V17: and staff are very friendly, positive and responsive."
A18: https://www.google.com/maps/place/Health+Care+Clinic/data=!4m7!3m6!1s0x3be7c3bc27753c85:0x6cfb8c05c28a9fb3!8m2!3d19.0245599!4d73.0197486!16s%2Fg%2F1pp2txp0_!19sChIJhTx1J7zD5zsRs5-KwgWM-2w?authuser=0&hl=en&rclk=1 | B18: Health Care Clinic | C18: 4.4 | D18: -15 | E18: Medical clinic | F18: · | G18: Siddhivinayak Building,Plot No.B-99,Shop No.2, Darave Rd | H18: Open | I18: · Closes 10:30 PM | J18: · | K18: +91 99200 84451 | L18:  | M18: Directions | N18: https://ssl.gstatic.com/local/servicebusiness/default_user.png | O18: "⭐⭐⭐⭐⭐ Dr. FM Chogle is very friendly and highly experienced."
A19: https://www.google.com/maps/place/Ivory+Physiotherapy+Clinic+Nerul+Navi+Mumbai/data=!4m7!3m6!1s0x3be7c357181be0f9:0x43273c8f83a0f300!8m2!3d19.0110622!4d73.013619!16s%2Fg%2F11t5dxshjk!19sChIJ-eAbGFfD5zsRAPOgg488J0M?authuser=0&hl=en&rclk=1 | B19: Ivory Physiotherapy Clinic Nerul Navi Mumbai | C19: 4.9 | D19: -537 | E19: Medical clinic | F19: · | G19: · | H19: First Floor, NEELKANTH RESIDENCY, Office No, 1-6 | I19: Open | J19: · | K19: +91 85911 26927 | L19:  | M19: Website | N19: https://ssl.gstatic.com/local/servicebusiness/default_user.png | O19: "The | P19:  | Q19: https://ivoryphysiotherapy.in/ | R19:  | S19: Directions | T19: · Closes 9:30 PM | U19: clinic | V19: is clean, professional, and truly focused on patient recovery."
A20: https://www.google.com/maps/place/BCA+CLINIC+NAVI+MUMBAI+by+Deepali+Banerjee/data=!4m7!3m6!1s0x3be7c1f3065cab8d:0x6bfadc5f2fe74d8b!8m2!3d19.053278!4d73.0070932!16s%2Fg%2F11zjvpwdcc!19sChIJjatcBvPB5zsRi03nL1_c-ms?authuser=0&hl=en&rclk=1 | B20: BCA CLINIC NAVI MUMBAI by Deepali Banerjee | E20: Skin care clinic | F20: · | G20: PLOT NO.- 88, 18, Palm Beach Rd | I20: Open | L20:  | M20: Website | Q20: https://www.bcaclinicindia.com/ | R20:  | S20: Directions | T20: · Closes 8 PM
A21: https://www.google.com/maps/place/Vyana+Skin+Clinic+and+Yoga+Center+%28Navi+Mumbai%29/data=!4m7!3m6!1s0x3be7c3997d07c021:0xb37297c118b5ff4d!8m2!3d19.01372!4d73.0112652!16s%2Fg%2F11hbvp_rn3!19sChIJIcAHfZnD5zsRTf-1GMGXcrM?authuser=0&hl=en&rclk=1 | B21: Vyana Skin Clinic and Yoga Center (Navi Mumbai) | C21: 5 | D21: -23 | E21: Skin care clinic | F21: · | G21: Shop No. 1, PLot no 62 | H21: Open | I21: · Closes 8 PM | J21: · | K21: +91 99673 29119 | L21:  | M21: Directions | N21: https://ssl.gstatic.com/local/servicebusiness/default_user.png | O21: "Way of doing things were professional and have been going for 4 years."
A22: https://www.google.com/maps/place/Terna+Speciality+Hospital+%26+Research+Centre,+Navi+Mumbai+%7C+Best+Hospital+in+Navi+Mumbai/data=!4m7!3m6!1s0x3be7c3ea86beb207:0x7f154e8cdff9c916!8m2!3d19.0315347!4d73.0162787!16s%2Fg%2F11gzm8fv1!19sChIJB7K-hurD5zsRFsn534xOFX8?authuser=0&hl=en&rclk=1 | B22: Terna Speciality Hospital & Research Centre, Navi Mumbai | Best Hospital in Navi Mumbai | C22: 4.1 | D22: -1737 | E22: General hospital | F22: · | G22: · | H22: Phase II, Plot no 12, Sector 22, opp. Nerul Railway Station | I22: Open 24 hours | J22: · | K22: +91 22 6157 8300 | L22:  | M22: Website | N22: https://ssl.gstatic.com/local/servicebusiness/default_user.png | O22: "Staff is friendly and understanding, | P22:  | Q22: https://ternahospital.org/ | R22:  | S22: Directions | U22: treatment | V22: is performed accurately."
A23: https://www.google.com/maps/place/Echelon+Hospital/data=!4m7!3m6!1s0x3be7c0ce2ed4c9cf:0x6f5fc27430527124!8m2!3d19.1085005!4d73.0017709!16s%2Fg%2F1thk764z!19sChIJz8nULs7A5zsRJHFSMHTCX28?authuser=0&hl=en&rclk=1 | B23: Echelon Hospital | C23: 4.5 | D23: -1794 | E23: General hospital | F23: · | G23: · | H23: plot no 12/13, near Indian Oil Petrol Pump | I23: Open 24 hours | J23: · | K23: +91 89895 85050 | L23:  | M23: Website | N23: https://ssl.gstatic.com/local/servicebusiness/default_user.png | O23: "Great | P23:  | Q23: https://www.echelonhospital.com/ | R23:  | S23: Directions | U23: doctors | V23: , clean facilities, friendly staff."
A24: https://www.google.com/maps/place/Dr+Batra%E2%80%99s+Homeopathy+Clinic/data=!4m7!3m6!1s0x3be7c3c0c782483b:0xe0a102e770fe4288!8m2!3d19.0310537!4d73.0217795!16s%2Fg%2F12hr5cmft!19sChIJO0iCx8DD5zsRiEL-cOcCoeA?authuser=0&hl=en&rclk=1 | B24: Dr Batra’s Homeopathy Clinic | C24: 4.6 | D24: -1050 | E24: Homeopath | F24: · | G24: · | H24: 1st Floor, No 101 & 103, Plot No 101, near D Mart | I24: Open | J24: · | K24: +91 70450 06060 | L24:  | M24: Website | N24: https://ssl.gstatic.com/local/servicebusiness/default_user.png | O24: "Helped tackle my dandruff issue and could see considerable growth in hair." | P24:  | Q24: https://clinics.drbatras.com/navi-mumbai/homeopathy-clinic-sector-21 | R24:  | S24: Directions | T24: · Closes 8 PM
A25: https://www.google.com/maps/place/SkinIQ+Skin+Clinic/data=!4m7!3m6!1s0x3be7c36e0a3f11ef:0x95f182a071cac221!8m2!3d19.0432094!4d73.0640734!16s%2Fg%2F11mvp6dv72!19sChIJ7xE_Cm7D5zsRIcLKcaCC8ZU?authuser=0&hl=en&rclk=1 | B25: SkinIQ Skin Clinic | C25: 4.9 | D25: -130 | E25: Dermatologist | F25: · | G25: Plot D59, CHS Near Furniture Market, Shree Krishna Paradise, Colours hospital, 101, Tower 10, near Starbucks | H25: · | I25: Open 24 hours | K25: +91 83830 24748 | L25:  | M25: Website | N25: https://ssl.gstatic.com/local/servicebusiness/default_user.png | O25: "It’s rare to find a | Q25: https://www.skiniq.in/ | R25:  | S25: Directions | U25: doctor | V25: who gives so much attention to patient concerns."
A26: https://www.google.com/maps/place/Dr.+Sanita%27s+Ananya+Women%27s+Clinic,+Best+Obstetrician+%26+Gynaecologist+in+Seawoods,+Navi+Mumbai+%7C+Maternity+%7C+Abortion+Clinic/data=!4m7!3m6!1s0x3be7c3abdfdd49c3:0x90063f53beb57217!8m2!3d19.0119188!4d73.0234878!16s%2Fg%2F11rg6xnq__!19sChIJw0nd36vD5zsRF3K1vlM_BpA?authuser=0&hl=en&rclk=1 | B26: Dr. Sanita's Ananya Women's Clinic, Best Obstetrician & Gynaecologist in Seawoods, Navi Mumbai | Maternity | Abortion Clinic | C26: 5 | D26: -110 | E26: Women's health clinic | F26: · | G26: · | H26: Shop No. 8, Shree Om Sadguru CHS, Plot No. 122 | I26: Open | J26: · | K26: +91 72086 44271 | L26:  | M26: Website | N26: https://ssl.gstatic.com/local/servicebusiness/default_user.png | O26: "The | P26:  | Q26: https://www.drsanitamishra.com/ | R26:  | S26: Directions | T26: · Closes 10 PM | U26: clinic | V26: is clean, peaceful, and welcoming, with very polite staff."
A27: https://www.google.com/maps/place/Prana+Shakti+Clinic.+Dr+Ashwini+Raval.+Best+Homeopathic+Doctor+in+Navi+Mumbai./data=!4m7!3m6!1s0x3be7c330780f4c7f:0xf778a5042230e637!8m2!3d19.041258!4d73.010146!16s%2Fg%2F11w3zyl_fm!19sChIJf0wPeDDD5zsRN-YwIgSlePc?authuser=0&hl=en&rclk=1 | B27: Prana Shakti Clinic. Dr Ashwini Raval. Best Homeopathic Doctor in Navi Mumbai. | C27: 4.8 | D27: -25 | E27: Doctor | F27: · | G27: chs, Sector 6, Shyam Niwas, Shop no 2, Plot no. 222,223 | H27: Open | I27: · Closes 11:30 PM | J27: · | K27: +91 88502 24001 | L27:  | M27: Directions | N27: https://ssl.gstatic.com/local/servicebusiness/default_user.png | O27: "Clean | U27: clinic | V27: , smooth consultation process, and a comfortable atmosphere."
A28: https://www.google.com/maps/place/Dr.+Divyashree+Infectious+Diseases+%26+Vaccination+Clinic+in+Nerul,+Navi+Mumbai/data=!4m7!3m6!1s0x3be7c37cc6529ced:0x7d955bb3f3d793cf!8m2!3d19.0237908!4d73.0227001!16s%2Fg%2F11z8symppq!19sChIJ7ZxSxnzD5zsRz5PX87NblX0?authuser=0&hl=en&rclk=1 | B28: Dr. Divyashree Infectious Diseases & Vaccination Clinic in Nerul, Navi Mumbai | C28: 5 | D28: -18 | E28: Infectious disease physician | F28: · | G28: Sankalp CHS, Shop No-22, Ground Floor, Safal Park | H28: · | I28: Opens soon | K28: +91 89763 94839 | L28:  | M28: Website | N28: https://ssl.gstatic.com/local/servicebusiness/default_user.png | O28: "The | Q28: https://divyashreeidclinic.com/ | R28:  | S28: Directions | T28: · 6:30 PM | U28: doctor | V28: is incredibly kind, friendly, and knowledgeable."
A29: https://www.google.com/maps/place/Dr+Pallavi+Clinic/data=!4m7!3m6!1s0x3be7c324c2fee1a7:0x955cfc8ff5ea8c55!8m2!3d19.0298618!4d73.0153222!16s%2Fg%2F11k434fxvp!19sChIJp-H-wiTD5zsRVYzq9Y_8XJU?authuser=0&hl=en&rclk=1 | B29: Dr Pallavi Clinic | C29: 5 | D29: -1 | E29: Medical clinic | F29: · | G29: Terna Hospital, Plot No 12, Sector 22, opposite Nerul Railway Station | H29: Open 24 hours | L29:  | M29: Directions
A30: https://www.google.com/maps/place/Nitai+children%27s+Clinic/data=!4m7!3m6!1s0x3be7c3a3064edaff:0x573a3fef53967679!8m2!3d19.030229!4d73.0225636!16s%2Fg%2F11g0s844bj!19sChIJ_9pOBqPD5zsReXaWU-8_Olc?authuser=0&hl=en&rclk=1 | B30: Nitai children's Clinic | C30: 4.9 | D30: -286 | E30: Medical clinic | F30: · | G30: Kamladevi birajdar marg, sai prem chs , plot number16, near excel lab | H30: · | I30: Open | K30: +91 77100 77873 | L30:  | M30: Website | N30: https://ssl.gstatic.com/local/servicebusiness/default_user.png | O30: "Dr Omi knowledgeable and took the time to answer all my questions." | Q30: https://dromprakashj.getmy.clinic/ | R30:  | S30: Directions | T30: · Closes 9 PM
A31: https://www.google.com/maps/place/Sparsh+Skin+and+Hair+Cosmetology+Center/data=!4m7!3m6!1s0x3be7c0d9fb9d57bb:0xaa1e83806765c80f!8m2!3d19.1023143!4d73.0054881!16s%2Fg%2F1ptxqbj47!19sChIJu1ed-9nA5zsRD8hlZ4CDHqo?authuser=0&hl=en&rclk=1 | B31: Sparsh Skin and Hair Cosmetology Center | C31: 4.6 | D31: -131 | E31: Dermatologist | F31: · | G31: · | H31: Shop No. 269, Road, Sector 6 Kopar Khairane Rd, near Shivshakti stores, near Police Station | I31: Open | J31: · | K31: +91 77383 81897 | L31:  | M31: Website | N31: https://ssl.gstatic.com/local/servicebusiness/default_user.png | O31: "This | P31:  | Q31: https://www.sparshskinclinics.com/ | R31:  | S31: Directions | T31: · Closes 9:30 PM | U31: Doctor | V31: and staff are professional and knowledgeable about hair."
A32: https://www.google.com/maps/place/Roselle+Skin+Clinic/data=!4m7!3m6!1s0x3be7c3d3d69e366f:0xa86c4b8733e4ee99!8m2!3d19.037539!4d73.0189684!16s%2Fg%2F11yjn3xyt5!19sChIJbzae1tPD5zsRme7kM4dLbKg?authuser=0&hl=en&rclk=1 | B32: Roselle Skin Clinic | C32: 5 | D32: -54 | E32: Skin care clinic | F32: · | G32: SHOP GR-9, Laxcon Plaza, PL-20;21 | H32: · | I32: Open | K32: +91 84509 59496 | L32:  | M32: Website | N32: https://ssl.gstatic.com/local/servicebusiness/default_user.png | O32: "The staff and | Q32: https://www.roselleskinclinic.com/ | R32:  | S32: Directions | T32: · Closes 9 PM | U32: doctors | V32: were incredibly professional and knowledgeable."
A33: https://www.google.com/maps/place/Restore+Aesthetic+Clinic/data=!4m7!3m6!1s0x3be7c3c0b8bf2fc3:0x6a79483b3aa2c9fc!8m2!3d19.0310537!4d73.0217795!16s%2Fg%2F11ryd8kgq5!19sChIJwy-_uMDD5zsR_MmiOjtIeWo?authuser=0&hl=en&rclk=1 | B33: Restore Aesthetic Clinic | C33: 4.9 | D33: -118 | E33: Plastic surgery clinic | F33: · | G33: · | H33: 4th Floor- Block no-401-Doctors House.Plot-101, Sector 21, Landmark:, behind D’Mart, behind DMart | I33: Open | J33: · | K33: +91 86920 99967 | L33:  | M33: Website | N33: https://ssl.gstatic.com/local/servicebusiness/default_user.png | O33: "The | P33:  | Q33: https://www.restoreclinics.in/ | R33:  | S33: Directions | T33: · Closes 8 PM | U33: clinic | V33: is modern, hygienic, and equipped with the latest technology."
A34: https://www.google.com/maps/place/Om+Clinic/data=!4m7!3m6!1s0x3be7c1316a7f9e77:0xcab164d190041735!8m2!3d19.080912!4d73.0004416!16s%2Fg%2F11tx_y_c22!19sChIJd55_ajHB5zsRNRcEkNFksco?authuser=0&hl=en&rclk=1 | B34: Om Clinic | C34: 5 | D34: -1 | E34: Medical clinic | F34: · | G34: Sector 15, Vashi, A8-1, Maratha Bhavan Marg, Juhu Nagar, Navi | H34: Open | I34: · Closes 10 PM | J34: · | K34: +91 76667 62557 | L34:  | M34: Directions
A35: https://www.google.com/maps/place/CLINIC/data=!4m7!3m6!1s0x3be7c12073549679:0xd6faf8e891d267c0!8m2!3d21.0680074!4d82.7525294!16s%2Fg%2F11mlsbg5n7!19sChIJeZZUcyDB5zsRwGfSkej4-tY?authuser=0&hl=en&rclk=1 | B35: CLINIC | C35: 5 | D35: -1 | E35: Doctor | G35: · | H35: Open | I35: · Closes 11 PM | K35: +91 72648 62656 | L35:  | M35: Directions
A36: https://www.google.com/maps/place/SHIFA+CLINIC+%26+HIJAMA+CENTER+%28DR+MOHD+ALIM%29/data=!4m7!3m6!1s0x3be7c3c395231817:0x9d389d4e4eeb3d10!8m2!3d19.036286!4d73.0214383!16s%2Fg%2F11tcwlhwgn!19sChIJFxgjlcPD5zsRED3rTk6dOJ0?authuser=0&hl=en&rclk=1 | B36: SHIFA CLINIC & HIJAMA CENTER (DR MOHD ALIM) | C36: 5 | D36: -26 | E36: Medical clinic | F36: · | G36: GANGA JAMUNA APARTMENT, NL2 Rd | H36: Open | I36: · Closes 10 PM | J36: · | K36: +91 96519 81942 | L36:  | M36: Directions | N36: https://ssl.gstatic.com/local/servicebusiness/default_user.png | O36: "Dr Alim Is So Friendly.Her | U36: Treatment | V36: Style is so different ."
A37: https://www.google.com/maps/place/TAWTE+clinic/data=!4m7!3m6!1s0x3be7c309ac054a59:0x615528e027fbdf20!8m2!3d19.0291268!4d73.0231878!16s%2Fg%2F11fk1410nx!19sChIJWUoFrAnD5zsRIN_7J-AoVWE?authuser=0&hl=en&rclk=1 | B37: TAWTE clinic | C37: 4.6 | D37: -67 | E37: Gastrointestinal surgeon | F37: · | G37: · | H37: Open | I37: · Closes 8 PM | J37: Shop No. 1, Himsagar CHS, Plot No. 67 & 68 | K37: +91 93232 28892 | L37:  | M37: Directions | N37: https://ssl.gstatic.com/local/servicebusiness/default_user.png | O37: "Dr. Nitin Tawte combines expertise and a willingness to listen and discuss." | P37:  | T37: ·
A38: https://www.google.com/maps/place/Dr+Ghogare%27s/data=!4m7!3m6!1s0x3be7c331998fcdeb:0xfd98877b283a9f5e!8m2!3d19.0250148!4d73.0223871!16s%2Fg%2F11h54x3yfp!19sChIJ682PmTHD5zsRXp86KHuHmP0?authuser=0&hl=en&rclk=1 | B38: Dr Ghogare's | C38: 4.7 | D38: -41 | E38: Medical clinic | F38: · | G38: · | H38: 1st Floor, Haware Centurion, F-2, near Seawoods Station Road | I38: Open | J38: · | K38: +91 90281 70123 | L38:  | M38: Website | N38: https://ssl.gstatic.com/local/servicebusiness/default_user.png | O38: "He is truly blessed with excellent skills and clinical knowledge." | P38:  | Q38: https://myheartclinics.com/index.php | R38:  | S38: Directions | T38: · Closes 10 PM
A39: https://www.google.com/maps/place/Sai+Clinic/data=!4m7!3m6!1s0x3be7c3ea1fe82e29:0xcd08ba9e0de631df!8m2!3d19.0349762!4d73.0153322!16s%2Fg%2F1pp2tyy6x!19sChIJKS7oH-rD5zsR3zHmDZ66CM0?authuser=0&hl=en&rclk=1 | B39: Sai Clinic | C39: 5 | D39: -11 | E39: Dental clinic | F39: · | G39: 2, Nerul Village Rd | H39: Open | I39: · Closes 10 PM | J39: · | K39: +91 98920 01920 | L39:  | M39: Directions | N39: https://ssl.gstatic.com/local/servicebusiness/default_user.png | O39: "Great work by dr"
A40: https://www.google.com/maps/place/Dr.Garje+Ayurved+Clinic+%26+Panchakarma+Centre/data=!4m7!3m6!1s0x3be7c3c1e2cd4725:0xe3749dd4caa1bd0a!8m2!3d19.0343512!4d73.0169596!16s%2Fg%2F1hc8421c4!19sChIJJUfN4sHD5zsRCr2hytSddOM?authuser=0&hl=en&rclk=1 | B40: Dr.Garje Ayurved Clinic & Panchakarma Centre | C40: 4.9 | D40: -455 | E40: Ayurvedic clinic | F40: · | G40: A203, A-Wing, 2nd Floor Om Shivam Centre building , Sector20A, &, Railway Station Rd, above Akash Institute, near LIC of India office | H40: · | I40: Open | K40: +91 86521 00501 | L40:  | M40: Website | N40: https://ssl.gstatic.com/local/servicebusiness/default_user.png | O40: "The | Q40: https://www.drgarjeayurved.com/ | R40:  | S40: Directions | T40: · Closes 9:30 PM | U40: clinic | V40: is clean, calming, and the staff is very professional."
A41: https://www.google.com/maps/place/Dr.+Shraddha+Patil+-+PHYSIOTHERAPY+CLINIC+in+Belapur,+Navi+Mumbai,+Best+Physiotherapist+in+Seawoods,+Nerul,+Navi+Mumbai/data=!4m7!3m6!1s0x3be7c326a9de510f:0xaaa49ab28cdc4da8!8m2!3d19.0302065!4d73.0429263!16s%2Fg%2F11rv8051gh!19sChIJD1HeqSbD5zsRqE3cjLKapKo?authuser=0&hl=en&rclk=1 | B41: Dr. Shraddha Patil - PHYSIOTHERAPY CLINIC in Belapur, Navi Mumbai, Best Physiotherapist in Seawoods, Nerul, Navi Mumbai | C41: 4.9 | D41: -111 | E41: Medical clinic | F41: · | G41: · | H41: Shop No. 46/47, Arenja Complex | I41: Open | J41: · | K41: +91 86001 42241 | L41:  | M41: Website | N41: https://ssl.gstatic.com/local/servicebusiness/default_user.png | O41: "Helped me with my neck pain and I got instant relief after visiting her." | P41:  | Q41: https://www.drshraddhapatil.com/ | R41:  | S41: Directions | T41: · Closes 10 PM
A42: https://www.google.com/maps/place/Arihant+Clinic/data=!4m7!3m6!1s0x3be7c3bf00b5c935:0x32e3708e152d2cd1!8m2!3d19.0269386!4d73.0201229!16s%2Fg%2F113gbxqjy!19sChIJNcm1AL_D5zsR0SwtFY5w4zI?authuser=0&hl=en&rclk=1 | B42: Arihant Clinic | C42: 4.5 | D42: -10 | E42: Doctor | F42: · | G42: 1st floor, Plot No 312 | H42: Open | I42: · Closes 8:30 PM | J42: · | K42: +91 90041 31975 | L42:  | M42: Directions
...

Sheet Cleaning
A1: Website | B1: Clinic Names | C1: Instagram | D1: Google Maps | E1: Rating | F1: Reviews | G1: Specialization | H1: Location | I1: Contact | J1: Remark 1 | K1: Remark 2 | L1: Remarks
A2: http://www.360homeocareclinic.com/ | B2: 360 HOMEO CARE CLINIC | C2: Not Found | D2: https://www.google.com/maps/place/360+HOMEO+CARE+CLINIC/data=!4m7!3m6!1s0x3be7c3bbdb4eb027:0x9e0cb6fa5c230ae6!8m2!3d19.0233747!4d73.0248128!16s%2Fg%2F11cmcb1kz9!19sChIJJ7BO27vD5zsR5gojXPq2DJ4?authuser=0&hl=en&rclk=1 | E2: 5 | F2: -152 | G2: Medical clinic | H2: Shop No. 3, Ganpati Complex, Plot No. 105 | L2: =J2 & " " & K2
A3: https://naneshhospital.com/ | B3: Acharya Shri Nanesh Hospital | C3: https://www.instagram.com/naneshhospital | D3: https://www.google.com/maps/place/Acharya+Shri+Nanesh+Hospital/data=!4m7!3m6!1s0x3be7c23539fec13b:0xd98d02fabb970045!8m2!3d19.033325!4d73.041195!16s%2Fg%2F12cpldkhr!19sChIJO8H-OTXC5zsRRQCXu_oCjdk?authuser=0&hl=en&rclk=1 | E3: 4.7 | F3: -599 | G3: Private hospital | H3: Plot No 34-37 | I3: +91 86930 84084 | L3: =J3 & " " & K3
A4: https://drnevinaabraham.getmy.clinic/ | B4: Alpha Dental Clinic | C4: https://www.instagram.com/dr.nevin.abraham | D4: https://www.google.com/maps/place/Alpha+Dental+Clinic/data=!4m7!3m6!1s0x3be7c3bd7981ef7d:0x45908abf3f22a486!8m2!3d19.0202786!4d73.0173018!16s%2Fg%2F11gcmmc1lr!19sChIJfe-Beb3D5zsRhqQiP7-KkEU?authuser=0&hl=en&rclk=1 | E4: 5 | F4: -263 | G4: Dental clinic | H4: Shop No.11, Shreeji Seva CHS, Plot No.42 | L4: =J4 & " " & K4
A5: Not Found | B5: Anand Clinic | C5: Not Found | D5: https://www.google.com/maps/place/Anand+Clinic/data=!4m7!3m6!1s0x3be7c3c303802b3d:0x286a0ce386758130!8m2!3d19.038677!4d73.0197082!16s%2Fg%2F11bw4jpygq!19sChIJPSuAA8PD5zsRMIF1huMMaig?authuser=0&hl=en&rclk=1 | E5: 5 | F5: -5 | G5: Medical clinic | H5: F-3, Jagatguru Aadi Shankracharya Marg | J5: "The | K5: plan was thorough and the results are visible." | L5: =J5 & " " & K5 -> "The plan was thorough and the results are visible."
A6: Not Found | B6: Aniruddha Health Clinic | C6: Not Found | D6: https://www.google.com/maps/place/Aniruddha+Health+Clinic/data=!4m7!3m6!1s0x3be7c24cb71e71f9:0x2fdc4500545e765a!8m2!3d19.0246747!4d73.0410086!16s%2Fg%2F11tdl6tyx6!19sChIJ-XEet0zC5zsRWnZeVABF3C8?authuser=0&hl=en&rclk=1 | G6: Medical clinic | H6: Shop Number 69, Prabhat Centre 1st Floor Plot 7 Sector Number 1a C B D Belapur Navi Mumbai | I6: +91 97696 95873 | J6: "The | K6: is clean, well-organized, and staff is friendly too." | L6: =J6 & " " & K6 -> "The is clean, well-organized, and staff is friendly too."
A7: https://www.apollohospitals.com/hospitals/apollo-hospitals-mumbai | B7: Apollo Hospital | C7: https://www.instagram.com/theapollohospitals | D7: https://www.google.com/maps/place/Apollo+Hospital,/data=!4m7!3m6!1s0x3be7c3903a3c9297:0xb858a25d34856005!8m2!3d19.0208646!4d73.0287337!16s%2Fg%2F11plkkvf08!19sChIJl5I8OpDD5zsRBWCFNF2iWLg?authuser=0&hl=en&rclk=1 | E7: 4.7 | F7: -28262 | G7: Hospital | H7: Plot no 13, Parsik Hill Rd, off Uran Road | I7: +91 80 6297 2766 | J7: "A rare combination of expertise, compassion, and genuine care." | L7: =J7 & " " & K7 -> "A rare combination of expertise, compassion, and genuine care."
A8: https://www.apollohospitals.com/ | B8: Apollo ProHealth - Navi Mumbai | C8: https://www.instagram.com/theapollohospitals | D8: https://www.google.com/maps/place/Apollo+ProHealth+-+Navi+Mumbai/data=!4m7!3m6!1s0x3be7c3d15044d7e7:0xbdebc5b46159df7a!8m2!3d19.020968!4d73.029081!16s%2Fg%2F11ltlczckh!19sChIJ59dEUNHD5zsRet9ZYbTF670?authuser=0&hl=en&rclk=1 | E8: 1 | F8: -1 | G8: Health consultant | H8: Plot 13, Parsik Hill Rd, off Uran Road, opp. Nerul Wonders Park | I8: +91 80 6942 0449 | J8: "The Receptionist is also very professional and Cooperative." | L8: =J8 & " " & K8 -> "The Receptionist is also very professional and Cooperative."
A9: Not Found | B9: Arihant Clinic | C9: Not Found | D9: https://www.google.com/maps/place/Arihant+Clinic/data=!4m7!3m6!1s0x3be7c3bf00b5c935:0x32e3708e152d2cd1!8m2!3d19.0269386!4d73.0201229!16s%2Fg%2F113gbxqjy!19sChIJNcm1AL_D5zsR0SwtFY5w4zI?authuser=0&hl=en&rclk=1 | E9: 4.5 | F9: -10 | G9: Doctor | H9: 1st floor, Plot No 312 | I9: +91 90041 31975 | J9: "Great work by dr" | L9: =J9 & " " & K9 -> "Great work by dr"
A10: https://www.google.com/aclk?sa=L&ai=DChsSEwjEga3j5-OVAxXGmGYCHSv4L60YACICCAEQABoCc20&co=1&ase=2&gclid=CjwKCAjwsfzSBhB5EiwAOGyqSRqHv8zm3JQ3XITZthGBOX6tl3OqxVUzpxkmKhbFNu2bIerIQf8YMBoCjJMQAvD_BwE&cid=CAAS0wHkaI85O8JJUOylJovBAy-LsWBAB44HDW28jy4X8dGtznyF_isMrSlPwW7sTH5AFdWHT7fxlxZo_JZ0-6d05FV3UdOg7gTP9H3eq3-J7h57WxOX68PrRCxfZFz40lzb70RcGBZfSGcaC1qzUeYsEgxCxQLmuTV3pJINCQRr475x_d4uQwJcjuaNO5akBPEOITW66yCBp0LSyqnvTNALN2-xCkdS_BwF6aN1kh5bBX41yJnvQFFPt6DrUvyf0mC-C3VRKV9d4ElkUmbEsRbpbr2MUDXI&cce=2&category=acrcp_v1_32&sig=AOD64_2AXjq4v1QR-MsYwLJX71Qe77Pj0A&adurl&q&ctype=99&nis=6 | B10: ART Fertility Clinics | C10: https://www.instagram.com/artfertilityclinics | D10: https://www.google.com/maps/place/ART+Fertility+Clinics/data=!4m7!3m6!1s0x3be7c9f4dd2ad901:0x69a60861fe685c28!8m2!3d19.07118!4d72.87709!16s%2Fg%2F11q8y5nz8r!19sChIJAdkq3fTJ5zsRKFxo_mEIpmk?authuser=0&hl=en&rclk=1 | E10: 4.9 | F10: -580 | G10: Fertility clinic | H10: beside Tata Communications | I10: 084488 01362 | J10: "Helped me with my neck pain and I got instant relief after visiting her." | L10: =J10 & " " & K10 -> "Helped me with my neck pain and I got instant relief after visiting her."
A11: https://www.google.com/aclk?sa=L&ai=DChsSEwjY_q3l5-OVAxXQhWYCHQ6GN9gYACICCAEQCxoCc20&co=1&ase=2&gclid=CjwKCAjwsfzSBhB5EiwAOGyqSa8bJmiInQcnqhYOoPHpcSABmZNKk6Nx2iOESQr5MdFW614cV373-BoCQxYQAvD_BwE&cid=CAAS0wHkaODk9ymShb7Z04lLS_EqdAKOIqLvKgwP3mO86X-_OoEctsv_3FXuaO1jDMNEWv3ZsaacnGcrt3-Gk9imYYv-lk92yoUBAhtU8PsekzJBlAcZE8JTqhMW1Ri9Cl8dHX-gS3iC_vEu4pE8Qq8PN2F0G6O-BdR69zntuUt_QyuM0pZpzrowL4N7RY81oVfCfQwMZtlimOTZSr3hT68g3tlzJ1EG1uxxVNJ8VFlXM33Q9zVdiCzEtCisPeXeyNbjergk15jhHrFRWSXY4aUocK8OraEc&cce=2&category=acrcp_v1_32&sig=AOD64_02BkDFe0onG1zHICP9IauMYOumMw&adurl&q&ctype=99&nis=6 | B11: ART Fertility Clinics | C11: https://www.instagram.com/artfertilityclinics | D11: https://www.google.com/maps/place/ART+Fertility+Clinics/data=!4m7!3m6!1s0x3be7c9f4dd2ad901:0x69a60861fe685c28!8m2!3d19.07118!4d72.87709!16s%2Fg%2F11q8y5nz8r!19sChIJAdkq3fTJ5zsRKFxo_mEIpmk?authuser=0&hl=en&rclk=1 | E11: 4.9 | F11: -580 | G11: Fertility clinic | H11: beside Tata Communications | I11: 084488 01362 | J11: "The staff and | K11: are extremely nice, professional, and caring." | L11: =J11 & " " & K11 -> "The staff and are extremely nice, professional, and caring."
A12: https://www.google.com/aclk?sa=L&ai=DChsSEwjEga3j5-OVAxXGmGYCHSv4L60YACICCAEQBRoCc20&co=1&ase=2&gclid=CjwKCAjwsfzSBhB5EiwAOGyqSTtAOGNHNSBEHIVnrWwP9gSl-fdjqI4VWBDSoXKHVxJLWLVFUHh5sRoCg9UQAvD_BwE&cid=CAAS0wHkaI85O8JJUOylJovBAy-LsWBAB44HDW28jy4X8dGtznyF_isMrSlPwW7sTH5AFdWHT7fxlxZo_JZ0-6d05FV3UdOg7gTP9H3eq3-J7h57WxOX68PrRCxfZFz40lzb70RcGBZfSGcaC1qzUeYsEgxCxQLmuTV3pJINCQRr475x_d4uQwJcjuaNO5akBPEOITW66yCBp0LSyqnvTNALN2-xCkdS_BwF6aN1kh5bBX41yJnvQFFPt6DrUvyf0mC-C3VRKV9d4ElkUmbEsRbpbr2MUDXI&cce=2&category=acrcp_v1_32&sig=AOD64_2VK-l2VpDixYtQZeT_BunAV-iMoA&adurl&q&ctype=99&nis=6 | B12: ASG Eye Hospital | Best Cataract, Lasik & Retina Centre - Vashi, Mumbai | C12: https://www.instagram.com/asgeyehospital | D12: https://www.google.com/maps/place/ASG+Eye+Hospital+%7C+Best+Cataract,+Lasik+%26+Retina+Centre+-+Vashi,+Mumbai/data=!4m7!3m6!1s0x3be7c1f454bd3783:0x9e0b8aaab5dc8756!8m2!3d19.070291!4d72.997918!16s%2Fg%2F11k3d0lph0!19sChIJgze9VPTB5zsRVofctaqKC54?authuser=0&hl=en&rclk=1 | E12: 4.9 | F12: -2924 | G12: Hospital | H12: Plot No 88 | I12: 0674 617 2480 | L12: =J12 & " " & K12
A13: http://aguramrit.org/ | B13: Ayuramrit Ayurved Clinic | C13: Not Found | D13: https://www.google.com/maps/place/Ayuramrit+Ayurved+Clinic/data=!4m7!3m6!1s0x3be7c219996deae3:0xbb9a097635c277e4!8m2!3d19.048221!4d73.0689048!16s%2Fg%2F11c0xvb29b!19sChIJ4-ptmRnC5zsR5HfCNXYJmrs?authuser=0&hl=en&rclk=1 | E13: 4.9 | F13: -100 | G13: Alternative medicine practitioner | H13: Shop No 66/67, Chaturbhuj CHS, Shilp Chowk | I13: +91 76668 05588 | J13: "Both the | K13: are very polite and knowledgeable." | L13: =J13 & " " & K13 -> "Both the are very polite and knowledgeable."
A14: Not Found | B14: Ayush Clinic | C14: Not Found | D14: https://www.google.com/maps/place/Ayush+Clinic/data=!4m7!3m6!1s0x3be7c3ea25555555:0x639edf4685ce5535!8m2!3d19.0341284!4d73.0146921!16s%2Fg%2F11srv8y1lx!19sChIJVVVVJerD5zsRNVXOhUbfnmM?authuser=0&hl=en&rclk=1 | E14: 1 | F14: -1 | G14: Medical clinic | H14: Sector 20, Nerul, Sion, Number 5 Plot Number, B 49, Nerul East, Navi | I14: +91 99672 63283 | J14: "His in depth knowledge has helped me a lot." | L14: =J14 & " " & K14 -> "His in depth knowledge has helped me a lot."
A15: https://www.ayushakti.com/ | B15: Ayushakti Ayurved Health Centre | Panchakarma Clinic in Navi Mumbai | C15: https://www.instagram.com/ayushakti | D15: https://www.google.com/maps/place/Ayushakti+Ayurved+Health+Centre+%7C+Panchakarma+Clinic+in+Navi+Mumbai/data=!4m7!3m6!1s0x3be7c3ab786a6a1f:0x4294e10b00f08572!8m2!3d19.0367236!4d73.0643284!16s%2Fg%2F11g_v6hfzy!19sChIJH2pqeKvD5zsRcoXwAAvhlEI?authuser=0&hl=en&rclk=1 | E15: 4.9 | F15: -274 | G15: Ayurvedic clinic | H15: h.s, shops, Mahavir Shraddha c, Plot no 11-B, opp. Kendriya Vihar Metro Station Road | I15: +91 86578 62385 | J15: "The treatments have made a noticeable difference in my skin and hair health." | L15: =J15 & " " & K15 -> "The treatments have made a noticeable difference in my skin and hair health."
A16: https://www.bcaclinicindia.com/ | B16: BCA CLINIC NAVI MUMBAI by Deepali Banerjee | C16: https://www.instagram.com/bcaclinicindia | D16: https://www.google.com/maps/place/BCA+CLINIC+NAVI+MUMBAI+by+Deepali+Banerjee/data=!4m7!3m6!1s0x3be7c1f3065cab8d:0x6bfadc5f2fe74d8b!8m2!3d19.053278!4d73.0070932!16s%2Fg%2F11zjvpwdcc!19sChIJjatcBvPB5zsRi03nL1_c-ms?authuser=0&hl=en&rclk=1 | G16: Skin care clinic | H16: PLOT NO.- 88, 18, Palm Beach Rd | J16: "⭐⭐⭐⭐⭐ Dr. FM Chogle is very friendly and highly experienced." | L16: =J16 & " " & K16 -> "⭐⭐⭐⭐⭐ Dr. FM Chogle is very friendly and highly experienced."
A17: http://www.drsupriyaskinandhairclinic.com/ | B17: Be You Aesthetics Clinic- Ayurvedic doctor | C17: Not Found | D17: https://www.google.com/maps/place/Be+You+Aesthetics+Clinic-+Ayurvedic+doctor/data=!4m7!3m6!1s0x3be7c3a6d49e90cb:0x353b6db365b25829!8m2!3d19.0262789!4d73.0427916!16s%2Fg%2F11vq9n9ls0!19sChIJy5Ce1KbD5zsRKViyZbNtOzU?authuser=0&hl=en&rclk=1 | E17: 4.9 | F17: -16 | G17: Skin care clinic | H17: ground floor, Sector 4, Neelkanth Apartments, C-5/8/0:4, beside Akshar investment services | I17: +91 87796 00322 | J17: "The staff is friendly and the | K17: is clean and well-equipped" | L17: =J17 & " " & K17 -> "The staff is friendly and the is clean and well-equipped"
A18: https://www.centreforsight.net/eye-hospitals-in-india/mumbai/navi-mumbai?utm_source=GMB&utm_medium=Local+Pack&utm_campaign=GMB_Navi_Mumbai_Mumbai | B18: Centre For Sight | Nerul | Navi Mumbai | C18: https://www.instagram.com/centreforsightindia | D18: https://www.google.com/maps/place/Centre+For+Sight+%7C+Nerul+%7C+Navi+Mumbai/data=!4m7!3m6!1s0x3be7c3c6b1555555:0x7a370656617c2e06!8m2!3d19.0238561!4d73.021885!16s%2Fg%2F1ptwt1mns!19sChIJVVVVscbD5zsRBi58YVYGN3o?authuser=0&hl=en&rclk=1 | E18: 4.9 | F18: -1690 | G18: Eye care center | H18: at Shivam Eye Foundation, Plot no. 14, beside Bihar Bhavan, behind HP Petrol Pump | I18: +91 80 6542 3838 | J18: "The | K18: and staff communicate well with patients." | L18: =J18 & " " & K18 -> "The and staff communicate well with patients."
A19: https://www.cloudninecare.com/centre/vashi?utm_city=mumbai&utm_source=gmb&utm_medium=organic&utm_campaign=mumbai+vashi+c9-hospital-gmb-website+c9-hospital-vashi&utm_content=website-button | B19: Cloudnine Hospital - Vashi | Maternity & Pregnancy Centre | C19: https://www.instagram.com/cloudninecare | D19: https://www.google.com/maps/place/Cloudnine+Hospital+-+Vashi+%7C+Maternity+%26+Pregnancy+Centre/data=!4m7!3m6!1s0x3be7c15eab21a345:0x7a38770bca94d1c0!8m2!3d19.0852316!4d73.007675!16s%2Fg%2F11f0_gktyv!19sChIJRaMhq17B5zsRwNGUygt3OHo?authuser=0&hl=en&rclk=1 | E19: 4.7 | F19: -3862 | G19: Maternity hospital | H19: · | I19: +91 99728 99728 | J19: "Procedure was thoroughly explained and post operative care was meticulous." | L19: =J19 & " " & K19 -> "Procedure was thoroughly explained and post operative care was meticulous."
A20: https://clovedental.in/dentist-near-me/navi-mumbai/sector-8nerulnavi-mumbai?utm_source=website&utm_medium=gmb&utm_campaign=Sector_8_Nerul_Navi_Mumbai_GMB | B20: Clove Dental Clinic - Nerul Sector 8, Navi Mumbai | C20: https://www.instagram.com/clovedentalindia | D20: https://www.google.com/maps/place/Clove+Dental+Clinic+-+Nerul+Sector+8,+Navi+Mumbai/data=!4m7!3m6!1s0x3be7c38379107e29:0xa53fc15c83c872c2!8m2!3d19.040947!4d73.0148091!16s%2Fg%2F11y7tg53v2!19sChIJKX4QeYPD5zsRwnLIg1zBP6U?authuser=0&hl=en&rclk=1 | E20: 4.9 | F20: -99 | G20: Dental clinic | H20: Ground Floor, Aryan Hospital, near, Hanuman Mandir Rd | I20: +91 11 6927 1067 | J20: "Best service Dr Sunayna is very nice and courteous." | L20: =J20 & " " & K20 -> "Best service Dr Sunayna is very nice and courteous."
A21: http://www.kbcclinics.com/ | B21: Cosmetic & Hair Transplant Clinic | C21: https://www.instagram.com/kbcclinics | D21: https://www.google.com/maps/place/Cosmetic+%26+Hair+Transplant+Clinic/data=!4m7!3m6!1s0x3be7c91028e4cc13:0x228f3ccb6c59d7d7!8m2!3d19.0246875!4d73.0221875!16s%2Fg%2F11bzwrt9t_!19sChIJE8zkKBDJ5zsR19dZbMs8jyI?authuser=0&hl=en&rclk=1 | E21: 4.3 | F21: -175 | G21: Plastic surgery clinic | H21: 22FC+VVC Hawares Centurion Mall, S04C | J21: On-site services not available | L21: =J21 & " " & K21 -> On-site services not available
A22: https://dypatilhospitals.com/ | B22: D Y Patil Hospital | C22: https://www.instagram.com/dypatilhospital | D22: https://www.google.com/maps/place/D+Y+Patil+Hospital/data=!4m7!3m6!1s0x3be7c618a5555555:0xa446b85191e625c8!8m2!3d19.0411561!4d73.0246854!16s%2Fg%2F11csrv8x53!19sChIJVVVVpRjG5zsRyCXmkVG4RqQ?authuser=0&hl=en&rclk=1 | E22: 4.1 | F22: -3440 | G22: Hospital | H22: Ayyappa Temple Rd | I22: +91 22 6517 5901 | J22: On-site services not available | L22: =J22 & " " & K22 -> On-site services not available
A23: http://dentalpulseclinic.com/ | B23: Dental Pulse Clinic | C23: Not Found | D23: https://www.google.com/maps/place/Dental+Pulse+Clinic/data=!4m7!3m6!1s0x3be7c3c0e2af0db3:0x5ae99b51c2d5444!8m2!3d19.0309791!4d73.0217513!16s%2Fg%2F11df80zt_8!19sChIJsw2v4sDD5zsRRFQtHLWZrgU?authuser=0&hl=en&rclk=1 | E23: 4.9 | F23: -147 | G23: Dental clinic | H23: 1st Floor, Doctor House, 102 E, near D-Mart Junction | I23: +91 83692 40730 | J23: "Staff is supportive, rooms are clean, and | K23: was affordable." | L23: =J23 & " " & K23 -> "Staff is supportive, rooms are clean, and was affordable."
A24: Not Found | B24: Dermed Clinic | C24: Not Found | D24: https://www.google.com/maps/place/Dermed+Clinic/data=!4m7!3m6!1s0x3be7c397bee9aa87:0xed9c3ab75bb93e8c!8m2!3d19.0182874!4d73.0123738!16s%2Fg%2F11c5zxh3vr!19sChIJh6rpvpfD5zsRjD65W7c6nO0?authuser=0&hl=en&rclk=1 | E24: 4.2 | F24: -75 | G24: Doctor | H24: Plot No 15, W, Shop 5, 6 & 7 Chamunda Serene | I24: +91 98926 82878 | J24: "Dr fees Also reasonable." | L24: =J24 & " " & K24 -> "Dr fees Also reasonable."
A25: https://drashwathyharidas.com/ | B25: Dr Ashwathy Haridas | Kidney and Hypertension Clinic | Best Nephrologist In Navi Mumbai | C25: https://www.instagram.com/drashwathyharidas | D25: https://www.google.com/maps/place/Dr+Ashwathy+Haridas+%7C+Kidney+and+Hypertension+Clinic+%7C+Best+Nephrologist+In+Navi+Mumbai/data=!4m7!3m6!1s0x3be7c3bed8600a5f:0x62b29724444747d8!8m2!3d19.0131344!4d73.012722!16s%2Fg%2F11s3zl3vxw!19sChIJXwpg2L7D5zsR2EdHRCSXsmI?authuser=0&hl=en&rclk=1 | E25: 5 | F25: -59 | G25: Nephrologist | H25: Shop No. 7, Ground floor, Dr Ashwathy's Kidney & Hypertension Clinic, The Signature, Plot Nr. 71, near HP Petrol Pump | I25: +91 91366 24877 | J25: On-site services not available | L25: =J25 & " " & K25 -> On-site services not available
A26: https://clinics.drbatras.com/navi-mumbai/homeopathy-clinic-sector-21 | B26: Dr Batra’s Homeopathy Clinic | C26: https://www.instagram.com/drbatrashealthcare | D26: https://www.google.com/maps/place/Dr+Batra%E2%80%99s+Homeopathy+Clinic/data=!4m7!3m6!1s0x3be7c3c0c782483b:0xe0a102e770fe4288!8m2!3d19.0310537!4d73.0217795!16s%2Fg%2F12hr5cmft!19sChIJO0iCx8DD5zsRiEL-cOcCoeA?authuser=0&hl=en&rclk=1 | E26: 4.6 | F26: -1050 | G26: Homeopath | H26: 1st Floor, No 101 & 103, Plot No 101, near D Mart | I26: +91 70450 06060 | J26: "Staff is friendly and understanding, | K26: is performed accurately." | L26: =J26 & " " & K26 -> "Staff is friendly and understanding, is performed accurately."
A27: Not Found | B27: Dr Chandan Saha MBBS Clinic | C27: Not Found | D27: https://www.google.com/maps/place/Dr+Chandan+Saha+MBBS+Clinic/data=!4m7!3m6!1s0x3be7c346e855170b:0x91ca99af8cacdbea!8m2!3d19.0401059!4d73.0176641!16s%2Fg%2F11c2qpjp0n!19sChIJCxdV6EbD5zsR6tusjK-ZypE?authuser=0&hl=en&rclk=1 | E27: 4.4 | F27: -36 | G27: General practitioner | H27: Shop Number E1 /1 C 4, next to Sai Baba Hotel | I27: +91 98210 39426 | J27: "Diagnosis was on point and | K27: was very effective" | L27: =J27 & " " & K27 -> "Diagnosis was on point and was very effective"
A28: https://myheartclinics.com/index.php | B28: Dr Ghogare's | C28: https://www.instagram.com/myheartclinics | D28: https://www.google.com/maps/place/Dr+Ghogare%27s/data=!4m7!3m6!1s0x3be7c331998fcdeb:0xfd98877b283a9f5e!8m2!3d19.0250148!4d73.0223871!16s%2Fg%2F11h54x3yfp!19sChIJ682PmTHD5zsRXp86KHuHmP0?authuser=0&hl=en&rclk=1 | E28: 4.7 | F28: -41 | G28: Medical clinic | H28: 1st Floor, Haware Centurion, F-2, near Seawoods Station Road | I28: +91 90281 70123 | L28: =J28 & " " & K28
A29: https://www.drjairajshospital.com/ | B29: Dr Jairajs Hospital | C29: Not Found | D29: https://www.google.com/maps/place/Dr+Jairajs+Hospital/data=!4m7!3m6!1s0x3be7c3ad73247343:0x7957b177cdfbb2a9!8m2!3d19.0252216!4d73.041946!16s%2Fg%2F1tg_dh_c!19sChIJQ3Mkc63D5zsRqbL7zXexV3k?authuser=0&hl=en&rclk=1 | E29: 3.8 | F29: -82 | G29: Private hospital | H29: 2nd Floor, Om Chanakya Complex | I29: +91 70450 11188 | J29: "The | K29: is clean and well - managed , Thank You for all care and support" | L29: =J29 & " " & K29 -> "The is clean and well - managed , Thank You for all care and support"
A30: https://www.google.com/aclk?sa=L&ai=DChsSEwjY_q3l5-OVAxXQhWYCHQ6GN9gYACICCAEQAhoCc20&co=1&ase=2&gclid=CjwKCAjwsfzSBhB5EiwAOGyqScQrE05nG84DLc6zM3CT0ECLsZPDstKPGssFpOVH50_pSqQpix5jAhoChTMQAvD_BwE&cid=CAAS0wHkaODk9ymShb7Z04lLS_EqdAKOIqLvKgwP3mO86X-_OoEctsv_3FXuaO1jDMNEWv3ZsaacnGcrt3-Gk9imYYv-lk92yoUBAhtU8PsekzJBlAcZE8JTqhMW1Ri9Cl8dHX-gS3iC_vEu4pE8Qq8PN2F0G6O-BdR69zntuUt_QyuM0pZpzrowL4N7RY81oVfCfQwMZtlimOTZSr3hT68g3tlzJ1EG1uxxVNJ8VFlXM33Q9zVdiCzEtCisPeXeyNbjergk15jhHrFRWSXY4aUocK8OraEc&cce=2&category=acrcp_v1_32&sig=AOD64_2DBhIsv40g5AAZmcura5Ue0IhxNw&adurl&q&ctype=99&nis=6 | B30: Dr Karve's Dentech | C30: https://www.instagram.com/drbatrashealthcare | D30: https://www.google.com/maps/place/Dr+Karve%27s+Dentech/data=!4m7!3m6!1s0x3be7c7e6674bdb77:0x5a92f706cb9de866!8m2!3d19.118699!4d72.916476!16s%2Fg%2F11clyc21yl!19sChIJd9tLZ-bH5zsRZuidywb3klo?authuser=0&hl=en&rclk=1 | E30: 5 | F30: -471 | G30: Dental clinic | H30: besides akshardham temple | I30: 022 2570 4247 | J30: "It provided me a long-term relief." | L30: =J30 & " " & K30 -> "It provided me a long-term relief."
A31: https://onehealthclinicmumbai.com/ | B31: Dr Madhav Dawkore – Pulmonologist & Allergy Specialist Navi mumbai | C31: Not Found | D31: https://www.google.com/maps/place/Dr+Madhav+Dawkore+%E2%80%93+Pulmonologist+%26+Allergy+Specialist+Navi+mumbai/data=!4m7!3m6!1s0x3be7c38546bb6453:0x67973f0a6aee839d!8m2!3d19.0505159!4d73.0161525!16s%2Fg%2F11t2t_f_pd!19sChIJU2S7RoXD5zsRnYPuago_l2c?authuser=0&hl=en&rclk=1 | E31: 5 | F31: -255 | G31: Pulmonologist | H31: Vikram Plaza, Plot no 10 | I31: +91 95941 97549 | J31: "The | K31: is friendly, and the office is clean." | L31: =J31 & " " & K31 -> "The is friendly, and the office is clean."
A32: https://www.drmaheshghogare.com/ | B32: Dr Mahesh Ghogare, BEST CARDIOLOGIST in Navi Mumbai, Interventional Cardiologist Navi Mumbai, TAVI / TAVR in Navi Mumbai | C32: Not Found | D32: https://www.google.com/maps/place/Dr+Mahesh+Ghogare,+BEST+CARDIOLOGIST+in+Navi+Mumbai,+Interventional+Cardiologist+Navi+Mumbai,+TAVI+%2F+TAVR+in+Navi+Mumbai/data=!4m7!3m6!1s0x3be7c142b0000001:0x9289e16f76d9552c!8m2!3d19.0246581!4d73.0222576!16s%2Fg%2F11hbdqx50v!19sChIJAQAAsELB5zsRLFXZdm_hiZI?authuser=0&hl=en&rclk=1 | E32: 4.9 | F32: -749 | G32: Cardiologist | H32: My Heart Clinics, F 02, First Floor, Haware's Centurion, near Seawoods Station | I32: +91 90281 70123 | J32: "Dr. Harshad is really good at diagnosing the issue." | L32: =J32 & " " & K32 -> "Dr. Harshad is really good at diagnosing the issue."
A33: Not Found | B33: Dr Modak's Harmony Homoeopathic Clinic | C33: Not Found | D33: https://www.google.com/maps/place/Dr+Modak%27s+Harmony+Homoeopathic+Clinic/data=!4m7!3m6!1s0x3be7c371d7cc6ab3:0x54f5a88bb02c46cd!8m2!3d19.0227311!4d73.0211799!16s%2Fg%2F11ghpzk27l!19sChIJs2rM13HD5zsRzUYssIuo9VQ?authuser=0&hl=en&rclk=1 | E33: 4.9 | F33: -115 | G33: Medical clinic | H33: CHS, Shop 01B, opp. Millenium Park Garden | I33: +91 98337 15477 | J33: "Good | K33: ." | L33: =J33 & " " & K33 -> "Good ."
A34: https://arogyabhet.com/ | B34: Dr Nagarekar Atharva Ayurveda clinic | C34: https://www.instagram.com/arogyabhet | D34: https://www.google.com/maps/place/Dr+Nagarekar+Atharva+Ayurveda+clinic/data=!4m7!3m6!1s0x3be7c34e2ebae60b:0xf2affcd51305bbe6!8m2!3d19.0403047!4d73.0152992!16s%2Fg%2F11h08dmsz8!19sChIJC-a6Lk7D5zsR5rsFE9X8r_I?authuser=0&hl=en&rclk=1 | E34: 5 | F34: -44 | G34: Medical clinic | H34: Plot no. 29, 105, sector 10, near sarsole depot | I34: +91 77770 70531 | J34: "I came in with severe pain, and I’m leaving with incredible results." | L34: =J34 & " " & K34 -> "I came in with severe pain, and I’m leaving with incredible results."
A35: Not Found | B35: Dr Omkar Mate's Midas Clinic | C35: Not Found | D35: https://www.google.com/maps/place/Dr+Omkar+Mate%27s+Midas+Clinic/data=!4m7!3m6!1s0x3be7c385d4d7de89:0x65fcbd4711f70a25!8m2!3d19.0332773!4d73.0180734!16s%2Fg%2F11gmg60rsv!19sChIJid7X1IXD5zsRJQr3EUe9_GU?authuser=0&hl=en&rclk=1 | E35: 4.7 | F35: -3 | G35: Medical clinic | H35: Station Complex, E102, Mata Amritanandamayi Marg | I35: +91 91673 59313 | J35: On-site services | L35: =J35 & " " & K35 -> On-site services
A36: Not Found | B36: Dr Pallavi Clinic | C36: Not Found | D36: https://www.google.com/maps/place/Dr+Pallavi+Clinic/data=!4m7!3m6!1s0x3be7c324c2fee1a7:0x955cfc8ff5ea8c55!8m2!3d19.0298618!4d73.0153222!16s%2Fg%2F11k434fxvp!19sChIJp-H-wiTD5zsRVYzq9Y_8XJU?authuser=0&hl=en&rclk=1 | E36: 5 | F36: -1 | G36: Medical clinic | H36: Terna Hospital, Plot No 12, Sector 22, opposite Nerul Railway Station | J36: "Clean | K36: , smooth consultation process, and a comfortable atmosphere." | L36: =J36 & " " & K36 -> "Clean , smooth consultation process, and a comfortable atmosphere."
A37: https://www.drpoojabansal.com/ | B37: Dr Pooja Bansal | C37: https://www.instagram.com/drpoojabansal | D37: https://www.google.com/maps/place/Dr+Pooja+Bansal/data=!4m7!3m6!1s0x3be7c3c6b6dc9349:0x103422387181eb13!8m2!3d19.0274048!4d73.0231625!16s%2Fg%2F11hzxf985w!19sChIJSZPctsbD5zsRE-uBcTgiNBA?authuser=0&hl=en&rclk=1 | E37: 4.9 | F37: -757 | G37: Obstetrician-gynecologist | H37: · | I37: +91 70453 13773 | J37: On-site services | L37: =J37 & " " & K37 -> On-site services
A38: Not Found | B38: Dr Rahul Bhatambre | C38: Not Found | D38: https://www.google.com/maps/place/Dr+Rahul+Bhatambre/data=!4m7!3m6!1s0x3be7c26a3fe726fb:0x9f05e057e93983a9!8m2!3d19.0334848!4d73.0655577!16s%2Fg%2F11c74_7fjp!19sChIJ-ybnP2rC5zsRqYM56VfgBZ8?authuser=0&hl=en&rclk=1 | E38: 4.8 | F38: -525 | G38: Psychiatrist | H38: Second Floor ,Shop No 6 and 7, Mansparsh Clinic, Hiranandani Crystal Plaza | I38: +91 77382 05586 | L38: =J38 & " " & K38
A39: https://drrajaeyecare.com/ | B39: Dr Raja | C39: https://www.instagram.com/drrajaeyecare | D39: https://www.google.com/maps/place/Dr+Raja/data=!4m7!3m6!1s0x3be7c717d4113341:0x5a2dbcad616792fc!8m2!3d19.0365259!4d73.017463!16s%2Fg%2F11fkhdl2g6!19sChIJQTMR1BfH5zsR_JJnYa28LVo?authuser=0&hl=en&rclk=1 | E39: 4.9 | F39: -590 | G39: Eye care center | H39: Office 2,3 1st floor, good will building, Station Road | I39: +91 81044 41581 | J39: "Medical facilities are modern, and the staff is professional and supportive." | L39: =J39 & " " & K39 -> "Medical facilities are modern, and the staff is professional and supportive."
A40: Not Found | B40: Dr Rajendra Patil.Clinic. | C40: Not Found | D40: https://www.google.com/maps/place/Dr+Rajendra+Patil.Clinic./data=!4m7!3m6!1s0x3be7c391b825dab5:0x7c8e84734ab868ca!8m2!3d19.037853!4d73.01539!16s%2Fg%2F11t5jdl1sh!19sChIJtdoluJHD5zsRymi4SnOEjnw?authuser=0&hl=en&rclk=1 | E40: 4.6 | F40: -22 | G40: Doctor | H40: 20.A, 4, West | I40: +91 98202 59594 | J40: "Significant relief from | K40: ." | L40: =J40 & " " & K40 -> "Significant relief from ."
...

Sheet Cleaned
A1: Website | B1: Clinic Names | C1: Instagram | D1: Google Maps | E1: Rating | F1: Reviews | G1: Specialization | H1: Location | I1: Contact | J1: Remarks | K1: Opportunity | L1: Category
A2: http://www.360homeocareclinic.com/ | B2: 360 HOMEO CARE CLINIC | C2: Not Found | D2: https://www.google.com/maps/place/360+HOMEO+CARE+CLINIC/data=!4m7!3m6!1s0x3be7c3bbdb4eb027:0x9e0cb6fa5c230ae6!8m2!3d19.0233747!4d73.0248128!16s%2Fg%2F11cmcb1kz9!19sChIJJ7BO27vD5zsR5gojXPq2DJ4?authuser=0&hl=en&rclk=1 | E2: 5 | F2: 152 | G2: Medical clinic | H2: Shop No. 3, Ganpati Complex, Plot No. 105 | K2: Medium | L2: Digital marketing
A3: https://naneshhospital.com/ | B3: Acharya Shri Nanesh Hospital | C3: https://www.instagram.com/naneshhospital | D3: https://www.google.com/maps/place/Acharya+Shri+Nanesh+Hospital/data=!4m7!3m6!1s0x3be7c23539fec13b:0xd98d02fabb970045!8m2!3d19.033325!4d73.041195!16s%2Fg%2F12cpldkhr!19sChIJO8H-OTXC5zsRRQCXu_oCjdk?authuser=0&hl=en&rclk=1 | E3: 4.7 | F3: 599 | G3: Private hospital | H3: Plot No 34-37 | I3: =+91 86930 84084 -> #ERROR! | K3: Low | L3: None
A4: https://drnevinaabraham.getmy.clinic/ | B4: Alpha Dental Clinic | C4: https://www.instagram.com/dr.nevin.abraham | D4: https://www.google.com/maps/place/Alpha+Dental+Clinic/data=!4m7!3m6!1s0x3be7c3bd7981ef7d:0x45908abf3f22a486!8m2!3d19.0202786!4d73.0173018!16s%2Fg%2F11gcmmc1lr!19sChIJfe-Beb3D5zsRhqQiP7-KkEU?authuser=0&hl=en&rclk=1 | E4: 5 | F4: 263 | G4: Dental clinic | H4: Shop No.11, Shreeji Seva CHS, Plot No.42 | K4: Low | L4: None
A5: Not Found | B5: Anand Clinic | C5: Not Found | D5: https://www.google.com/maps/place/Anand+Clinic/data=!4m7!3m6!1s0x3be7c3c303802b3d:0x286a0ce386758130!8m2!3d19.038677!4d73.0197082!16s%2Fg%2F11bw4jpygq!19sChIJPSuAA8PD5zsRMIF1huMMaig?authuser=0&hl=en&rclk=1 | E5: 5 | F5: 5 | G5: Medical clinic | H5: F-3, Jagatguru Aadi Shankracharya Marg | J5: "The plan was thorough and the results are visible." | K5: High | L5: Both
A6: Not Found | B6: Aniruddha Health Clinic | C6: Not Found | D6: https://www.google.com/maps/place/Aniruddha+Health+Clinic/data=!4m7!3m6!1s0x3be7c24cb71e71f9:0x2fdc4500545e765a!8m2!3d19.0246747!4d73.0410086!16s%2Fg%2F11tdl6tyx6!19sChIJ-XEet0zC5zsRWnZeVABF3C8?authuser=0&hl=en&rclk=1 | F6: nan | G6: Medical clinic | H6: Shop Number 69, Prabhat Centre 1st Floor Plot 7 Sector Number 1a C B D Belapur Navi Mumbai | I6: =+91 97696 95873 -> #ERROR! | J6: "The is clean, well-organized, and staff is friendly too." | K6: High | L6: Both
A7: https://www.apollohospitals.com/hospitals/apollo-hospitals-mumbai | B7: Apollo Hospital | C7: https://www.instagram.com/theapollohospitals | D7: https://www.google.com/maps/place/Apollo+Hospital,/data=!4m7!3m6!1s0x3be7c3903a3c9297:0xb858a25d34856005!8m2!3d19.0208646!4d73.0287337!16s%2Fg%2F11plkkvf08!19sChIJl5I8OpDD5zsRBWCFNF2iWLg?authuser=0&hl=en&rclk=1 | E7: 4.7 | F7: 28262 | G7: Hospital | H7: Plot no 13, Parsik Hill Rd, off Uran Road | I7: =+91 80 6297 2766 -> #ERROR! | J7: "A rare combination of expertise, compassion, and genuine care." | K7: Low | L7: None
A8: https://www.apollohospitals.com/ | B8: Apollo ProHealth - Navi Mumbai | C8: https://www.instagram.com/theapollohospitals | D8: https://www.google.com/maps/place/Apollo+ProHealth+-+Navi+Mumbai/data=!4m7!3m6!1s0x3be7c3d15044d7e7:0xbdebc5b46159df7a!8m2!3d19.020968!4d73.029081!16s%2Fg%2F11ltlczckh!19sChIJ59dEUNHD5zsRet9ZYbTF670?authuser=0&hl=en&rclk=1 | E8: 1 | F8: 1 | G8: Health consultant | H8: Plot 13, Parsik Hill Rd, off Uran Road, opp. Nerul Wonders Park | I8: =+91 80 6942 0449 -> #ERROR! | J8: "The Receptionist is also very professional and Cooperative." | K8: Low | L8: None
A9: Not Found | B9: Arihant Clinic | C9: Not Found | D9: https://www.google.com/maps/place/Arihant+Clinic/data=!4m7!3m6!1s0x3be7c3bf00b5c935:0x32e3708e152d2cd1!8m2!3d19.0269386!4d73.0201229!16s%2Fg%2F113gbxqjy!19sChIJNcm1AL_D5zsR0SwtFY5w4zI?authuser=0&hl=en&rclk=1 | E9: 4.5 | F9: 10 | G9: Doctor | H9: 1st floor, Plot No 312 | I9: =+91 90041 31975 -> #ERROR! | J9: "Great work by dr" | K9: High | L9: Both
A10: https://www.google.com/aclk?sa=L&ai=DChsSEwjEga3j5-OVAxXGmGYCHSv4L60YACICCAEQABoCc20&co=1&ase=2&gclid=CjwKCAjwsfzSBhB5EiwAOGyqSRqHv8zm3JQ3XITZthGBOX6tl3OqxVUzpxkmKhbFNu2bIerIQf8YMBoCjJMQAvD_BwE&cid=CAAS0wHkaI85O8JJUOylJovBAy-LsWBAB44HDW28jy4X8dGtznyF_isMrSlPwW7sTH5AFdWHT7fxlxZo_JZ0-6d05FV3UdOg7gTP9H3eq3-J7h57WxOX68PrRCxfZFz40lzb70RcGBZfSGcaC1qzUeYsEgxCxQLmuTV3pJINCQRr475x_d4uQwJcjuaNO5akBPEOITW66yCBp0LSyqnvTNALN2-xCkdS_BwF6aN1kh5bBX41yJnvQFFPt6DrUvyf0mC-C3VRKV9d4ElkUmbEsRbpbr2MUDXI&cce=2&category=acrcp_v1_32&sig=AOD64_2AXjq4v1QR-MsYwLJX71Qe77Pj0A&adurl&q&ctype=99&nis=6 | B10: ART Fertility Clinics | C10: https://www.instagram.com/artfertilityclinics | D10: https://www.google.com/maps/place/ART+Fertility+Clinics/data=!4m7!3m6!1s0x3be7c9f4dd2ad901:0x69a60861fe685c28!8m2!3d19.07118!4d72.87709!16s%2Fg%2F11q8y5nz8r!19sChIJAdkq3fTJ5zsRKFxo_mEIpmk?authuser=0&hl=en&rclk=1 | E10: 4.9 | F10: 580 | G10: Fertility clinic | H10: beside Tata Communications | I10: 084488 01362 | J10: "Helped me with my neck pain and I got instant relief after visiting her." | K10: Low | L10: None
A11: https://www.google.com/aclk?sa=L&ai=DChsSEwjY_q3l5-OVAxXQhWYCHQ6GN9gYACICCAEQCxoCc20&co=1&ase=2&gclid=CjwKCAjwsfzSBhB5EiwAOGyqSa8bJmiInQcnqhYOoPHpcSABmZNKk6Nx2iOESQr5MdFW614cV373-BoCQxYQAvD_BwE&cid=CAAS0wHkaODk9ymShb7Z04lLS_EqdAKOIqLvKgwP3mO86X-_OoEctsv_3FXuaO1jDMNEWv3ZsaacnGcrt3-Gk9imYYv-lk92yoUBAhtU8PsekzJBlAcZE8JTqhMW1Ri9Cl8dHX-gS3iC_vEu4pE8Qq8PN2F0G6O-BdR69zntuUt_QyuM0pZpzrowL4N7RY81oVfCfQwMZtlimOTZSr3hT68g3tlzJ1EG1uxxVNJ8VFlXM33Q9zVdiCzEtCisPeXeyNbjergk15jhHrFRWSXY4aUocK8OraEc&cce=2&category=acrcp_v1_32&sig=AOD64_02BkDFe0onG1zHICP9IauMYOumMw&adurl&q&ctype=99&nis=6 | B11: ART Fertility Clinics | C11: https://www.instagram.com/artfertilityclinics | D11: https://www.google.com/maps/place/ART+Fertility+Clinics/data=!4m7!3m6!1s0x3be7c9f4dd2ad901:0x69a60861fe685c28!8m2!3d19.07118!4d72.87709!16s%2Fg%2F11q8y5nz8r!19sChIJAdkq3fTJ5zsRKFxo_mEIpmk?authuser=0&hl=en&rclk=1 | E11: 4.9 | F11: 580 | G11: Fertility clinic | H11: beside Tata Communications | I11: 084488 01362 | J11: "The staff and are extremely nice, professional, and caring." | K11: Low | L11: None
A12: https://www.google.com/aclk?sa=L&ai=DChsSEwjEga3j5-OVAxXGmGYCHSv4L60YACICCAEQBRoCc20&co=1&ase=2&gclid=CjwKCAjwsfzSBhB5EiwAOGyqSTtAOGNHNSBEHIVnrWwP9gSl-fdjqI4VWBDSoXKHVxJLWLVFUHh5sRoCg9UQAvD_BwE&cid=CAAS0wHkaI85O8JJUOylJovBAy-LsWBAB44HDW28jy4X8dGtznyF_isMrSlPwW7sTH5AFdWHT7fxlxZo_JZ0-6d05FV3UdOg7gTP9H3eq3-J7h57WxOX68PrRCxfZFz40lzb70RcGBZfSGcaC1qzUeYsEgxCxQLmuTV3pJINCQRr475x_d4uQwJcjuaNO5akBPEOITW66yCBp0LSyqnvTNALN2-xCkdS_BwF6aN1kh5bBX41yJnvQFFPt6DrUvyf0mC-C3VRKV9d4ElkUmbEsRbpbr2MUDXI&cce=2&category=acrcp_v1_32&sig=AOD64_2VK-l2VpDixYtQZeT_BunAV-iMoA&adurl&q&ctype=99&nis=6 | B12: ASG Eye Hospital | Best Cataract, Lasik & Retina Centre - Vashi, Mumbai | C12: https://www.instagram.com/asgeyehospital | D12: https://www.google.com/maps/place/ASG+Eye+Hospital+%7C+Best+Cataract,+Lasik+%26+Retina+Centre+-+Vashi,+Mumbai/data=!4m7!3m6!1s0x3be7c1f454bd3783:0x9e0b8aaab5dc8756!8m2!3d19.070291!4d72.997918!16s%2Fg%2F11k3d0lph0!19sChIJgze9VPTB5zsRVofctaqKC54?authuser=0&hl=en&rclk=1 | E12: 4.9 | F12: 2924 | G12: Hospital | H12: Plot No 88 | I12: 0674 617 2480 | K12: Low | L12: None
