Workbook

Sheet Notes
C7: YOGA LEADS MUMBAI - COLLECTED AND PREPARED BY AKISHABHUJEL@GMAIL.COM
C11: YOGA INSTITUTE DATASET
C13: LOCATION - NAVI MUMBAI
C15: TOTAL UNIQUE DATAS - 108. DATA COLLECTED NAMES, CONTACT, WEBSITE, LOCATION, INDUSTRY.
C17: EVERYTHING IN THE SHEET ARE COLLECTED FROM PUBLIC AVAILABLE INFORMATION ON GOOGLE.

Sheet Raw
A1: OSrXXb | B1: rllt__details | C1: yi40Hd | D1: Reviews | E1: rllt__details 2 | F1: rllt__details 3 | G1: rllt__details 4 | H1: rllt__details 5 | I1: uDyWh | J1: yYlJEf href | K1: QuU3Wb | L1: yYlJEf href 2 | M1: QuU3Wb 2 | N1: uDyWh 2
A2: Yog with Sushmita | B2: · Yoga studio | C2: 4.8 | D2: -156 | E2: 7+ years in business · Navi Mumbai, Maharashtra, India | F2: · +91 70453 52810 | G2: · Closes 9:30 PM | H2: Open | I2: "Love the positive energy here & the instructor is very skilled." | J2: https://www.sushmitamukhia.co.in/ | K2: Website | L2: https://www.google.com/maps/dir//Plot+no+18a,+Yog+with+Sushmita,+Shree+Ganesh+CHSL,+Shop+Num+7+%26+8,+Plot+number+18+A,+Sector+14,+Sanpada,+Navi+Mumbai,+Maharashtra+400705,+India/data=!4m6!4m5!1m1!4e2!1m2!1m1!1s0x3be7c11941d09c61:0xdcb3e77543ed6203?sa=X&ved=1t:57443&ictx=111 | M2: Directions
A3: Yoga Vidya Niketan"s "YOG BHAVAN" | B3: · Yoga studio | C3: 4.8 | D3: -263 | E3: 10+ years in business · Navi Mumbai, Maharashtra, India | F3: · +91 93216 43305 | G3: · Closes 8 PM | H3: Open | I3: "The course prepares one as a confident teacher ." | J3: https://yogavidyaniketan.zohocommerce.in/ | K3: Website | L3: https://www.google.com/maps/dir//Yoga+Vidya+Niketan%22s+%22YOG+BHAVAN%22,+Yoga+Vidya+Niketan,+Plot+No:14,+Chowk,+Sector+9A,+Vashi,+Navi+Mumbai,+Maharashtra+400703,+India/data=!4m6!4m5!1m1!4e2!1m2!1m1!1s0x3be7c1338fffffff:0xc7e47b3442ab3ca6?sa=X&ved=1t:57443&ictx=111 | M3: Directions | N3: yoga
A4: International Sahaja Yoga Research and Health Centre | B4: · Yoga studio | C4: 4.8 | D4: -256 | E4: Navi Mumbai, Maharashtra, India | F4: · +91 83691 10612 | G4: · Closes 6 PM | H4: Open | I4: "Adopt Sahaja meditation , elevate your life." | J4: https://www.sahajahealthcentre.com/ | K4: Website | L4: https://www.google.com/maps/dir//International+Sahaja+Yoga+Research+and+Health+Centre,+Plot+No.+1,+Sector+8,+CBD+Belapur,+Navi+Mumbai,+Maharashtra+400614,+India/data=!4m6!4m5!1m1!4e2!1m2!1m1!1s0x3be7c3b535fd037f:0x135a7312f6ca3990?sa=X&ved=1t:57443&ictx=111 | M4: Directions | N4: yoga
A5: Yoga Sadhana Mandir | B5: · Yoga studio | C5: 4.9 | D5: -160 | E5: 10+ years in business · Navi Mumbai, Maharashtra, India | F5: · +91 98673 85786 | G5: · Closes 9 PM | H5: Open | I5: "In this classes, the teachers are really well experienced." | J5: https://www.ysmyoga.com/ | K5: Website | L5: https://www.google.com/maps/dir//Yoga+Sadhana+Mandir,+3+Plot+no.+41,+above+Shree+Krishna+mandir,+Nerul+East,+Sector+19A,+Navi+Mumbai,+Maharashtra+400706,+India/data=!4m6!4m5!1m1!4e2!1m2!1m1!1s0x3be7c3c7243940bd:0x73fbf7448782bc85?sa=X&ved=1t:57443&ictx=111 | M5: Directions | N5: Yoga
A6: Nirvana Yoga Community Studio by Shradha | B6: · Yoga studio | C6: 4.9 | D6: -128 | E6: 10+ years in business · Panvel, Maharashtra, India | F6: · +91 98334 14151 | G6: · Closes 8 PM | H6: Open | I6: "I left each session feeling rejuvenated and more connected to my body." | J6: https://www.youtube.com/watch?v=IOv-F95L3MI | K6: Website | L6: https://www.google.com/maps/dir//Shop+No:+42%2643,+Nirvana+Yoga+Community+Studio+by+Shradha,+KESAR+GARDENS,+Plot+no:+53,+opposite+Ramsheth+Thakur+Public+School,+Sector+20,+Kharghar,+Panvel,+Maharashtra+410210,+India/data=!4m6!4m5!1m1!4e2!1m2!1m1!1s0x3be7c3172175d633:0x6f16cea8ab96d6b3?sa=X&ved=1t:57443&ictx=111 | M6: Directions
A7: Yoga classes offline and online | B7: · Yoga studio | C7: 5.0 | D7: -300 | E7: 7+ years in business · Navi Mumbai, Maharashtra, India | F7: · +91 80555 77374 | G7: · Closes 9 PM | H7: Open | I7: "Easy to follow, gentle stretches, and very relaxing 😌" | J7: http://www.allaboutyoga.in/ | K7: Website | L7: https://www.google.com/maps/dir//Yoga+classes+offline+and+online,+Stree+Mukti+Sanghatana,+Sector+18,+Kopar+Khairane,+Navi+Mumbai,+Maharashtra+400709,+India/data=!4m6!4m5!1m1!4e2!1m2!1m1!1s0x3be7c16c64dc54a3:0x1b1239445ca13076?sa=X&ved=1t:57443&ictx=111 | M7: Directions
A8: Yogam Isha Hatha Yoga - Navi Mumbai | B8: · Yoga studio | C8: 4.5 | D8: -355 | E8: Navi Mumbai, Maharashtra, India | I8: " program conducted by Isha Hatha trained teacher." | J8: https://www.instagram.com/yogam.life?igsh=MXZ5MHdyc2Y5Z3F3cw== | K8: Website | L8: https://www.google.com/maps/dir//Yogam+Isha+Hatha+Yoga+-+Navi+Mumbai,+Mayuresh+Square+301,+Sector+15,+CBD+Belapur,+Navi+Mumbai,+Maharashtra+400614,+India/data=!4m6!4m5!1m1!4e2!1m2!1m1!1s0x3be7c238c251f225:0x7cd21c4ac74648c2?sa=X&ved=1t:57443&ictx=111 | M8: Directions | N8: Yoga
A9: Oshiva Yoga | B9: · Yoga studio | C9: 5.0 | D9: -103 | E9: 10+ years in business · Navi Mumbai, Maharashtra, India | F9: · +91 97693 15233 | G9: · Closes 8 PM | H9: Open | I9: "Their teaching style is calm, clear, and deeply insightful." | J9: https://oshivayoga.in/ | K9: Website | L9: https://www.google.com/maps/dir//Oshiva+Yoga,+Community+Hall,+opp.+Grand+Central+Mall,+Konkan+Rail+Vihar,+Sector+40,+Seawoods,+Navi+Mumbai,+Maharashtra+400706,+India/data=!4m6!4m5!1m1!4e2!1m2!1m1!1s0x3be7c3473a9206b9:0xd4d99c4858521ddb?sa=X&ved=1t:57443&ictx=111 | M9: Directions
A10: Yoga journey | B10: · Yoga studio | C10: 5.0 | D10: -243 | E10: 7+ years in business · Maharashtra, India | G10: · Closes 5 PM Tue | H10: Open | I10: "She taught me various methods of ." | J10: https://www.facebook.com/yoga143/ | K10: Website | L10: https://www.google.com/maps/dir//Yoga+journey,+chowk+multispeciality+hospital,+near+by+tempo+naka,+Chauk,+Maharashtra+410207,+India/data=!4m6!4m5!1m1!4e2!1m2!1m1!1s0x3be7e9b6fb324feb:0x28c6e722717683ac?sa=X&ved=1t:57443&ictx=111 | M10: Directions | N10: yoga
A11: Shunyamudra Yoga & Wellness Centre | B11: · Yoga studio | C11: 4.9 | D11: -88 | E11: 5+ years in business · Navi Mumbai, Maharashtra, India | F11: · +91 77770 16109 | G11: · Closes 9 PM | H11: Open | I11: "Transformative experience with exceptional instructors." | J11: http://www.shunyamudra.com/ | K11: Website | L11: https://www.google.com/maps/dir//Shop+no+21,+Shunyamudra+Yoga+%26+Wellness+Centre,+Bhoomi+Heights,+opposite+Little+World+Mall,+Sector+8,+Kharghar,+Navi+Mumbai,+Maharashtra+410210,+India/data=!4m6!4m5!1m1!4e2!1m2!1m1!1s0x3be7c32836927f6f:0x437bd17bdf179ac6?sa=X&ved=1t:57443&ictx=111 | M11: Directions | N11: yoga
A12: Yoga Asanaaa Traditional Yoga Studio | B12: · Yoga studio | C12: 4.9 | D12: -56 | E12: 3+ years in business · Navi Mumbai, Maharashtra, India | F12: · +91 98671 07899 | G12: · Closes 8 PM | H12: Open | I12: "Very relaxing and body work class, lovely atmosphere and vibe" | J12: https://www.instagram.com/yoga_asanaaa/?hl=en | K12: Website | L12: https://www.google.com/maps/dir//shop+no,+Yoga+Asanaaa+Traditional+Yoga+Studio,+Eurokids,+Plot+44+%26+45,+2+%26+3,+Sector+15,+CBD+Belapur,+Navi+Mumbai,+Maharashtra+400614,+India/data=!4m6!4m5!1m1!4e2!1m2!1m1!1s0x3be7c3aa07aaaaab:0x48f7d935a496d6fc?sa=X&ved=1t:57443&ictx=111 | M12: Directions | N12: yoga
A13: YogAhara | B13: · Yoga retreat center | C13: 4.9 | D13: -87 | E13: Navi Mumbai, Maharashtra, India | F13: · +91 89833 38833 | G13: · Closes 8 PM | H13: Open | I13: "Each class feels safe, positive, and full of good energy." | L13: https://www.google.com/maps/dir//Plot+No.63,+YogAhara,+Progressive+Villa+C,+Sector+20,+CBD+Belapur,+Navi+Mumbai,+Maharashtra+400614,+India/data=!4m6!4m5!1m1!4e2!1m2!1m1!1s0x3be7c3e46c4981d7:0xb7b17a958a6b813f?sa=X&ved=1t:57443&ictx=111 | M13: Directions
A14: Yoga 108 Studio | B14: · Yoga studio | C14: 4.9 | D14: -92 | E14: 7+ years in business · Navi Mumbai, Maharashtra, India | F14: · +91 93722 46727 | G14: · Closes 9 PM | H14: Open | I14: "Your sessions have helped improve my flexibility." | L14: https://www.google.com/maps/dir//Yoga+108+Studio,+Building+A11,+Flat.+1,+Kendriya+Vihar,+Sector+11,+Kharghar,+Navi+Mumbai,+Maharashtra+410210,+India/data=!4m6!4m5!1m1!4e2!1m2!1m1!1s0x3be7e90e1a20009b:0x72983055471418d9?sa=X&ved=1t:57443&ictx=111 | M14: Directions | N14: yoga
A15: Dr. Kalyani's Yoga | B15: · Yoga studio | C15: 4.8 | D15: -81 | E15: 10+ years in business · Navi Mumbai, Maharashtra, India | F15: · +91 76205 95613 | G15: · Closes 10 PM | H15: Open | I15: "I can say that because I was a extremely sceptical about ." | L15: https://www.google.com/maps/dir//Dr.+Kalyani's+Yoga,+Shop+No.+01,+Plot+No.+23,+Ground+Floor,+Sec-18A,+beside+to+Ganesh+Talav,+Nerul,+Navi+Mumbai,+Maharashtra+400706,+India/data=!4m6!4m5!1m1!4e2!1m2!1m1!1s0x3be7c375d063845b:0x91b15efacb3d48c6?sa=X&ved=1t:57443&ictx=111 | M15: Directions | N15: yoga
A16: YogaaNation-Yoga Clasess in Nerul West | B16: · Yoga studio | C16: 4.9 | D16: -57 | E16: 10+ years in business · Navi Mumbai, Maharashtra, India | F16: · +91 96532 10275 | G16: · Closes 8:30 PM | H16: Open | I16: "After the classes, I feel so relaxed, energetic and healthy." | J16: https://www.instagram.com/yogaaanation?igsh=MzJrazR5c2M1Yjlr | K16: Website | L16: https://www.google.com/maps/dir//Shop+C-34,+YogaaNation-Yoga+Clasess+in+Nerul+West,+Neighbourhood+Shopping+Complex,+Plot+10%2F11,+near+SBI+Bank+and+Rasoi+Restaurant,+Sector+4,+Nerul+West,+Navi+Mumbai,+Maharashtra+400706,+India/data=!4m6!4m5!1m1!4e2!1m2!1m1!1s0x3be7c3ca10046b87:0x3214b8bf35a12b3a?sa=X&ved=1t:57443&ictx=111 | M16: Directions | N16: yoga
A17: YOGREEKA YOGA FITNESS STUDIO | B17: · Yoga studio | C17: 4.9 | D17: -59 | E17: 3+ years in business · Navi Mumbai, Maharashtra, India | F17: · +91 99702 63472 | G17: · Closes 8 PM | H17: Open | I17: "The instructor is patient and ensures our posture is correct." | L17: https://www.google.com/maps/dir//Shop+No.+4,+YOGREEKA+YOGA+FITNESS+STUDIO,+Mangal+Krupa+Society,+near+Datta+Mandir,+Sector+11,+Kopar+Khairane,+Navi+Mumbai,+Maharashtra+400709,+India/data=!4m6!4m5!1m1!4e2!1m2!1m1!1s0x3be7c124320dd0f7:0x1290e391d6bde764?sa=X&ved=1t:57443&ictx=111 | M17: Directions
A18: Blue Eye Yoga Studio | B18: · Yoga studio | C18: 5.0 | D18: -131 | E18: 3+ years in business · Navi Mumbai, Maharashtra, India | F18: · +91 98209 28789 | G18: · Closes 9 PM | H18: Open | I18: "Each class leaves me feeling relaxed, energized, and centered." | L18: https://www.google.com/maps/dir//Shop+No.+05,+Blue+Eye+Yoga+Studio,+The+Signature,+Plot+No.+71,+beside+The+Signature,+Sector+44,+Seawoods,+Navi+Mumbai,+Maharashtra+400706,+India/data=!4m6!4m5!1m1!4e2!1m2!1m1!1s0x3be7c37675321a89:0xe6babb6ab317e62b?sa=X&ved=1t:57443&ictx=111 | M18: Directions
A19: YOGA MUDRA FITNESS CLASSES ALIES YOGANESH FITNESS CLASSES | B19: · Yoga studio | C19: 5.0 | D19: -225 | E19: Navi Mumbai, Maharashtra, India | F19: · +91 87792 41367 | G19: · Closes 10 PM | H19: Open | I19: "The teacher is very friendly, helpful, and highly experienced." | J19: https://yogamudrafitnessclasses.com/ | K19: Website | L19: https://www.google.com/maps/dir//901,+902,+YOGA+MUDRA+FITNESS+CLASSES+ALIES+YOGANESH+FITNESS+CLASSES,+Nms+Icon,+PLOT+NO.+194,+Sector+19,+Ulwe,+Navi+Mumbai,+Maharashtra+410206,+India/data=!4m6!4m5!1m1!4e2!1m2!1m1!1s0x3be7c31878a5c22b:0x5e77ef7487ef61f3?sa=X&ved=1t:57443&ictx=111 | M19: Directions | N19: yoga
A20: Yog Sanskruti Studio | B20: · Yoga studio | C20: 4.9 | D20: -43 | E20: Navi Mumbai, Maharashtra, India | F20: · +91 85912 70868 | G20: · Closes 10 PM | H20: Open | I20: "Mamta mam is a talented, motivating and dedicated teacher." | L20: https://www.google.com/maps/dir//Yog+Sanskruti+Studio,+Megh+Malhar+society+building+no+L02,+shop+02,+Sector+11,+Jijamata+Nagar,+Ghansoli,+Navi+Mumbai,+Maharashtra+400701,+India/data=!4m6!4m5!1m1!4e2!1m2!1m1!1s0x3be7c100228a3da1:0xa695e6c700aaafbb?sa=X&ved=1t:57443&ictx=111 | M20: Directions | N20: yoga
A21: The Yoga Institute | B21: · Yoga studio | C21: 4.8 | D21: (1.1K) | E21: 105+ years in business · Mumbai, Maharashtra, India | F21: · +91 70455 58181 | G21: · Closes 8 PM | H21: Open | I21: "A life changing experience that nurtures the body, mind and spirit 🙏🙏" | J21: http://theyogainstitute.org/ | K21: Website | L21: https://www.google.com/maps/dir//The+Yoga+Institute,+Sri+Yogendra+Marg,+Prabhat+Colony,+Santacruz+East,+Mumbai,+Maharashtra+400055,+India/data=!4m6!4m5!1m1!4e2!1m2!1m1!1s0x3be7c9a916aaaaab:0xb1b1dcb9c91cb9a?sa=X&ved=1t:57443&ictx=111 | M21: Directions
A22: Shri Ambika Yoga Kutir, CBD Belapur Navi Mumbai | B22: · Yoga retreat center | C22: 5.0 | D22: -51 | E22: Navi Mumbai, Maharashtra, India | F22: · +91 98196 79480 | G22: · Closes 7 PM | H22: Open | I22: "Class is free of cost due to their devoted & dedicated Teacher." | J22: http://ambikayogkutir.org/ | K22: Website | L22: https://www.google.com/maps/dir//Shri+Ambika+Yoga+Kutir,+CBD+Belapur+Navi+Mumbai,+Shri+Ambika+yog+Vanousadhi,+medicinal+plant+nursery)+kendra,+Sector+9N,+CBD+Belapur,+Navi+Mumbai,+Maharashtra+400614,+India/data=!4m6!4m5!1m1!4e2!1m2!1m1!1s0x3be7c3b56ce4f723:0x14ec6f5e2d6c2e3c?sa=X&ved=1t:57443&ictx=111 | M22: Directions | N22: Yoga
A23: Drona Yoga | B23: · Yoga instructor | C23: 5.0 | D23: -88 | E23: Navi Mumbai, Maharashtra, India | F23: · +91 95400 04700 | G23: · Closes 9 PM | H23: Open | I23: "Perfect teacher with true passion and great teaching style." | J23: https://youtube.com/shorts/fjfV47qOJ4s?feature=shared | K23: Website | L23: https://www.google.com/maps/dir//Drona+Yoga,+Parsik+Hill+Rd,+Sector+30,+CBD+Belapur,+Navi+Mumbai,+Maharashtra+400614,+India/data=!4m6!4m5!1m1!4e2!1m2!1m1!1s0x3be7c3048598dcb3:0xb2a5c6f6c0b93ecf?sa=X&ved=1t:57443&ictx=111 | M23: Directions | N23: yoga
A24: Swami Vivekananda Yoga Kendra - Online Mediation Classes & online Yoga Courses | B24: · Yoga studio | C24: 4.8 | D24: -260 | E24: 15+ years in business · Navi Mumbai, Maharashtra, India | G24: · Closes 9 PM | H24: Open | I24: "Very nice way of teaching online..." | J24: http://www.vivekanandayoga.in/ | K24: Website | L24: https://www.google.com/maps/dir//Plot+No+20,+Swami+Vivekananda+Yoga+Kendra+-+Online+Mediation+Classes+%26+online+Yoga+Courses,+Indian+Welfare+Association+SIWA,+Swami+Vivekananda+Yoga+Kendra,+South,+Sector+14,+Kopar+Khairane,+Navi+Mumbai,+Maharashtra+400709,+India/data=!4m6!4m5!1m1!4e2!1m2!1m1!1s0x3be7c0d6ffffffff:0x8a34b8cef9ecbc2?sa=X&ved=1t:57443&ictx=111 | M24: Directions | N24: yoga
A25: Vitalis - Pilates Yoga & Physiotherapy | B25: · Yoga studio | C25: 4.9 | D25: -81 | E25: Navi Mumbai, Maharashtra, India | F25: · +91 85912 82742 | G25: · Closes 10 PM | H25: Open | I25: "... experience,feel great 👍 good class &with proper coach 😊" | J25: https://vitalismove.com/ | K25: Website | L25: https://www.google.com/maps/dir//Shop+No.+20+%26+21,+Vitalis+-+Pilates+Yoga+%26+Physiotherapy,+Dhara+Complex,+Sector+44A,+Seawoods,+Navi+Mumbai,+Maharashtra+400706,+India/data=!4m6!4m5!1m1!4e2!1m2!1m1!1s0x3be7c385e3cc0ea3:0xcc20adc45d70bff8?sa=X&ved=1t:57443&ictx=111 | M25: Directions | N25: yoga
A26: YOGA CLASS (Shakti Yog Sadhana) | B26: · Yoga studio | C26: 4.9 | D26: -108 | E26: 5+ years in business · Navi Mumbai, Maharashtra, India | F26: · +91 98199 95302 | G26: · Opens 6 AM Tue | H26: Closed | I26: "The sessions conducted by Nisha and Kavita madam are very effective." | J26: https://www.instagram.com/shakti_yog_sadhana?igsh=dnV2OTljbHVhaWV5 | K26: Website | L26: https://www.google.com/maps/dir//YOGA+CLASS+(Shakti+Yog+Sadhana),+Nurturing+roots+Yoga+Class+Hari+Dharshan+society,+Plot+No.+1,+Sector+9,+Ulwe,+Navi+Mumbai,+Maharashtra+410206,+India/data=!4m6!4m5!1m1!4e2!1m2!1m1!1s0x3be7c316baf3143f:0x9a486465b9ad34e1?sa=X&ved=1t:57443&ictx=111 | M26: Directions | N26: yoga
A27: Healing Soul Studio | B27: · Yoga studio | C27: 4.9 | D27: -47 | E27: 3+ years in business · Navi Mumbai, Maharashtra, India | F27: · +91 84540 05360 | G27: · Closes 7 PM | H27: Open | I27: "My body felt lighter, my breath deeper, and my heart more open." | L27: https://www.google.com/maps/dir//Healing+Soul+Studio,+Shop+No.26,+Neelkanth+Pride,+Plot+No.+35,+36,+Seawoods+West,+Sector+42A,+Navi+Mumbai,+Maharashtra+400706,+India/data=!4m6!4m5!1m1!4e2!1m2!1m1!1s0x3be7c3fd8240ffa9:0xfccd3785b9b521e8?sa=X&ved=1t:57443&ictx=111 | M27: Directions
A28: New Aura Health & Fitness Institute | Yoga Classes in Kharghar Navi Mumbai | B28: · Yoga studio | C28: 5.0 | D28: -87 | E28: Panvel, Maharashtra, India | F28: · +91 89286 81639 | H28: Open 24 hours | I28: "I feel so stress-free, relaxed, and energetic after joining this class." | L28: https://www.google.com/maps/dir//H5,+New+Aura+Health+%26+Fitness+Institute+%7C+Yoga+Classes+in+Kharghar+Navi+Mumbai,+Chs,+1403,+Sector+36,+Kharghar,+Panvel,+Maharashtra+410210,+India/data=!4m6!4m5!1m1!4e2!1m2!1m1!1s0x3be7c1e0752b931d:0x3d252f3af340a1f8?sa=X&ved=1t:57443&ictx=111 | M28: Directions | N28: yoga
A29: RFSS Yoga & Fitness Academy | B29: · Yoga studio | C29: 5.0 | D29: -36 | E29: Navi Mumbai, Maharashtra, India | F29: · +91 75459 20285 | G29: · Closes 10 PM | H29: Open | I29: "Amazing classes Sir is polite and teaches really well 👍" | J29: https://www.rfss.co.in/ | K29: Website | L29: https://www.google.com/maps/dir//Shop+No.3,+RFSS+Yoga+%26+Fitness+Academy,+Tricity+Panache,+Plot+no+7,+Sector+38,+Seawoods,+Navi+Mumbai,+Maharashtra+400706,+India/data=!4m6!4m5!1m1!4e2!1m2!1m1!1s0x3be7c3c152d1ad4b:0x235ebb44e1a3d097?sa=X&ved=1t:57443&ictx=111 | M29: Directions
A30: Yoga With Indra | B30: · Yoga instructor | C30: 5.0 | D30: -14 | E30: Navi Mumbai, Maharashtra, India | F30: · +91 81087 70760 | H30: Open 24 hours | I30: "An amazing instructor who teaches with so much dedication and detail." | J30: https://www.instagram.com/the_yoga_granny?igsh=OWg2Y3A0eDdyNGJh | K30: Website | L30: https://www.google.com/maps/dir//a+and+b,+Yoga+With+Indra,+Twins+Heritage+CHS,+Plot+79,+Sector+19A,+Nerul,+Navi+Mumbai,+Maharashtra+400706,+India/data=!4m6!4m5!1m1!4e2!1m2!1m1!1s0x3be7c323ba56a39d:0x4c18dec19ebbc8c7?sa=X&ved=1t:57443&ictx=111 | M30: Directions | N30: yoga
A31: GREEN TARA YOGA AND WELLNESS | B31: · Yoga studio | C31: 5.0 | D31: -11 | E31: Kharghar, Navi Mumbai, Maharashtra, India | G31: · Closes 8:30 PM | H31: Open | I31: "Amazing teacher with positive energy and great guidance." | J31: http://www.greentarayogastudio.com/ | K31: Website | L31: https://www.google.com/maps/dir//Office+129+,1st+Floor,+GREEN+TARA+YOGA+AND+WELLNESS,+Grow+More+Tower,+Plot+no+5,+Sector+2,+Kharghar,+Navi+Mumbai,+Maharashtra+410210,+India/data=!4m6!4m5!1m1!4e2!1m2!1m1!1s0x3be7c3007383a603:0xbbc2f3c69d8df00f?sa=X&ved=1t:57443&ictx=111 | M31: Directions | N31: yoga
A32: Rising yoga Studio | B32: · Yoga studio | C32: 4.9 | D32: -13 | E32: Panvel, Maharashtra, India | G32: · Opens 11 AM Tue | H32: Closed | I32: "The class with the kind and supportive instructor was wonderful." | L32: https://www.google.com/maps/dir//Ground+Floor,+Rising+yoga+Studio,+Om+Harmony,+Ultra+Instinct+Fitness+Chamber,+Sector+10,+Kharghar,+Panvel,+Maharashtra+410210,+India/data=!4m6!4m5!1m1!4e2!1m2!1m1!1s0x3be7c3a676064f0f:0x253dba676d84c98a?sa=X&ved=1t:57443&ictx=111 | M32: Directions | N32: yoga
A33: YogAmbika | B33: · Yoga studio | C33: 5.0 | D33: -117 | E33: 10+ years in business · Panvel, Maharashtra, India | F33: · +91 95570 36487 | G33: · Closes 8 PM | H33: Open | I33: "It is very calm and quiet and the practices are really good." | J33: http://www.yogambika.in/ | K33: Website | L33: https://www.google.com/maps/dir//YogAmbika,+Srujan+Kids,+Anushaktinagar,+Sector+10,+Kharghar,+Panvel,+Maharashtra+410210,+India/data=!4m6!4m5!1m1!4e2!1m2!1m1!1s0x3be7c36b6841cd9f:0x9f9680c110476cb4?sa=X&ved=1t:57443&ictx=111 | M33: Directions | N33: yoga
A34: MAHESHWARI YOGA | B34: · Yoga studio | C34: 4.9 | D34: -228 | E34: 7+ years in business · Navi Mumbai, Maharashtra, India | F34: · +91 93218 50787 | G34: · 5 PM | H34: Opens soon | I34: "Great institute with skilled and supportive instructors." | J34: https://maheshwariyoga.com/ | K34: Website | L34: https://www.google.com/maps/dir//Shop+18%2619,+MAHESHWARI+YOGA,+Green+Palms,+Sector+15,+Ghansoli,+Navi+Mumbai,+Maharashtra+400701,+India/data=!4m6!4m5!1m1!4e2!1m2!1m1!1s0x3be7c1f452fb94ab:0x9eb3dea611053b?sa=X&ved=1t:57443&ictx=111 | M34: Directions | N34: yoga
A35: Zumba Fitness With Raksha and Neha | B35: · Fitness center | C35: 5.0 | D35: -12 | E35: 3+ years in business · Navi Mumbai, Maharashtra, India | F35: · +91 88284 02238 | G35: · Closes 10 PM | H35: Open | I35: "Amazing work out and classes feel so great and relaxed after class" | L35: https://www.google.com/maps/dir//second+Floor,+Zumba+Fitness+With+Raksha+and+Neha,+Orkid+academy,+Merchant+Classic+Building,+Plot+No.3,+above+Ratna+Konkan+restaurant,+Sector+48-A,+Seawoods,+Navi+Mumbai,+Maharashtra+400706,+India/data=!4m6!4m5!1m1!4e2!1m2!1m1!1s0x3be7c38fcd47c2ab:0xe85ec1e08a0a1355?sa=X&ved=1t:57443&ictx=111 | M35: Directions | N35: yoga
A36: Vimukti Yoga and Wellness center | B36: · Yoga studio | C36: 5.0 | D36: -50 | E36: 10+ years in business · Navi Mumbai, Maharashtra, India | F36: · +91 80975 08815 | G36: · Closes 8 PM | H36: Open | I36: "Me and my wife are taking sessions regularly from him for past 3 years" | J36: https://vimuktiyoga.com/ | K36: Website | L36: https://www.google.com/maps/dir//4th+floor,+Vimukti+Yoga+and+Wellness+center,+Ashram+kant+darshan+Darbar,+plot+no+315-316,+Sector+6,+Nerul,+Navi+Mumbai,+Maharashtra+400706,+India/data=!4m6!4m5!1m1!4e2!1m2!1m1!1s0x3be7c30d8684ee45:0x6a1ae50221a6fe0b?sa=X&ved=1t:57443&ictx=111 | M36: Directions | N36: yoga
A37: AnandaLaxmi Yoga | B37: · Yoga studio | C37: 4.9 | D37: -12 | E37: 3+ years in business · Navi Mumbai, Maharashtra, India | F37: · +91 91672 00801 | H37: Open 24 hours | I37: "Excellent classes with a calm and welcoming atmosphere." | J37: https://www.anandalaxmiyoga.co.in/ | K37: Website | L37: https://www.google.com/maps/dir//%2628,+AnandaLaxmi+Yoga,+coming+soon,+First+Floor+Vitthal+Rukmini+Mandir+opp+nerul+gymkhana+sector+28+nerul+Location+1+sector+28,+location+2+sector+22+Branch:+vashi,+Nerul+22,+Kharghar,+Navi+Mumbai,+Maharashtra+400706,+India/data=!4m6!4m5!1m1!4e2!1m2!1m1!1s0x3be7c3abba0597d3:0x1403a4d9a0f4c1aa?sa=X&ved=1t:57443&ictx=111 | M37: Directions | N37: Yoga
A38: THE YOGA ART - Seawoods | B38: · Yoga studio | C38: 4.8 | D38: -45 | E38: Panvel, Maharashtra, India | G38: · Closes 8 PM | H38: Open | I38: "Joining the art for weight loss." | J38: https://theyoga.artcastle.org.in/ | K38: Website | L38: https://www.google.com/maps/dir//C%2Fo+Mindseed,+THE+YOGA+ART+-+Seawoods,+Lakhani's+Palm+view,+Plot+12,+Sector-48,+Seawoods,+Panvel,+Maharashtra+400706,+India/data=!4m6!4m5!1m1!4e2!1m2!1m1!1s0x3be7c344bae2688f:0x98eab19e9a451f41?sa=X&ved=1t:57443&ictx=111 | M38: Directions | N38: yoga
A39: Female yoga teacher at home in Kharghar | B39: · Yoga instructor | C39: 4.9 | D39: -44 | E39: · +91 96532 37116 | G39: · Closes 9 PM | H39: Open | I39: "Your sessions are a wonderful combination of stress relief and fitness." | J39: http://swamiyogi.com/ | K39: Website | N39: yoga
A40: Acarya Yoga | B40: · Yoga instructor | C40: 5.0 | D40: -41 | E40: +91 99208 00193 | I40: "She is not just instructor but also very talented and good human being." | J40: https://instagram.com/acaryayoga?igshid=YmMyMTA2M2Y= | K40: Website | N40: yoga
...

Sheet Final
A1: S.N | B1: Institute Name | C1: Industry | D1: Rating | E1: Total Reviews | F1: Contact | G1: Top Reviews | H1: Website | I1: Google Maps
A2: 1 | B2: Aarambh Yoga Institute | C2: Yoga studio | D2: 4.9 | E2: =SUBSTITUTE(SUBSTITUTE(SUBSTITUTE(Raw!D42,"-",""),"(",""),")","") -> 273 | F2: +91 91361 22892 | G2: "All the teachers are incredibly warm, knowledgeable, and notably patient." | H2: Aarambh Yoga Institute | I2: =IF(Raw!L42="","Not Available",HYPERLINK(Raw!L42,"Maps")) -> Maps
A3: 2 | B3: Aayurvati yoga classes | C3: Yoga instructor | D3: 4.9 | E3: =SUBSTITUTE(SUBSTITUTE(SUBSTITUTE(Raw!D61,"-",""),"(",""),")","") -> 17 | F3: +91 93260 64014 | G3: "They will teach you exercises to maintain your health and body." | H3: Not Available | I3: =IF(Raw!L61="","Not Available",HYPERLINK(Raw!L61,"Maps")) -> Maps
A4: 3 | B4: Acarya Yoga | C4: Yoga instructor | D4: 5 | E4: =SUBSTITUTE(SUBSTITUTE(SUBSTITUTE(Raw!D39,"-",""),"(",""),")","") -> 44 | G4: "She is not just instructor but also very talented and good human being." | H4: Not Available | I4: =IF(Raw!L39="","Not Available",HYPERLINK(Raw!L39,"Maps")) -> Not Available
A5: 4 | B5: Adi Yoga - Yoga classes Mumbai | Yoga at Home | C5: Yoga studio | D5: 4.9 | E5: =SUBSTITUTE(SUBSTITUTE(SUBSTITUTE(Raw!D56,"-",""),"(",""),")","") -> 219 | F5: +91 89286 81840 | G5: "Very help full for health and really awesome teachers in Adi ." | H5: adiyoga | I5: =IF(Raw!L56="","Not Available",HYPERLINK(Raw!L56,"Maps")) -> Maps
A6: 5 | B6: AdyantiYoga (A group of Traditional Yogis) | C6: Yoga instructor | D6: 5 | E6: =SUBSTITUTE(SUBSTITUTE(SUBSTITUTE(Raw!D96,"-",""),"(",""),")","") -> 109 | F6: +91 84332 52193 | G6: "Amazing teachers with a great experience and knowledge." | H6: Adyanti Yoga | I6: =IF(Raw!L96="","Not Available",HYPERLINK(Raw!L96,"Maps")) -> Maps
A7: 6 | B7: AnandaLaxmi Yoga | C7: Yoga studio | D7: 4.9 | E7: =SUBSTITUTE(SUBSTITUTE(SUBSTITUTE(Raw!D36,"-",""),"(",""),")","") -> 50 | F7: +91 91672 00801 | G7: "Excellent classes with a calm and welcoming atmosphere." | H7: Soccer Predictions | I7: =IF(Raw!L36="","Not Available",HYPERLINK(Raw!L36,"Maps")) -> Maps
A8: 7 | B8: Ancient Martial Arts & Yoga Studio | C8: Martial arts club | D8: 5 | E8: =SUBSTITUTE(SUBSTITUTE(SUBSTITUTE(Raw!D81,"-",""),"(",""),")","") -> 14 | F8: +91 98212 35167 | H8: Not Available | I8: =IF(Raw!L81="","Not Available",HYPERLINK(Raw!L81,"Maps")) -> Maps
A9: 8 | B9: Aqua Fitness Club | C9: Fitness center | D9: 4.6 | E9: =SUBSTITUTE(SUBSTITUTE(SUBSTITUTE(Raw!D72,"-",""),"(",""),")","") -> 159 | F9: +91 85915 03535 | G9: "Swimming, zumba, kick boxing, steam, shower facility, ." | H9: Aqua Fitness Club (@aquafitnessclubvashi) • Instagram photos and videos | I9: =IF(Raw!L72="","Not Available",HYPERLINK(Raw!L72,"Maps")) -> Maps
A10: 9 | B10: Art of Living - Nerul East, Navi Mumbai | C10: Meditation center | D10: 4.9 | E10: =SUBSTITUTE(SUBSTITUTE(SUBSTITUTE(Raw!D76,"-",""),"(",""),")","") -> 7 | F10: +91 98199 24757 | G10: "This is very good place for & MEDITATION" | H10: The Art of Living | I10: =IF(Raw!L76="","Not Available",HYPERLINK(Raw!L76,"Maps")) -> Maps
A11: 10 | B11: Art of Living - Nerul West, Navi Mumbai | C11: Meditation center | D11: 4.8 | E11: =SUBSTITUTE(SUBSTITUTE(SUBSTITUTE(Raw!D70,"-",""),"(",""),")","") -> 4 | F11: +91 98198 40320 | H11: Art of Living | I11: =IF(Raw!L70="","Not Available",HYPERLINK(Raw!L70,"Maps")) -> Maps
A12: 11 | B12: Best yoga Classes - Yogawithrajani | C12: Yoga studio | D12: 4.8 | E12: =SUBSTITUTE(SUBSTITUTE(SUBSTITUTE(Raw!D48,"-",""),"(",""),")","") -> 196 | F12: +91 98193 33241 | G12: "The instructor explains each pose clearly and encourages us throughout." | H12: Best Yoga Instructor in Mumbai | Yoga With Rajani | I12: =IF(Raw!L48="","Not Available",HYPERLINK(Raw!L48,"Maps")) -> Maps
A13: 12 | B13: Bharatiya Yog Sansthan (Free Yoga Sessions near Nageshwar Temple CBD Belapur) | C13: Yoga studio | D13: 5 | E13: =SUBSTITUTE(SUBSTITUTE(SUBSTITUTE(Raw!D69,"-",""),"(",""),")","") -> 9 | F13: +91 96532 35405 | G13: "Early morning has its own unique amazing benefits." | H13: Free Yoga CBD Belapur (@yogacbdbelapur) • Instagram photos and videos | I13: =IF(Raw!L69="","Not Available",HYPERLINK(Raw!L69,"Maps")) -> Maps
A14: 13 | B14: Big Breathe Yoga and Fitness Studio|Best Yoga Classes In Near Kharghar-Zumba Classes Kharghar-Fitness Studio Near Me Kharghar | C14: Yoga studio | D14: 4.8 | E14: =SUBSTITUTE(SUBSTITUTE(SUBSTITUTE(Raw!D52,"-",""),"(",""),")","") -> 44 | F14: +91 93720 54498 | G14: "Very good classes, gives equal attention to each student!" | H14: Big Breathe Yoga and Fitness Studio | I14: =IF(Raw!L52="","Not Available",HYPERLINK(Raw!L52,"Maps")) -> Maps
A15: 14 | B15: Blue Eye Yoga Studio | C15: Yoga studio | D15: 5 | E15: =SUBSTITUTE(SUBSTITUTE(SUBSTITUTE(Raw!D18,"-",""),"(",""),")","") -> 131 | F15: +91 98209 28789 | G15: "Each class leaves me feeling relaxed, energized, and centered." | H15: Not Available | I15: =IF(Raw!L18="","Not Available",HYPERLINK(Raw!L18,"Maps")) -> Maps
A16: 15 | B16: Divine Parneeta Yoga | C16: Fitness center | D16: 5 | E16: =SUBSTITUTE(SUBSTITUTE(SUBSTITUTE(Raw!D88,"-",""),"(",""),")","") -> 26 | F16: +91 99694 32268 | G16: "Attending Divine Praneeta class is a deeply enriching experience." | H16: Not Available | I16: =IF(Raw!L88="","Not Available",HYPERLINK(Raw!L88,"Maps")) -> Maps
A17: 16 | B17: DNYAN YOG SADHANA | C17: Yoga studio | E17: =SUBSTITUTE(SUBSTITUTE(SUBSTITUTE(Raw!D109,"-",""),"(",""),")","") | H17: Not Available | I17: =IF(Raw!L109="","Not Available",HYPERLINK(Raw!L109,"Maps")) -> Maps
A18: 17 | B18: Dr. Kalyani's Yoga | C18: Yoga studio | D18: 4.8 | E18: =SUBSTITUTE(SUBSTITUTE(SUBSTITUTE(Raw!D15,"-",""),"(",""),")","") -> 81 | F18: +91 76205 95613 | G18: "I can say that because I was a extremely sceptical about ." | H18: Not Available | I18: =IF(Raw!L15="","Not Available",HYPERLINK(Raw!L15,"Maps")) -> Maps
A19: 18 | B19: Drona Yoga | C19: Yoga instructor | D19: 5 | E19: =SUBSTITUTE(SUBSTITUTE(SUBSTITUTE(Raw!D23,"-",""),"(",""),")","") -> 88 | F19: +91 95400 04700 | G19: "Perfect teacher with true passion and great teaching style." | H19: Top 3 Asanas To Increase Height #yoga #tadasana #bhujangasana #paschimottanasana #yogaforheight - YouTube | I19: =IF(Raw!L23="","Not Available",HYPERLINK(Raw!L23,"Maps")) -> Maps
A20: 19 | B20: Ekatvam Yoga Classes | C20: Physical fitness program | D20: 5 | E20: =SUBSTITUTE(SUBSTITUTE(SUBSTITUTE(Raw!D85,"-",""),"(",""),")","") -> 80 | F20: +91 98207 72757 | G20: " has given me a sense of peace and has improved my health and fitness." | H20: Not Available | I20: =IF(Raw!L85="","Not Available",HYPERLINK(Raw!L85,"Maps")) -> Maps
A21: 20 | B21: Female yoga teacher at home in Kharghar | C21: Yoga instructor | D21: 4.9 | E21: =SUBSTITUTE(SUBSTITUTE(SUBSTITUTE(Raw!D38,"-",""),"(",""),")","") -> 45 | G21: "Your sessions are a wonderful combination of stress relief and fitness." | H21: Not Available | I21: =IF(Raw!L38="","Not Available",HYPERLINK(Raw!L38,"Maps")) -> Maps
A22: 21 | B22: Finding Fitness | C22: Gym | D22: 4.8 | E22: =SUBSTITUTE(SUBSTITUTE(SUBSTITUTE(Raw!D89,"-",""),"(",""),")","") -> 110 | F22: +91 84335 37777 | G22: "The coaching staff is helpful and informative." | H22: Not Available | I22: =IF(Raw!L89="","Not Available",HYPERLINK(Raw!L89,"Maps")) -> Maps
A23: 22 | B23: First Light Yoga | C23: Yoga studio | D23: 4.9 | E23: =SUBSTITUTE(SUBSTITUTE(SUBSTITUTE(Raw!D73,"-",""),"(",""),")","") -> 13 | F23: +91 99304 85255 | G23: "Very good, experienced qualified teacher." | H23: Not Available | I23: =IF(Raw!L73="","Not Available",HYPERLINK(Raw!L73,"Maps")) -> Maps
A24: 23 | B24: Fitness with Shikha | C24: Fitness center | D24: 5 | E24: =SUBSTITUTE(SUBSTITUTE(SUBSTITUTE(Raw!D59,"-",""),"(",""),")","") -> 72 | F24: +91 99305 61765 | G24: "My stretching ability has improved a lot and she is a superb instructor" | H24: Not Available | I24: =IF(Raw!L59="","Not Available",HYPERLINK(Raw!L59,"Maps")) -> Maps
A25: 24 | B25: Flawless Dance & Fitness Studio | C25: Yoga studio | D25: 4.9 | E25: =SUBSTITUTE(SUBSTITUTE(SUBSTITUTE(Raw!D66,"-",""),"(",""),")","") -> 102 | F25: +91 88501 20018 | G25: "Super supportive instructors, fun classes and a chill vibes ....✨" | H25: Not Available | I25: =IF(Raw!L66="","Not Available",HYPERLINK(Raw!L66,"Maps")) -> Maps
A26: 25 | B26: Gauri's Yoga Studio | C26: Yoga studio | D26: 5 | E26: =SUBSTITUTE(SUBSTITUTE(SUBSTITUTE(Raw!D64,"-",""),"(",""),")","") -> 5 | F26: +91 98198 15151 | H26: https://www.gaurisyogastudio.in/ | I26: =IF(Raw!L64="","Not Available",HYPERLINK(Raw!L64,"Maps")) -> Maps
A27: 26 | B27: GREEN TARA YOGA AND WELLNESS | C27: Yoga studio | D27: 5 | E27: =SUBSTITUTE(SUBSTITUTE(SUBSTITUTE(Raw!D31,"-",""),"(",""),")","") -> 11 | G27: "Amazing teacher with positive energy and great guidance." | H27: Green Tara Yoga And Wellness | I27: =IF(Raw!L31="","Not Available",HYPERLINK(Raw!L31,"Maps")) -> Maps
A28: 27 | B28: Healing Soul Studio | C28: Yoga studio | D28: 4.9 | E28: =SUBSTITUTE(SUBSTITUTE(SUBSTITUTE(Raw!D27,"-",""),"(",""),")","") -> 47 | F28: +91 84540 05360 | G28: "My body felt lighter, my breath deeper, and my heart more open." | H28: Not Available | I28: =IF(Raw!L27="","Not Available",HYPERLINK(Raw!L27,"Maps")) -> Maps
A29: 28 | B29: International Sahaja Yoga Research and Health Centre | C29: Yoga studio | D29: 4.8 | E29: =SUBSTITUTE(SUBSTITUTE(SUBSTITUTE(Raw!D4,"-",""),"(",""),")","") -> 256 | F29: +91 83691 10612 | G29: "Adopt Sahaja meditation , elevate your life." | H29: Not Available | I29: =IF(Raw!L4="","Not Available",HYPERLINK(Raw!L4,"Maps")) -> Maps
A30: 29 | B30: Isha Yoga Center, Mumbai (Yoga Classes designed by Sadhguru) | C30: Yoga studio | D30: 4.7 | E30: =SUBSTITUTE(SUBSTITUTE(SUBSTITUTE(Raw!D62,"-",""),"(",""),")","") -> 115 | F30: +91 83000 14333 | G30: "Quite,green,great revebration, Isha shoppee, Classical Hatha classes" | H30: Not Available | I30: =IF(Raw!L62="","Not Available",HYPERLINK(Raw!L62,"Maps")) -> Maps
A31: 30 | B31: Jewel of Navi Mumbai (JNM) | C31: Park | D31: 4.4 | E31: =SUBSTITUTE(SUBSTITUTE(SUBSTITUTE(Raw!D101,"-",""),"(",""),")","") -> 12K | G31: "it’s an experience that rejuvenates the mind and soul." | H31: jewelofnavimumbai.com is for sale — Buy now for $199 | GoDaddy | I31: =IF(Raw!L101="","Not Available",HYPERLINK(Raw!L101,"Maps")) -> Maps
A32: 31 | B32: Kaivalyadhama Yoga Centre, Mumbai | C32: Yoga studio | D32: 4.5 | E32: =SUBSTITUTE(SUBSTITUTE(SUBSTITUTE(Raw!D99,"-",""),"(",""),")","") -> 60 | F32: +91 83699 04778 | G32: "The teachers are highly knowledgeable, dedicated, and compassionate." | H32: Kdham Mumbai Home | I32: =IF(Raw!L99="","Not Available",HYPERLINK(Raw!L99,"Maps")) -> Maps
A33: 32 | B33: Luv You Zindagi - Ladies Yoga Classes in Mumbai | C33: Yoga studio | D33: 5 | E33: =SUBSTITUTE(SUBSTITUTE(SUBSTITUTE(Raw!D97,"-",""),"(",""),")","") -> 57 | F33: +91 99677 33962 | G33: "Amaizing sessions, personal attention,you made learn exciting and fun." | H33: Not Available | I33: =IF(Raw!L97="","Not Available",HYPERLINK(Raw!L97,"Maps")) -> Maps
A34: 33 | B34: Maha yoga wellness centre | C34: Yoga studio | E34: =SUBSTITUTE(SUBSTITUTE(SUBSTITUTE(Raw!D107,"-",""),"(",""),")","") | F34: +91 99308 05559 | H34: Not Available | I34: =IF(Raw!L107="","Not Available",HYPERLINK(Raw!L107,"Maps")) -> Maps
A35: 34 | B35: MAHESHWARI YOGA | C35: Yoga studio | D35: 4.9 | E35: =SUBSTITUTE(SUBSTITUTE(SUBSTITUTE(Raw!D33,"-",""),"(",""),")","") -> 117 | F35: +91 93218 50787 | G35: "Great institute with skilled and supportive instructors." | H35: Maheshwari Yoga | I35: =IF(Raw!L33="","Not Available",HYPERLINK(Raw!L33,"Maps")) -> Maps
A36: 35 | B36: Me Time Yoga | C36: Yoga instructor | D36: 5 | E36: =SUBSTITUTE(SUBSTITUTE(SUBSTITUTE(Raw!D104,"-",""),"(",""),")","") -> 3 | F36: +91 99870 38168 | G36: "Me Time is the best class." | H36: Not Available | I36: =IF(Raw!L104="","Not Available",HYPERLINK(Raw!L104,"Maps")) -> Maps
A37: 36 | B37: Mindful Yoga by Hema Shankar | C37: Physical fitness program | D37: 5 | E37: =SUBSTITUTE(SUBSTITUTE(SUBSTITUTE(Raw!D50,"-",""),"(",""),")","") -> 69 | G37: "Ms. Hema, my instructor has helped me gain confidence in life." | H37: Not Available | I37: =IF(Raw!L50="","Not Available",HYPERLINK(Raw!L50,"Maps")) -> Maps
A38: 37 | B38: Namami Yog | Yoga at home | C38: Yoga instructor | D38: 4.9 | E38: =SUBSTITUTE(SUBSTITUTE(SUBSTITUTE(Raw!D94,"-",""),"(",""),")","") -> 41 | F38: +91 73512 63378 | G38: "Guiding best technique to improve body flexibility and calmness" | H38: http://namamiyog.com/ | I38: =IF(Raw!L94="","Not Available",HYPERLINK(Raw!L94,"Maps")) -> Maps
A39: 38 | B39: Namaste Yoga Classes | C39: Yoga studio | D39: 5 | E39: =SUBSTITUTE(SUBSTITUTE(SUBSTITUTE(Raw!D49,"-",""),"(",""),")","") -> 182 | F39: +91 99303 99993 | G39: "The instructor explains poses clearly and keeps the session well-paced." | H39: Namaste Yoga Classes | I39: =IF(Raw!L49="","Not Available",HYPERLINK(Raw!L49,"Maps")) -> Maps
A40: 39 | B40: NatureFit | C40: Health consultant | D40: 4.7 | E40: =SUBSTITUTE(SUBSTITUTE(SUBSTITUTE(Raw!D58,"-",""),"(",""),")","") -> 739 | F40: +91 89768 21409 | G40: "Good informative and useful session by Nature fit team." | H40: Naturefit | I40: =IF(Raw!L58="","Not Available",HYPERLINK(Raw!L58,"Maps")) -> Maps
...

Sheet Linked In Leads
D5: Leads | E5: Contact | F5: Requirement
D6: Mohanad Alhroub • 3rd+ | E6: info@mohanadalhroub.com | F6: Needs sales executive with marketing agency
D7: Vensor | E7: jeff.j@vesnor.net | F7: Freelance marketers
D8: Preet Patel • 3rd+ | E8: post | F8: Social media manager
D9: Prashant Tiwari • 3rd+ | E9: post | F9: Need long term partner
D10: Twincore Digital | E10: post | F10: Partnet ship oppurtunity
D11: Daljeet Kumar Singh • 3rd+ | E11: post | F11: Need website for new business
D12: YOGENDER K. • 3rd+ | E12: post | F12: freelancer developer
